Workbook

Sheet Start here
B1: Edexcel A Level Maths
B2: A quick check of how confident you feel on every topic, so revision goes where it's needed most.
B4: How it works
A5: 1 | B5: Open the Pure / Statistics / Mechanics tabs | C5: Each topic has a yellow Rating box. Click it and pick R, A or G. That's the only thing to fill in (Notes are optional).
A7: 2 | B7: Be honest, not kind | C7: If you're torn between two colours, pick the lower one. A Green topic gets almost no time, so only use it when you're sure.
A9: 3 | B9: Take your time | C9: 236 topics, most take a glance. About 45 minutes, and it's fine to do one tab at a time.
B12: What the colours mean
B13: R · Red | C13: I can't do this yet, or I'd probably get it wrong.
B14: A · Amber | C14: I can do some of it, or I'm slow and make mistakes.
B15: G · Green | C15: I can do this confidently in exam conditions.
B17: The tabs
B18: Pure | C18: 158 topics for Paper 1 and Paper 2.
B19: Statistics | C19: 42 topics for Paper 3, Section A.
B20: Mechanics | C20: 36 topics for Paper 3, Section B.
B21: Chapter tests | C21: Real exam questions for each textbook chapter. Mark them Done as you go.
B22: Progress | C22: Fills itself in: your Red / Amber / Green totals and a practice plan.
B24: Want to check a topic first?
B25: ▶ Watch | C25: A short Maths Genie video lesson on the topic.
B26: Questions links | C26: Each link lists the questions on that topic. 'Q 3, 7' means questions 3 and 7; 'Q 4–11' means questions 4 to 11. Past-paper sheets use pages instead, e.g. 'Pages 2, 5' (their question numbers can repeat). Click to open the PDF at the first one; hover to see which parts. 'none on this topic' means that source has no question on it.
B27: Maths Genie | C27: Exam-style questions written by Maths Genie, with worked answers.
B28: PMT worksheet | C28: Physics & Maths Tutor sheets: Edexcel past-paper questions (with mark scheme and model answers), or a Solomon topic worksheet (with answers) where that covers the topic better. Set A sheets have the mark scheme at the back of the same PDF.
B29: Textbook | C29: Where it is in the Pearson textbooks (Pure 1 and 2, Applied 1 and 2), plus the questions on that topic from the chapter test (real Edexcel exam questions).
B30: Ref and Year | C30: The official specification reference (e.g. P7.4). Y1 = AS / first-year content, Y2 = second year.
B32: The exams
C33: Three 2-hour papers, 100 marks each, each worth a third: Paper 1 and Paper 2 are Pure; Paper 3 is Statistics (Section A) and Mechanics (Section B). Year 1 content is examined too, and Pure can come up on Paper 3.

Sheet Pure
A1: Pure maths
A2: Paper 1 and Paper 2 · 158 topics · pick R, A or G in the yellow Rating column for each one
A3: ="Rated so far: "&(COUNTIF($D$7:$D$184,"R")+COUNTIF($D$7:$D$184,"A")+COUNTIF($D$7:$D$184,"G"))&" of 158 Red "&COUNTIF($D$7:$D$184,"R")&" · Amber "&COUNTIF($D$7:$D$184,"A")&" · Green "&COUNTIF($D$7:$D$184,"G")
A5: Your check | F5: Maths Genie | I5: PMT worksheet | M5: Textbook chapter test
A6: Ref | B6: Topic | C6: Year | D6: Rating | E6: Notes | F6: Video | G6: Questions | H6: Answers | I6: Worksheet | J6: Questions | K6: Mark scheme | L6: Answers | M6: Textbook | N6: Questions | O6: Mark scheme
A8: 1 | B8: Proof | E8: 3 topics · Year 1: 2 · Year 2: 1
A9: P1.1 | B9: Proof by deduction and proof by exhaustion | C9: 1 | F9: ▶ Watch | G9: Q 11, 12, 14, 15, 17, 18, 28, 32 | H9: Answers | I9: Proof | J9: Pages 1–5 | K9: Marks | L9: Answers | M9: Pure 1 Ch7 | N9: Pages 1–5 | O9: Marks | P9: P1
A10: P1.1 | B10: Disproof by counter-example | C10: 1 | F10: ▶ Watch | G10: Q 8, 11, 13, 17, 18, 24, 32, 35 | H10: Answers | I10: Solomon: Mixed exam-style questions on proof | J10: Q 1, 3, 7, 8 | K10: none | L10: Answers | M10: Pure 1 Ch7 | N10: Pages 1, 3 | O10: Marks | P10: P1
A11: P1.1 | B11: Proof by contradiction (incl. √2 irrational, infinitely many primes) | C11: 2 | F11: ▶ Watch | G11: Q 13–18 | H11: Answers | I11: Proof | J11: Page 4 | K11: Marks | L11: Answers | M11: Pure 2 Ch1 | N11: Page 4 | O11: Marks | P11: P1
A13: 2 | B13: Algebra and functions | E13: 38 topics · Year 1: 25 · Year 2: 13
A14: P2.1 | B14: Laws of indices | C14: 1 | F14: ▶ Watch | G14: Q 1–6, 8, 10 | H14: Answers | I14: Exponential Equations | J14: Page 1 | K14: Marks | L14: Answers | M14: Pure 1 Ch1 | N14: Pages 1, 2, 4, 6, 7, 9 | O14: Marks | P14: P2
A15: P2.1 | B15: Negative and fractional indices | C15: 1 | F15: ▶ Watch | G15: Q 1–3 | H15: Answers | I15: Solomon: Indices | J15: Q 4–11 | K15: none | L15: Answers | M15: Pure 1 Ch1 | N15: Pages 4, 7, 8 | O15: Marks | P15: P2
A16: P2.2 | B16: Surds and rationalising the denominator | C16: 1 | F16: ▶ Watch | G16: Q 2, 3, 5, 6, 8, 9, 11 | H16: Answers | I16: Solomon: Surds | J16: Q 4, 5, 7–9, 11, 12, 15 | K16: none | L16: Answers | M16: Pure 1 Ch1 | N16: Pages 2, 5–7, 10–13 | O16: Marks | P16: P2
A17: P2.3 | B17: Solving quadratics (factorising, formula, calculator) | C17: 1 | F17: ▶ Watch | G17: Q 11, 15 | H17: Answers | I17: Quadratics | J17: Page 1 | K17: Marks | L17: Answers | M17: Pure 1 Ch2 | N17: none | P17: P2
A18: P2.3 | B18: Completing the square | C18: 1 | F18: ▶ Watch | G18: Q 1–7 | H18: Answers | I18: Quadratics | J18: Page 6 | K18: Marks | L18: Answers | M18: Pure 1 Ch2 | N18: Page 11 | O18: Marks | P18: P2
A19: P2.3 | B19: Sketching quadratic graphs and quadratic functions | C19: 1 | F19: ▶ Watch | G19: Q 12, 14, 18, 19, 24 | H19: Answers | I19: Quadratics | J19: Page 6 | K19: Marks | L19: Answers | M19: Pure 1 Ch2 | N19: Page 11 | O19: Marks | P19: P2
A20: P2.3 | B20: The discriminant (real, repeated and no roots) | C20: 1 | F20: ▶ Watch | G20: Q 1–8 | H20: Answers | I20: Circles | J20: Pages 3, 5 | K20: Marks | L20: Answers | M20: Pure 1 Ch2 | N20: Pages 3, 4, 6–10, 13 | O20: Marks | P20: P2
A21: P2.3 | B21: Hidden quadratics (quadratics in a function of x) | C21: 1 | F21: ▶ Watch | G21: Q 6, 7, 9 | H21: Answers | I21: Quadratics | J21: Pages 1, 4 | K21: Marks | L21: Answers | M21: Pure 1 Ch2 | N21: Pages 1, 3 | O21: Marks | P21: P2
A22: P2.4 | B22: Linear simultaneous equations | C22: 1 | F22: ▶ Watch | G22: none on this topic | I22: Solomon: Simultaneous equations | J22: Q 1 | K22: none | L22: Answers | M22: Pure 1 Ch3 | N22: none | P22: P2
A23: P2.4 | B23: Simultaneous equations: one linear, one quadratic | C23: 1 | F23: ▶ Watch | G23: Q 3, 5–7, 12 | H23: Answers | I23: Solomon: Simultaneous equations | J23: Q 2–5 | K23: none | L23: Answers | M23: Pure 1 Ch3 | N23: Page 8 | O23: Marks | P23: P2
A24: P2.5 | B24: Linear inequalities | C24: 1 | F24: ▶ Watch | G24: Q 8, 13 | H24: Answers | I24: Solomon: Inequalities | J24: Q 1, 2 | K24: none | L24: Answers | M24: Pure 1 Ch3 | N24: Page 5 | O24: Marks | P24: P2
A25: P2.5 | B25: Quadratic inequalities (incl. set notation answers) | C25: 1 | F25: ▶ Watch | G25: Q 1, 2, 4, 8, 9, 11, 14, 15 | H25: Answers | I25: Inequalities | J25: Page 1 | K25: Marks | L25: Answers | M25: Pure 1 Ch3 | N25: Pages 4–7, 9, 13 | O25: Marks | P25: P2
A26: P2.5 | B26: Inequalities on graphs (shading regions) | C26: 1 | F26: ▶ Watch | G26: none on this topic | I26: Inequalities | J26: Page 2 | K26: Marks | L26: Answers | M26: Pure 1 Ch3 | N26: Page 6 | O26: Marks | P26: P2
A27: P2.6 | B27: Expanding brackets and collecting like terms | C27: 1 | F27: ▶ Watch | G27: Q 13, 14 | H27: Answers | I27: Solomon: Polynomials | J27: Q 1–6 | K27: none | L27: Answers | M27: Pure 1 Ch1 | N27: none | P27: P2
A28: P2.6 | B28: Factorising (incl. cubics) | C28: 1 | F28: ▶ Watch | G28: Q 11, 12 | H28: Answers | I28: Stationary Points | J28: Page 2 | K28: Marks | L28: Answers | M28: Pure 1 Ch1 | N28: Page 5 | O28: Marks | P28: P2
A29: P2.6 | B29: Simplifying algebraic fractions (factorising and cancelling) | C29: 2 | F29: ▶ Watch | G29: none on this topic | I29: Solomon: Rational expressions (Yr 2) | J29: Q 1, 4 | K29: none | L29: Answers | M29: Pure 1 Ch7 | N29: none | P29: P2
A30: P2.6 | B30: Algebraic division | C30: 1 | F30: ▶ Watch | G30: Q 1, 2, 25, 29, 33 | H30: Answers | I30: Factor Theorem | J30: Page 1 | K30: Marks | L30: Answers | M30: Pure 1 Ch7 | N30: Pages 1, 3, 4, 6, 8, 13 | O30: Marks | P30: P2
A31: P2.6 | B31: The factor theorem | C31: 1 | F31: ▶ Watch | G31: Q 1–6, 21, 33 | H31: Answers | I31: Factor Theorem | J31: Pages 1–3, 5 | K31: Marks | L31: Answers | M31: Pure 1 Ch7 | N31: Pages 1, 3, 4, 6, 8, 13 | O31: Marks | P31: P2
A32: P2.6 | B32: Adding, subtracting, multiplying and dividing algebraic fractions | C32: 2 | F32: ▶ Watch | G32: Q 18, 19 | H32: Answers | I32: Solomon: Rational expressions (Yr 2) | J32: Q 2, 3, 5, 6, 8–10, 13 | K32: none | L32: Answers | M32: Pure 2 Ch1 | N32: Page 15 | O32: Marks | P32: P2
A33: P2.6 | B33: Algebraic division of improper fractions | C33: 2 | F33: ▶ Watch | G33: Q 5–9 | H33: Answers | I33: Composite & Inverse Functions (Yr 2) | J33: Page 2 | K33: Marks | L33: Answers | M33: Pure 2 Ch1 | N33: Page 10 | O33: Marks | P33: P2
A34: P2.7 | B34: Sketching cubic graphs | C34: 1 | F34: ▶ Watch | G34: Q 1, 7, 8, 15, 16, 18, 20, 21 | H34: Answers | I34: Transformations & Graphs | J34: Page 3 | K34: Marks | L34: Answers | M34: Pure 1 Ch4 | N34: Pages 5, 11 | O34: Marks | P34: P2
A35: P2.7 | B35: Sketching quartic graphs | C35: 1 | F35: ▶ Watch | G35: none on this topic | I35: Solomon: Graphs of functions | J35: Q 1 | K35: none | L35: Answers | M35: Pure 1 Ch4 | N35: none | P35: P2
A36: P2.7 | B36: Reciprocal graphs y = a/x and y = a/x² (asymptotes) | C36: 1 | F36: ▶ Watch | G36: Q 2, 6, 13, 14, 16, 23 | H36: Answers | I36: Transformations & Graphs | J36: Page 1 | K36: Marks | L36: Answers | M36: Pure 1 Ch4 | N36: Page 2 | O36: Marks | P36: P2
A37: P2.7 | B37: Points of intersection and solving equations graphically | C37: 1 | F37: ▶ Watch | G37: Q 2, 12, 23 | H37: Answers | I37: Transformations & Graphs | J37: Pages 3, 4 | K37: Marks | L37: Answers | M37: Pure 1 Ch4 | N37: Pages 2, 3, 11 | O37: Marks | P37: P2
A38: P2.7 | B38: Proportional relationships and their graphs | C38: 1 | F38: ▶ Watch | G38: none on this topic | I38: none for this topic | J38: none on this topic | M38: Pure 1 Ch4 | N38: none | P38: P2
A39: P2.7 | B39: The modulus function and its graph y = |ax + b| | C39: 2 | F39: ▶ Watch | G39: Q 7, 10, 16–18, 22, 30 | H39: Answers | I39: Modulus of Functions (Yr 2) | J39: Page 1 | K39: Marks | L39: Answers | M39: Pure 2 Ch2 | N39: Pages 1, 3, 5, 6, 8, 10 | O39: Marks | P39: P2
A40: P2.7 | B40: Solving modulus equations and inequalities | C40: 2 | F40: ▶ Watch | G40: Q 7, 8, 16, 22, 25, 28, 30, 34 | H40: Answers | I40: Modulus of Functions (Yr 2) | J40: Pages 1–3 | K40: Marks | L40: Answers | M40: Pure 2 Ch2 | N40: Pages 1, 3, 5, 8–10 | O40: Marks | P40: P2
A41: P2.8 | B41: Functions and mappings: domain and range | C41: 2 | F41: ▶ Watch | G41: Q 6, 11, 20, 21, 23, 24, 29 | H41: Answers | I41: Composite & Inverse Functions (Yr 2) | J41: Page 2 | K41: Marks | L41: Answers | M41: Pure 2 Ch2 | N41: Pages 3, 8–10, 13, 15 | O41: Marks | P41: P2
A42: P2.8 | B42: Composite functions | C42: 2 | F42: ▶ Watch | G42: Q 1, 4, 8, 12, 26, 29, 32 | H42: Answers | I42: Composite & Inverse Functions (Yr 2) | J42: Pages 1–3 | K42: Marks | L42: Answers | M42: Pure 2 Ch2 | N42: Pages 1, 5, 7–9, 12, 14, 16 | O42: Marks | P42: P2
A43: P2.8 | B43: Inverse functions and their graphs | C43: 2 | F43: ▶ Watch | G43: Q 2, 5, 8, 13, 19, 27, 31, 33 | H43: Answers | I43: Composite & Inverse Functions (Yr 2) | J43: Pages 1–3 | K43: Marks | L43: Answers | M43: Pure 2 Ch2 | N43: Pages 1, 4, 8–11, 14, 15 | O43: Marks | P43: P2
...

Sheet Statistics
A1: Statistics
A2: Paper 3, Section A · 42 topics · pick R, A or G in the yellow Rating column for each one
A3: ="Rated so far: "&(COUNTIF($D$7:$D$58,"R")+COUNTIF($D$7:$D$58,"A")+COUNTIF($D$7:$D$58,"G"))&" of 42 Red "&COUNTIF($D$7:$D$58,"R")&" · Amber "&COUNTIF($D$7:$D$58,"A")&" · Green "&COUNTIF($D$7:$D$58,"G")
A5: Your check | F5: Maths Genie | I5: PMT worksheet | M5: Textbook chapter test
A6: Ref | B6: Topic | C6: Year | D6: Rating | E6: Notes | F6: Video | G6: Questions | H6: Answers | I6: Worksheet | J6: Questions | K6: Mark scheme | L6: Answers | M6: Textbook | N6: Questions | O6: Mark scheme
A8: 1 | B8: Statistical sampling | E8: 3 topics · Year 1: 3
A9: S1.1 | B9: Populations, samples and census | C9: 1 | F9: ▶ Watch | G9: Q 2, 3 | H9: Answers | I9: Set A: Sampling methods 1 | J9: Pages 1–5 | K9: in the PDF | L9: in the PDF | M9: Applied 1 Ch1 | N9: Page 11 | O9: Marks | P9: S1
A10: S1.1 | B10: Random sampling: simple random, systematic, stratified | C10: 1 | F10: ▶ Watch | G10: Q 1, 4, 6, 7 | H10: Answers | I10: Set A: Sampling methods 2 | J10: Pages 1–5 | K10: in the PDF | L10: in the PDF | M10: Applied 1 Ch1 | N10: Page 2 | O10: Marks | P10: S1
A11: S1.1 | B11: Non-random sampling: quota and opportunity | C11: 1 | F11: ▶ Watch | G11: Q 1, 3, 5 | H11: Answers | I11: Set A: Sampling methods 2 | J11: Pages 2–5 | K11: in the PDF | L11: in the PDF | M11: Applied 1 Ch1 | N11: Page 5 | O11: Marks | P11: S1
A13: 2 | B13: Data presentation and interpretation | E13: 14 topics · Year 1: 13 · Year 2: 1
A14: S2.3 | B14: Types of data (qualitative, discrete, continuous, grouped) | C14: 1 | F14: ▶ Watch | G14: none on this topic | I14: none for this topic | J14: none on this topic | M14: Applied 1 Ch1 | N14: none | P14: S2
A15: S2.3 | B15: Mean, median and mode (incl. grouped data) | C15: 1 | F15: ▶ Watch | G15: Q 1–4 | H15: Answers | I15: Data Presentation | J15: Pages 1–3 | K15: Marks | L15: Answers | M15: Applied 1 Ch2 | N15: Pages 1, 3, 8, 9, 11–13, 16 | O15: Marks | P15: S2
A16: S2.3 | B16: Quartiles, percentiles and interpolation | C16: 1 | F16: ▶ Watch | G16: Q 1–4 | H16: Answers | I16: Data Presentation | J16: Pages 1, 2 | K16: Marks | L16: Answers | M16: Applied 1 Ch2 | N16: Pages 1, 3, 8, 9, 11, 12, 16 | O16: Marks | P16: S2
A17: S2.3 | B17: Range, IQR, variance and standard deviation | C17: 1 | F17: ▶ Watch | G17: Q 1–7 | H17: Answers | I17: Large data sets (Yr 2) | J17: Pages 1–4 | K17: Marks | L17: Answers | M17: Applied 1 Ch2 | N17: Pages 2, 3, 5, 6, 9, 12, 13 | O17: Marks | P17: S2
A18: S2.3 | B18: Coding | C18: 1 | F18: ▶ Watch | G18: Q 2 | H18: Answers | I18: Large data sets (Yr 2) | J18: Page 1 | K18: Marks | L18: Answers | M18: Applied 1 Ch2 | N18: Page 13 | O18: Marks | P18: S2
A19: S2.1 | B19: Box plots | C19: 1 | F19: ▶ Watch | G19: Q 5–7, 9 | H19: Answers | I19: Set A: Representation and summary data | J19: Pages 13, 19, 24–26, 30, 32, 33 | K19: in the PDF | L19: in the PDF | M19: Applied 1 Ch3 | N19: Pages 2, 8, 15 | O19: Marks | P19: S2
A20: S2.1 | B20: Cumulative frequency diagrams | C20: 1 | F20: ▶ Watch | G20: none on this topic | I20: none for this topic | J20: none on this topic | M20: Applied 1 Ch3 | N20: none | P20: S2
A21: S2.1 | B21: Histograms (frequency density) and frequency polygons | C21: 1 | F21: ▶ Watch | G21: Q 1–4, 10 | H21: Answers | I21: Data Presentation | J21: Pages 1–4 | K21: Marks | L21: Answers | M21: Applied 1 Ch3 | N21: Pages 1, 4, 7, 10–12, 14, 16 | O21: Marks | P21: S2
A22: S2.4 | B22: Outliers and cleaning data | C22: 1 | F22: ▶ Watch | G22: Q 5–7, 9 | H22: Answers | I22: Data Presentation | J22: Page 1 | K22: Marks | L22: Answers | M22: Applied 1 Ch3 | N22: Pages 1, 3, 8, 15 | O22: Marks | P22: S2
A23: S2.4 | B23: Comparing distributions | C23: 1 | F23: ▶ Watch | G23: Q 7, 8 | H23: Answers | I23: Large data sets | J23: Page 5 | K23: Marks | L23: Answers | M23: Applied 1 Ch3 | N23: Pages 8, 16 | O23: Marks | P23: S2
A24: S2.2 | B24: Scatter diagrams and correlation (correlation vs causation) | C24: 1 | F24: ▶ Watch | G24: Q 1, 2 | H24: Answers | I24: Regression and Correlation | J24: Pages 1, 2, 4 | K24: Marks | L24: Answers | M24: Applied 1 Ch4 | N24: Pages 1, 3, 5 | O24: Marks | P24: S2
A25: S2.2 | B25: Linear regression lines (interpolation and extrapolation) | C25: 1 | F25: ▶ Watch | G25: Q 2, 3 | H25: Answers | I25: Regression and Correlation | J25: Page 1 | K25: Marks | L25: Answers | M25: Applied 1 Ch4 | N25: Pages 1, 2, 5 | O25: Marks | P25: S2
A26: S2.2 | B26: Exponential models and log coding (y = axⁿ, y = kbˣ) | C26: 2 | F26: ▶ Watch | G26: Q 6–9 | H26: Answers | I26: Regression and Correlation | J26: Page 4 | K26: Marks | L26: Answers | M26: Applied 2 Ch1 | N26: none | P26: S2
A27: LDS | B27: The large data set (context and familiarity) | C27: 1 | F27: ▶ Watch | G27: none on this topic | I27: Large data sets | J27: Pages 1, 2, 4–6 | K27: Marks | L27: Answers | M27: Applied 1 Ch1 | N27: Pages 2, 3, 6 | O27: Marks | P27: S2
A29: 3 | B29: Probability | E29: 10 topics · Year 1: 4 · Year 2: 6
A30: S3.1 | B30: Calculating probabilities and sample spaces | C30: 1 | F30: ▶ Watch | G30: Q 3, 5, 6 | H30: Answers | I30: Probability | J30: Pages 2, 4 | K30: Marks | L30: Answers | M30: Applied 1 Ch5 | N30: Pages 1, 4, 6 | O30: Marks | P30: S3
A31: S3.1 | B31: Venn diagrams | C31: 1 | F31: ▶ Watch | G31: Q 1–7 | H31: Answers | I31: Probability | J31: Pages 5, 9, 11 | K31: Marks | L31: Answers | M31: Applied 1 Ch5 | N31: Pages 3, 5, 7, 9 | O31: Marks | P31: S3
A32: S3.1 | B32: Mutually exclusive and independent events | C32: 1 | F32: ▶ Watch | G32: Q 1, 2, 4–6 | H32: Answers | I32: Probability | J32: Pages 5, 11 | K32: Marks | L32: Answers | M32: Applied 1 Ch5 | N32: Pages 3, 5, 7 | O32: Marks | P32: S3
A33: S3.1 | B33: Tree diagrams | C33: 1 | F33: ▶ Watch | G33: Q 5, 6 | H33: Answers | I33: Probability | J33: Page 2 | K33: Marks | L33: Answers | M33: Applied 1 Ch5 | N33: Pages 1, 6, 8 | O33: Marks | P33: S3
A34: S3.1 | B34: Set notation for probability | C34: 2 | F34: ▶ Watch | G34: Q 1–4 | H34: Answers | I34: Probability (Yr 2) | J34: Pages 3, 5, 6 | K34: Marks | L34: Answers | M34: Applied 2 Ch2 | N34: Pages 6–8, 11, 15, 19 | O34: Marks | P34: S3
A35: S3.2 | B35: Conditional probability (incl. two-way tables) | C35: 2 | F35: ▶ Watch | G35: Q 1, 2, 4–8, 10 | H35: Answers | I35: Conditional Probability (Yr 2) | J35: Pages 1, 2, 5 | K35: Marks | L35: Answers | M35: Applied 2 Ch2 | N35: Pages 9, 10, 12, 14, 16–18, 21 | O35: Marks | P35: S3
A36: S3.2 | B36: Conditional probability with Venn diagrams | C36: 2 | F36: ▶ Watch | G36: Q 7, 10 | H36: Answers | I36: Conditional Probability (Yr 2) | J36: Pages 1, 2, 4 | K36: Marks | L36: Answers | M36: Applied 2 Ch2 | N36: Pages 4, 7, 9, 14, 16, 19, 20 | O36: Marks | P36: S3
A37: S3.2 | B37: Probability formulae: P(A ∪ B) and P(A | B) | C37: 2 | F37: ▶ Watch | G37: Q 1–4 | H37: Answers | I37: Probability (Yr 2) | J37: Pages 5, 6 | K37: Marks | L37: Answers | M37: Applied 2 Ch2 | N37: Pages 6, 7, 11, 15, 19 | O37: Marks | P37: S3
A38: S3.2 | B38: Conditional probability with tree diagrams | C38: 2 | F38: ▶ Watch | G38: Q 5, 6, 8 | H38: Answers | I38: Set A: Probability (Yr 2) | J38: Pages 1, 4, 8, 11, 19 | K38: in the PDF | L38: in the PDF | M38: Applied 2 Ch2 | N38: Pages 8, 10, 17, 18 | O38: Marks | P38: S3
A39: S3.3 | B39: Modelling with probability: critiquing assumptions (e.g. a fair die) | C39: 2 | F39: ▶ Watch | G39: Q 12, 14 | H39: Answers | I39: Conditional Probability (Yr 2) | J39: Page 5 | K39: Marks | L39: Answers | M39: Applied 2 Ch2 | N39: Pages 1, 2 | O39: Marks | P39: S3
A41: 4 | B41: Statistical distributions | E41: 8 topics · Year 1: 3 · Year 2: 5
A42: S4.1 | B42: Discrete random variables, probability distributions and the discrete uniform distribution | C42: 1 | F42: ▶ Watch | G42: Q 1–4, 9, 11, 13, 15 | H42: Answers | I42: Probability | J42: Pages 4, 6, 8 | K42: Marks | L42: Answers | M42: Applied 1 Ch6 | N42: Pages 1, 2, 5 | O42: Marks | P42: S4
A43: S4.1 | B43: The binomial distribution B(n, p) | C43: 1 | F43: ▶ Watch | G43: Q 5–8, 10, 12, 14 | H43: Answers | I43: Binomial Distribution | J43: Pages 1, 3–5 | K43: Marks | L43: Answers | M43: Applied 1 Ch6 | N43: Pages 1, 2, 4–6 | O43: Marks | P43: S4
A44: S4.1 | B44: Cumulative binomial probabilities | C44: 1 | F44: ▶ Watch | G44: Q 5–8, 10, 14 | H44: Answers | I44: Binomial Distribution | J44: Pages 1, 3–5 | K44: Marks | L44: Answers | M44: Applied 1 Ch6 | N44: Pages 1, 2, 4–6 | O44: Marks | P44: S4
A45: S4.2 | B45: The normal distribution: properties (incl. inflection at μ ± σ) and finding probabilities | C45: 2 | F45: ▶ Watch | G45: Q 1, 2, 8, 9, 11 | H45: Answers | I45: Normal Distribution (Yr 2) | J45: Page 1 | K45: Marks | L45: Answers | M45: Applied 2 Ch3 | N45: Pages 1, 19–24, 26 | O45: Marks | P45: S4
...

Sheet Mechanics
A1: Mechanics
A2: Paper 3, Section B · 36 topics · pick R, A or G in the yellow Rating column for each one
A3: ="Rated so far: "&(COUNTIF($D$7:$D$50,"R")+COUNTIF($D$7:$D$50,"A")+COUNTIF($D$7:$D$50,"G"))&" of 36 Red "&COUNTIF($D$7:$D$50,"R")&" · Amber "&COUNTIF($D$7:$D$50,"A")&" · Green "&COUNTIF($D$7:$D$50,"G")
A5: Your check | F5: Maths Genie | I5: PMT worksheet | M5: Textbook chapter test
A6: Ref | B6: Topic | C6: Year | D6: Rating | E6: Notes | F6: Video | G6: Questions | H6: Answers | I6: Worksheet | J6: Questions | K6: Mark scheme | L6: Answers | M6: Textbook | N6: Questions | O6: Mark scheme
A8: 6 | B8: Quantities and units in mechanics | E8: 2 topics · Year 1: 2
A9: M6.1 | B9: SI units and derived quantities | C9: 1 | F9: ▶ Watch | G9: Q 3 | H9: Answers | I9: Motion Graphs (Yr 2) | J9: Page 1 | K9: Marks | L9: Answers | M9: Applied 1 Ch8 | N9: Page 11 | O9: Marks | P9: M6
A10: OT3.5 | B10: Modelling assumptions (particle, light, inextensible, smooth, rigid) | C10: 1 | F10: ▶ Watch | G10: Q 16, 17 | H10: Answers | I10: suvat | J10: Pages 1–3, 7 | K10: Marks | L10: Answers | M10: Applied 1 Ch8 | N10: Pages 2, 3 | O10: Marks | P10: M6
A12: 7 | B12: Kinematics | E12: 15 topics · Year 1: 10 · Year 2: 5
A13: M7.1 | B13: Language of kinematics: position, displacement, distance, velocity, speed, acceleration | C13: 1 | F13: ▶ Watch | G13: none on this topic | I13: suvat | J13: Page 1 | K13: Marks | L13: Answers | M13: Applied 1 Ch9 | N13: Page 9 | O13: Marks | P13: M7
A14: M7.2 | B14: Displacement-time graphs | C14: 1 | F14: ▶ Watch | G14: none on this topic | I14: none for this topic | J14: none on this topic | M14: Applied 1 Ch9 | N14: none | P14: M7
A15: M7.2 | B15: Velocity-time graphs (gradient and area) | C15: 1 | F15: ▶ Watch | G15: Q 1–4 | H15: Answers | I15: Motion Graphs | J15: Pages 1, 2 | K15: Marks | L15: Answers | M15: Applied 1 Ch9 | N15: Pages 2–7, 9, 12 | O15: Marks | P15: M7
A16: M7.3 | B16: Constant acceleration (suvat) formulae | C16: 1 | F16: ▶ Watch | G16: Q 1, 3, 5–7, 9 | H16: Answers | I16: suvat | J16: Pages 1–3, 5 | K16: Marks | L16: Answers | M16: Applied 1 Ch9 | N16: Pages 1, 3–7, 10, 11 | O16: Marks | P16: M7
A17: M7.3 | B17: suvat: multi-stage and two-particle problems | C17: 1 | F17: ▶ Watch | G17: Q 11–14, 16 | H17: Answers | I17: Motion Graphs | J17: Pages 1, 2 | K17: Marks | L17: Answers | M17: Applied 1 Ch9 | N17: Pages 2–7, 9, 12 | O17: Marks | P17: M7
A18: M7.3 | B18: Vertical motion under gravity (suvat with g) | C18: 1 | F18: ▶ Watch | G18: Q 2, 4, 8, 10, 15, 17 | H18: Answers | I18: suvat | J18: Pages 1–3 | K18: Marks | L18: Answers | M18: Applied 1 Ch9 | N18: Pages 1–3, 5, 7, 10, 11 | O18: Marks | P18: M7
A19: M7.4 | B19: Variable acceleration: using differentiation | C19: 1 | F19: ▶ Watch | G19: Q 4, 5, 8, 9, 11 | H19: Answers | I19: Calculus in Kinematics | J19: Pages 1–3 | K19: Marks | L19: Answers | M19: Applied 1 Ch11 | N19: Pages 1–4 | O19: Marks | P19: M7
A20: M7.4 | B20: Variable acceleration: maxima and minima | C20: 1 | F20: ▶ Watch | G20: Q 5, 6, 8 | H20: Answers | I20: Set A: Problems with calculus | J20: Pages 1, 2 | K20: in the PDF | L20: in the PDF | M20: Applied 1 Ch11 | N20: Pages 1, 3 | O20: Marks | P20: M7
A21: M7.4 | B21: Variable acceleration: using integration | C21: 1 | F21: ▶ Watch | G21: Q 1–4, 6, 7, 10, 12 | H21: Answers | I21: Calculus in Kinematics | J21: Pages 1, 3 | K21: Marks | L21: Answers | M21: Applied 1 Ch11 | N21: Pages 5, 7–10 | O21: Marks | P21: M7
A22: M7.3 | B22: Deriving the suvat formulae (using graphs or calculus) | C22: 1 | F22: ▶ Watch | G22: none on this topic | I22: Set B: Motion Graphs | J22: Page 1 | K22: none | L22: Answers | M22: Applied 1 Ch11 | N22: Page 1 | O22: Marks | P22: M7
A23: M7.3 | B23: Constant acceleration in 2D with vectors | C23: 2 | F23: ▶ Watch | G23: Q 1, 2, 6, 16, 18, 19 | H23: Answers | I23: suvat (Yr 2) | J23: Pages 1, 3 | K23: Marks | L23: Answers | M23: Applied 2 Ch8 | N23: Pages 1, 3, 4, 6, 8, 10, 12, 13 | O23: Marks | P23: M7
A24: M7.4 | B24: Variable acceleration in 2D: differentiating and integrating vectors | C24: 2 | F24: ▶ Watch | G24: Q 11–15, 17, 20, 21 | H24: Answers | I24: Calculus in Kinematics (Yr 2) | J24: Pages 1–4 | K24: Marks | L24: Answers | M24: Applied 2 Ch8 | N24: Pages 1, 3, 4, 6, 11 | O24: Marks | P24: M7
A25: M7.5 | B25: Projectiles: horizontal projection | C25: 2 | F25: ▶ Watch | G25: none on this topic | I25: Set A: Projectiles 2 (Yr 2) | J25: Page 9 | K25: in the PDF | L25: in the PDF | M25: Applied 2 Ch6 | N25: Page 6 | O25: Marks | P25: M7
A26: M7.5 | B26: Projectiles at any angle (horizontal and vertical components) | C26: 2 | F26: ▶ Watch | G26: Q 1–5, 7–9 | H26: Answers | I26: Projectiles (Yr 2) | J26: Pages 1–3 | K26: Marks | L26: Answers | M26: Applied 2 Ch6 | N26: Pages 1, 3, 4, 7, 10–12, 14 | O26: Marks | P26: M7
A27: M7.5 | B27: Projectile formulae: time of flight, range, maximum height, equation of the path | C27: 2 | F27: ▶ Watch | G27: Q 1, 3, 5, 6 | H27: Answers | I27: Projectiles (Yr 2) | J27: Pages 1–3 | K27: Marks | L27: Answers | M27: Applied 2 Ch6 | N27: Pages 1, 3, 6, 10, 13 | O27: Marks | P27: M7
A29: 8 | B29: Forces and Newton's laws | E29: 13 topics · Year 1: 6 · Year 2: 7
A30: M8.1 | B30: Force diagrams, types of force and Newton's first law | C30: 1 | F30: ▶ Watch | G30: Q 6 | H30: Answers | I30: none for this topic | J30: none on this topic | M30: Applied 1 Ch10 | N30: none | P30: M8
A31: M8.2 | B31: Forces as vectors in i, j form | C31: 1 | F31: ▶ Watch | G31: Q 6, 9, 12 | H31: Answers | I31: Forces & Newton's Laws | J31: Page 4 | K31: Marks | L31: Answers | M31: Applied 1 Ch10 | N31: Pages 6, 9, 12, 13 | O31: Marks | P31: M8
A32: M8.2 | B32: Newton's second law F = ma (incl. weight, M8.3) | C32: 1 | F32: ▶ Watch | G32: Q 3–5 | H32: Answers | I32: Forces & Newton's Laws | J32: Pages 1, 2, 5 | K32: Marks | L32: Answers | M32: Applied 1 Ch10 | N32: Pages 10, 11 | O32: Marks | P32: M8
A33: M8.2 | B33: F = ma in 2D with vectors | C33: 1 | F33: ▶ Watch | G33: Q 7, 8 | H33: Answers | I33: Forces & Newton's Laws | J33: Page 4 | K33: Marks | L33: Answers | M33: Applied 1 Ch10 | N33: Pages 6, 9, 12, 13 | O33: Marks | P33: M8
A34: M8.4 | B34: Connected particles (incl. Newton's third law) | C34: 1 | F34: ▶ Watch | G34: Q 3–5 | H34: Answers | I34: Forces & Newton's Laws | J34: Pages 1, 2 | K34: Marks | L34: Answers | M34: Applied 1 Ch10 | N34: Page 11 | O34: Marks | P34: M8
A35: M8.4 | B35: Pulleys | C35: 1 | F35: ▶ Watch | G35: Q 1, 2, 13–15 | H35: Answers | I35: Connected Particles (Yr 2) | J35: Page 1 | K35: Marks | L35: Answers | M35: Applied 1 Ch10 | N35: Pages 1–4, 10 | O35: Marks | P35: M8
A36: M8.5 | B36: Resolving forces and resultant forces (magnitude-direction form) | C36: 2 | F36: ▶ Watch | G36: Q 1–3, 8 | H36: Answers | I36: Forces & Newton's Laws | J36: Pages 3, 6 | K36: Marks | L36: Answers | M36: Applied 2 Ch5 | N36: Pages 1, 5, 7, 16 | O36: Marks | P36: M8
A37: M8.2 | B37: Inclined planes | C37: 2 | F37: ▶ Watch | G37: Q 4–7, 9, 10 | H37: Answers | I37: F = ma on a slope (Yr 2) | J37: Pages 1, 2 | K37: Marks | L37: Answers | M37: Applied 2 Ch5 | N37: Pages 3, 4, 7, 11, 16 | O37: Marks | P37: M8
A38: M8.6 | B38: Friction (F ≤ μR) and limiting friction | C38: 2 | F38: ▶ Watch | G38: Q 3–10 | H38: Answers | I38: Forces & Newton's Laws | J38: Pages 3, 5 | K38: Marks | L38: Answers | M38: Applied 2 Ch5 | N38: Pages 1, 3–5, 7, 11, 16 | O38: Marks | P38: M8
A39: M8.4 | B39: Statics: particles in equilibrium | C39: 2 | F39: ▶ Watch | G39: Q 1, 2 | H39: Answers | I39: Forces & Newton's Laws | J39: Page 3 | K39: Marks | L39: Answers | M39: Applied 2 Ch7 | N39: Pages 3, 7, 10, 16 | O39: Marks | P39: M8
A40: M8.6 | B40: Friction and static particles (limiting equilibrium) | C40: 2 | F40: ▶ Watch | G40: Q 3, 4, 6, 7, 10 | H40: Answers | I40: Forces & Newton's Laws | J40: Page 3 | K40: Marks | L40: Answers | M40: Applied 2 Ch7 | N40: Pages 3, 4, 7, 9, 10, 16 | O40: Marks | P40: M8
A41: M8.2 | B41: Dynamics on inclined planes | C41: 2 | F41: ▶ Watch | G41: Q 5, 9, 10 | H41: Answers | I41: F = ma on a slope (Yr 2) | J41: Pages 1, 2 | K41: Marks | L41: Answers | M41: Applied 2 Ch7 | N41: Pages 4, 6, 11, 16 | O41: Marks | P41: M8
A42: M8.4 | B42: Connected particles on slopes and with friction | C42: 2 | F42: ▶ Watch | G42: Q 6–8, 10 | H42: Answers | I42: Connected Particles (Yr 2) | J42: Page 2 | K42: Marks | L42: Answers | M42: Applied 2 Ch7 | N42: Pages 6, 8–10, 12, 15, 17 | O42: Marks | P42: M8
A44: 9 | B44: Moments | E44: 6 topics · Year 2: 6
A45: M9.1 | B45: Moments of a force | C45: 2 | F45: ▶ Watch | G45: Q 1, 2 | H45: Answers | I45: Moments (Yr 2) | J45: Page 3 | K45: Marks | L45: Answers | M45: Applied 2 Ch4 | N45: Pages 1, 2, 11 | O45: Marks | P45: M9
...

Sheet Chapter tests
A1: Chapter tests
A2: Real Edexcel exam questions for each textbook chapter, plus the textbook review exercises. Try one once every topic in it is Amber or Green. A few sets include old-specification questions: they are listed in the last column, so skip them.
A4: Book | B4: Chapters | C4: Test | D4: Questions | E4: Mark scheme | F4: Done? | G4: Score / notes | H4: Skip (not on the current spec)
A6: Pure maths | C6: Paper 1 and Paper 2
A7: Pure 1 | B7: Ch1 Algebraic Expression | C7: Ch1 Algebraic Expression Exam Questions | D7: Questions | E7: Marks
A8: Pure 1 | B8: Ch2 Quadratics, Ch3 Equations and Inequalities | C8: Ch2 Quadratics and Ch3 Equations and Inequalities Exam Questions | D8: Questions | E8: Marks
A9: Pure 1 | B9: Ch1-Ch4 review (textbook) | C9: Textbook review exercise 1 - pg.85-88 | D9: in the book
A10: Pure 1 | B10: Ch5 Straight Line Graphs | C10: Ch5 Straight Line Graphs Exam Questions | D10: Questions | E10: Marks
A11: Pure 1 | B11: Ch6 Circles | C11: Ch6 Circles Exam Questions | D11: Questions | E11: Marks
A12: Pure 1 | B12: Ch4 Graphs and Transformations, Ch7 Algebraic Methods | C12: Ch4 Graphs and Transformations + Ch7 Algebraic Methods Exam Questions 1 | D12: Questions | E12: Marks
A13: Pure 1 | B13: Ch4 Graphs and Transformations, Ch7 Algebraic Methods | C13: Ch4 Graphs and Transformations + Ch7 Algebraic Methods Exam Questions 2 | D13: Questions | E13: Marks
A14: Pure 1 | B14: Ch8 Binomial Expansion | C14: Ch8 Binomial Expansion Exam Questions | D14: Questions | E14: Marks
A15: Pure 1 | B15: Ch9 Trigonometric ratios | C15: Ch9 Trigonometric Ratos Exam Questions | D15: Questions | E15: Marks
A16: Pure 1 | B16: Ch10 Trigonometric Identities and Equations | C16: Ch10 Trigonometric Identities and Equations Exam Questions | D16: Questions | E16: Marks
A17: Pure 1 | B17: Ch5-Ch10 review (textbook) | C17: Textbook review exercise 2 - pg.226 - 229 | D17: in the book
A18: Pure 1 | B18: Ch11 Vectors | C18: Ch11 Vectors Exam Questions | D18: Questions | E18: Marks
A19: Pure 1 | B19: Ch12 Differentiation | C19: Ch12 Differentiation Exam Questions | D19: Questions | E19: Marks
A20: Pure 1 | B20: Ch12 Differentiation | C20: Ch12 Differentiation: optimisation exam questions (filed on the source site as Pure 2 Ch9 set 3) | D20: Questions | E20: Marks
A21: Pure 1 | B21: Ch13 Integration | C21: Ch13 Integration Exam Question | D21: Questions | E21: Marks
A22: Pure 1 | B22: Ch14 Exponential and Logarithms | C22: Ch14 Exponential and Logarithms Exam Questions 1 | D22: Questions | E22: Marks
A23: Pure 1 | B23: Ch14 Exponential and Logarithms | C23: Ch14 Exponential and Logarithms Exam Questions 2 | D23: Questions | E23: Marks
A24: Pure 1 | B24: Ch11-Ch14 review (textbook) | C24: Textbook review exercise 3 - pg.338-341 | D24: in the book
A25: Pure 2 | B25: Ch1 Algebraic Methods | C25: Ch1 Algebraic Methods Exam Questions | D25: Questions | E25: Marks
A26: Pure 2 | B26: Ch2 Functions and Graphs | C26: Ch2 Functions and Graphs Exam Questions 1 | D26: Questions | E26: Marks
A27: Pure 2 | B27: Ch2 Functions and Graphs | C27: Ch2 Functions and Graphs Exam Questions 2 | D27: Questions | E27: Marks
A28: Pure 2 | B28: Ch3 Sequences and Series | C28: Ch3 Sequences and Series Exam Questions 1 | D28: Questions | E28: Marks
A29: Pure 2 | B29: Ch3 Sequences and Series | C29: Ch3 Sequences and Series Exam Questions 2 | D29: Questions | E29: Marks
A30: Pure 2 | B30: Ch4 Binomial Expansion | C30: Ch4 Binomial Expansion Exam Questions | D30: Questions | E30: none
A31: Pure 2 | B31: Ch1-Ch4 review (textbook) | C31: Textbook review exercise 1 - pg.107-112 | D31: in the book
A32: Pure 2 | B32: Ch5 Radians | C32: Ch5 Radians Exam Questions | D32: Questions | E32: Marks
A33: Pure 2 | B33: Ch6 Trigonometric Functions, Ch7 Trigonometry and Modelling | C33: Ch6 Trigonometric Functions and Ch7 Trigonometry and Modelling Exam Questions 1 | D33: Questions | E33: Marks
A34: Pure 2 | B34: Ch6 Trigonometric Functions, Ch7 Trigonometry and Modelling | C34: Ch6 Trigonometric Functions and Ch7 Trigonometry and Modelling Exam Questions 2 | D34: Questions | E34: Marks
A35: Pure 2 | B35: Ch8 Parametric Equations | C35: Ch8 Parametric Equations Exam Questions | D35: Questions | E35: Marks
A36: Pure 2 | B36: Ch5-Ch8 review (textbook) | C36: Textbook review exercise 2 - pg.225-230 | D36: in the book
A37: Pure 2 | B37: Ch9 Differentiation | C37: Ch9 Differentiation Exam Questions 1 | D37: Questions | E37: Marks
A38: Pure 2 | B38: Ch9 Differentiation | C38: Ch9 Differentiation Exam Questions 2 | D38: Questions | E38: Marks
A39: Pure 2 | B39: Ch10 Numerical Methods | C39: Ch10 Numerical Methods Exam Questions | D39: Questions | E39: Marks
A40: Pure 2 | B40: Ch11 Integration | C40: Ch11 Integration Exam Questions 1 | D40: Questions | E40: Marks
A41: Pure 2 | B41: Ch11 Integration | C41: Ch11 Integration Exam Questions 2 | D41: Questions | E41: Marks | H41: p5 Q13(d), p9 Q8(b): volumes of revolution
A42: Pure 2 | B42: Ch11 Integration | C42: Ch11 Integration Exam Questions 3 | D42: Questions | E42: Marks
...

Sheet Progress
A1: Progress
A2: This page fills itself in from your ratings. Nothing to type here except the yellow cells, if you want to change them.
A4: =TEXT((COUNTIFS('Pure'!$D$7:$D$184,"R",'Pure'!$C$7:$C$184,">0")+COUNTIFS('Statistics'!$D$7:$D$58,"R",'Statistics'!$C$7:$C$58,">0")+COUNTIFS('Mechanics'!$D$7:$D$50,"R",'Mechanics'!$C$7:$C$50,">0")+COUNTIFS('Pure'!$D$7:$D$184,"A",'Pure'!$C$7:$C$184,">0")+COUNTIFS('Statistics'!$D$7:$D$58,"A",'Statistics'!$C$7:$C$58,">0")+COUNTIFS('Mechanics'!$D$7:$D$50,"A",'Mechanics'!$C$7:$C$50,">0")+COUNTIFS('Pure'!$D$7:$D$184,"G",'Pure'!$C$7:$C$184,">0")+COUNTIFS('Statistics'!$D$7:$D$58,"G",'Statistics'!$C$7:$C$58,">0")+COUNTIFS('Mechanics'!$D$7:$D$50,"G",'Mechanics'!$C$7:$C$50,">0"))/236,"0%") | C4: =COUNTIFS('Pure'!$D$7:$D$184,"R",'Pure'!$C$7:$C$184,">0")+COUNTIFS('Statistics'!$D$7:$D$58,"R",'Statistics'!$C$7:$C$58,">0")+COUNTIFS('Mechanics'!$D$7:$D$50,"R",'Mechanics'!$C$7:$C$50,">0") | E4: =COUNTIFS('Pure'!$D$7:$D$184,"A",'Pure'!$C$7:$C$184,">0")+COUNTIFS('Statistics'!$D$7:$D$58,"A",'Statistics'!$C$7:$C$58,">0")+COUNTIFS('Mechanics'!$D$7:$D$50,"A",'Mechanics'!$C$7:$C$50,">0") | G4: =COUNTIFS('Pure'!$D$7:$D$184,"G",'Pure'!$C$7:$C$184,">0")+COUNTIFS('Statistics'!$D$7:$D$58,"G",'Statistics'!$C$7:$C$58,">0")+COUNTIFS('Mechanics'!$D$7:$D$50,"G",'Mechanics'!$C$7:$C$50,">0")
A5: Topics rated (of 236) | C5: Red | E5: Amber | G5: Green
A7: Your practice plan
A8: Rating | B8: Topics | C8: Qs each | D8: Qs total | E8: What to do
A9: Red | B9: =COUNTIFS('Pure'!$D$7:$D$184,"R",'Pure'!$C$7:$C$184,">0")+COUNTIFS('Statistics'!$D$7:$D$58,"R",'Statistics'!$C$7:$C$58,">0")+COUNTIFS('Mechanics'!$D$7:$D$50,"R",'Mechanics'!$C$7:$C$50,">0") | C9: 10 | D9: =B9*C9 | E9: Full worksheet, taught first
A10: Amber | B10: =COUNTIFS('Pure'!$D$7:$D$184,"A",'Pure'!$C$7:$C$184,">0")+COUNTIFS('Statistics'!$D$7:$D$58,"A",'Statistics'!$C$7:$C$58,">0")+COUNTIFS('Mechanics'!$D$7:$D$50,"A",'Mechanics'!$C$7:$C$50,">0") | C10: 5 | D10: =B10*C10 | E10: Practise until 3 right in a row
A11: Green | B11: =COUNTIFS('Pure'!$D$7:$D$184,"G",'Pure'!$C$7:$C$184,">0")+COUNTIFS('Statistics'!$D$7:$D$58,"G",'Statistics'!$C$7:$C$58,">0")+COUNTIFS('Mechanics'!$D$7:$D$50,"G",'Mechanics'!$C$7:$C$50,">0") | C11: 2 | D11: =B11*C11 | E11: 2-question spot check
A12: Not rated yet | B12: =COUNTIFS('Pure'!$D$7:$D$184,"",'Pure'!$C$7:$C$184,">0")+COUNTIFS('Statistics'!$D$7:$D$58,"",'Statistics'!$C$7:$C$58,">0")+COUNTIFS('Mechanics'!$D$7:$D$50,"",'Mechanics'!$C$7:$C$50,">0")
A13: Total questions | D13: =SUM(D9:D11)
A14: Minutes per question | D14: 6
A15: Hours of practice | D15: =ROUND(D13*D14/60,1)
A16: Chapter tests done | D16: =COUNTIF('Chapter tests'!$F$5:$F$71,"Done")&" of 61"
A18: By year
B19: Topics | C19: Red | D19: Amber | E19: Green | F19: Not rated | G19: % Green
A20: Year 1 (AS content) | B20: =COUNTIFS('Pure'!$C$7:$C$184,1)+COUNTIFS('Statistics'!$C$7:$C$58,1)+COUNTIFS('Mechanics'!$C$7:$C$50,1) | C20: =COUNTIFS('Pure'!$C$7:$C$184,1,'Pure'!$D$7:$D$184,"R")+COUNTIFS('Statistics'!$C$7:$C$58,1,'Statistics'!$D$7:$D$58,"R")+COUNTIFS('Mechanics'!$C$7:$C$50,1,'Mechanics'!$D$7:$D$50,"R") | D20: =COUNTIFS('Pure'!$C$7:$C$184,1,'Pure'!$D$7:$D$184,"A")+COUNTIFS('Statistics'!$C$7:$C$58,1,'Statistics'!$D$7:$D$58,"A")+COUNTIFS('Mechanics'!$C$7:$C$50,1,'Mechanics'!$D$7:$D$50,"A") | E20: =COUNTIFS('Pure'!$C$7:$C$184,1,'Pure'!$D$7:$D$184,"G")+COUNTIFS('Statistics'!$C$7:$C$58,1,'Statistics'!$D$7:$D$58,"G")+COUNTIFS('Mechanics'!$C$7:$C$50,1,'Mechanics'!$D$7:$D$50,"G") | F20: =COUNTIFS('Pure'!$C$7:$C$184,1,'Pure'!$D$7:$D$184,"")+COUNTIFS('Statistics'!$C$7:$C$58,1,'Statistics'!$D$7:$D$58,"")+COUNTIFS('Mechanics'!$C$7:$C$50,1,'Mechanics'!$D$7:$D$50,"") | G20: =IFERROR(E20/B20,0)
A21: Year 2 | B21: =COUNTIFS('Pure'!$C$7:$C$184,2)+COUNTIFS('Statistics'!$C$7:$C$58,2)+COUNTIFS('Mechanics'!$C$7:$C$50,2) | C21: =COUNTIFS('Pure'!$C$7:$C$184,2,'Pure'!$D$7:$D$184,"R")+COUNTIFS('Statistics'!$C$7:$C$58,2,'Statistics'!$D$7:$D$58,"R")+COUNTIFS('Mechanics'!$C$7:$C$50,2,'Mechanics'!$D$7:$D$50,"R") | D21: =COUNTIFS('Pure'!$C$7:$C$184,2,'Pure'!$D$7:$D$184,"A")+COUNTIFS('Statistics'!$C$7:$C$58,2,'Statistics'!$D$7:$D$58,"A")+COUNTIFS('Mechanics'!$C$7:$C$50,2,'Mechanics'!$D$7:$D$50,"A") | E21: =COUNTIFS('Pure'!$C$7:$C$184,2,'Pure'!$D$7:$D$184,"G")+COUNTIFS('Statistics'!$C$7:$C$58,2,'Statistics'!$D$7:$D$58,"G")+COUNTIFS('Mechanics'!$C$7:$C$50,2,'Mechanics'!$D$7:$D$50,"G") | F21: =COUNTIFS('Pure'!$C$7:$C$184,2,'Pure'!$D$7:$D$184,"")+COUNTIFS('Statistics'!$C$7:$C$58,2,'Statistics'!$D$7:$D$58,"")+COUNTIFS('Mechanics'!$C$7:$C$50,2,'Mechanics'!$D$7:$D$50,"") | G21: =IFERROR(E21/B21,0)
A23: By paper
B24: Topics | C24: Red | D24: Amber | E24: Green | F24: Not rated | G24: % Green
A25: Pure maths (Paper 1 and Paper 2) | B25: =COUNTIFS('Pure'!$C$7:$C$184,">0") | C25: =COUNTIFS('Pure'!$C$7:$C$184,">0",'Pure'!$D$7:$D$184,"R") | D25: =COUNTIFS('Pure'!$C$7:$C$184,">0",'Pure'!$D$7:$D$184,"A") | E25: =COUNTIFS('Pure'!$C$7:$C$184,">0",'Pure'!$D$7:$D$184,"G") | F25: =COUNTIFS('Pure'!$C$7:$C$184,">0",'Pure'!$D$7:$D$184,"") | G25: =IFERROR(E25/B25,0)
A26: Statistics (Paper 3, Section A) | B26: =COUNTIFS('Statistics'!$C$7:$C$58,">0") | C26: =COUNTIFS('Statistics'!$C$7:$C$58,">0",'Statistics'!$D$7:$D$58,"R") | D26: =COUNTIFS('Statistics'!$C$7:$C$58,">0",'Statistics'!$D$7:$D$58,"A") | E26: =COUNTIFS('Statistics'!$C$7:$C$58,">0",'Statistics'!$D$7:$D$58,"G") | F26: =COUNTIFS('Statistics'!$C$7:$C$58,">0",'Statistics'!$D$7:$D$58,"") | G26: =IFERROR(E26/B26,0)
A27: Mechanics (Paper 3, Section B) | B27: =COUNTIFS('Mechanics'!$C$7:$C$50,">0") | C27: =COUNTIFS('Mechanics'!$C$7:$C$50,">0",'Mechanics'!$D$7:$D$50,"R") | D27: =COUNTIFS('Mechanics'!$C$7:$C$50,">0",'Mechanics'!$D$7:$D$50,"A") | E27: =COUNTIFS('Mechanics'!$C$7:$C$50,">0",'Mechanics'!$D$7:$D$50,"G") | F27: =COUNTIFS('Mechanics'!$C$7:$C$50,">0",'Mechanics'!$D$7:$D$50,"") | G27: =IFERROR(E27/B27,0)
A29: By topic area
B30: Topics | C30: Red | D30: Amber | E30: Green | F30: Not rated | G30: % Green
A31: Pure 1: Proof | B31: =COUNTIFS('Pure'!$P$7:$P$184,"P1") | C31: =COUNTIFS('Pure'!$P$7:$P$184,"P1",'Pure'!$D$7:$D$184,"R") | D31: =COUNTIFS('Pure'!$P$7:$P$184,"P1",'Pure'!$D$7:$D$184,"A") | E31: =COUNTIFS('Pure'!$P$7:$P$184,"P1",'Pure'!$D$7:$D$184,"G") | F31: =COUNTIFS('Pure'!$P$7:$P$184,"P1",'Pure'!$D$7:$D$184,"") | G31: =IFERROR(E31/B31,0)
A32: Pure 2: Algebra and functions | B32: =COUNTIFS('Pure'!$P$7:$P$184,"P2") | C32: =COUNTIFS('Pure'!$P$7:$P$184,"P2",'Pure'!$D$7:$D$184,"R") | D32: =COUNTIFS('Pure'!$P$7:$P$184,"P2",'Pure'!$D$7:$D$184,"A") | E32: =COUNTIFS('Pure'!$P$7:$P$184,"P2",'Pure'!$D$7:$D$184,"G") | F32: =COUNTIFS('Pure'!$P$7:$P$184,"P2",'Pure'!$D$7:$D$184,"") | G32: =IFERROR(E32/B32,0)
A33: Pure 3: Coordinate geometry in the (x, y) plane | B33: =COUNTIFS('Pure'!$P$7:$P$184,"P3") | C33: =COUNTIFS('Pure'!$P$7:$P$184,"P3",'Pure'!$D$7:$D$184,"R") | D33: =COUNTIFS('Pure'!$P$7:$P$184,"P3",'Pure'!$D$7:$D$184,"A") | E33: =COUNTIFS('Pure'!$P$7:$P$184,"P3",'Pure'!$D$7:$D$184,"G") | F33: =COUNTIFS('Pure'!$P$7:$P$184,"P3",'Pure'!$D$7:$D$184,"") | G33: =IFERROR(E33/B33,0)
A34: Pure 4: Sequences and series | B34: =COUNTIFS('Pure'!$P$7:$P$184,"P4") | C34: =COUNTIFS('Pure'!$P$7:$P$184,"P4",'Pure'!$D$7:$D$184,"R") | D34: =COUNTIFS('Pure'!$P$7:$P$184,"P4",'Pure'!$D$7:$D$184,"A") | E34: =COUNTIFS('Pure'!$P$7:$P$184,"P4",'Pure'!$D$7:$D$184,"G") | F34: =COUNTIFS('Pure'!$P$7:$P$184,"P4",'Pure'!$D$7:$D$184,"") | G34: =IFERROR(E34/B34,0)
A35: Pure 5: Trigonometry | B35: =COUNTIFS('Pure'!$P$7:$P$184,"P5") | C35: =COUNTIFS('Pure'!$P$7:$P$184,"P5",'Pure'!$D$7:$D$184,"R") | D35: =COUNTIFS('Pure'!$P$7:$P$184,"P5",'Pure'!$D$7:$D$184,"A") | E35: =COUNTIFS('Pure'!$P$7:$P$184,"P5",'Pure'!$D$7:$D$184,"G") | F35: =COUNTIFS('Pure'!$P$7:$P$184,"P5",'Pure'!$D$7:$D$184,"") | G35: =IFERROR(E35/B35,0)
A36: Pure 6: Exponentials and logarithms | B36: =COUNTIFS('Pure'!$P$7:$P$184,"P6") | C36: =COUNTIFS('Pure'!$P$7:$P$184,"P6",'Pure'!$D$7:$D$184,"R") | D36: =COUNTIFS('Pure'!$P$7:$P$184,"P6",'Pure'!$D$7:$D$184,"A") | E36: =COUNTIFS('Pure'!$P$7:$P$184,"P6",'Pure'!$D$7:$D$184,"G") | F36: =COUNTIFS('Pure'!$P$7:$P$184,"P6",'Pure'!$D$7:$D$184,"") | G36: =IFERROR(E36/B36,0)
A37: Pure 7: Differentiation | B37: =COUNTIFS('Pure'!$P$7:$P$184,"P7") | C37: =COUNTIFS('Pure'!$P$7:$P$184,"P7",'Pure'!$D$7:$D$184,"R") | D37: =COUNTIFS('Pure'!$P$7:$P$184,"P7",'Pure'!$D$7:$D$184,"A") | E37: =COUNTIFS('Pure'!$P$7:$P$184,"P7",'Pure'!$D$7:$D$184,"G") | F37: =COUNTIFS('Pure'!$P$7:$P$184,"P7",'Pure'!$D$7:$D$184,"") | G37: =IFERROR(E37/B37,0)
A38: Pure 8: Integration | B38: =COUNTIFS('Pure'!$P$7:$P$184,"P8") | C38: =COUNTIFS('Pure'!$P$7:$P$184,"P8",'Pure'!$D$7:$D$184,"R") | D38: =COUNTIFS('Pure'!$P$7:$P$184,"P8",'Pure'!$D$7:$D$184,"A") | E38: =COUNTIFS('Pure'!$P$7:$P$184,"P8",'Pure'!$D$7:$D$184,"G") | F38: =COUNTIFS('Pure'!$P$7:$P$184,"P8",'Pure'!$D$7:$D$184,"") | G38: =IFERROR(E38/B38,0)
A39: Pure 9: Numerical methods | B39: =COUNTIFS('Pure'!$P$7:$P$184,"P9") | C39: =COUNTIFS('Pure'!$P$7:$P$184,"P9",'Pure'!$D$7:$D$184,"R") | D39: =COUNTIFS('Pure'!$P$7:$P$184,"P9",'Pure'!$D$7:$D$184,"A") | E39: =COUNTIFS('Pure'!$P$7:$P$184,"P9",'Pure'!$D$7:$D$184,"G") | F39: =COUNTIFS('Pure'!$P$7:$P$184,"P9",'Pure'!$D$7:$D$184,"") | G39: =IFERROR(E39/B39,0)
A40: Pure 10: Vectors | B40: =COUNTIFS('Pure'!$P$7:$P$184,"P10") | C40: =COUNTIFS('Pure'!$P$7:$P$184,"P10",'Pure'!$D$7:$D$184,"R") | D40: =COUNTIFS('Pure'!$P$7:$P$184,"P10",'Pure'!$D$7:$D$184,"A") | E40: =COUNTIFS('Pure'!$P$7:$P$184,"P10",'Pure'!$D$7:$D$184,"G") | F40: =COUNTIFS('Pure'!$P$7:$P$184,"P10",'Pure'!$D$7:$D$184,"") | G40: =IFERROR(E40/B40,0)
A41: Statistics 1: Statistical sampling | B41: =COUNTIFS('Statistics'!$P$7:$P$58,"S1") | C41: =COUNTIFS('Statistics'!$P$7:$P$58,"S1",'Statistics'!$D$7:$D$58,"R") | D41: =COUNTIFS('Statistics'!$P$7:$P$58,"S1",'Statistics'!$D$7:$D$58,"A") | E41: =COUNTIFS('Statistics'!$P$7:$P$58,"S1",'Statistics'!$D$7:$D$58,"G") | F41: =COUNTIFS('Statistics'!$P$7:$P$58,"S1",'Statistics'!$D$7:$D$58,"") | G41: =IFERROR(E41/B41,0)
A42: Statistics 2: Data presentation and interpretation | B42: =COUNTIFS('Statistics'!$P$7:$P$58,"S2") | C42: =COUNTIFS('Statistics'!$P$7:$P$58,"S2",'Statistics'!$D$7:$D$58,"R") | D42: =COUNTIFS('Statistics'!$P$7:$P$58,"S2",'Statistics'!$D$7:$D$58,"A") | E42: =COUNTIFS('Statistics'!$P$7:$P$58,"S2",'Statistics'!$D$7:$D$58,"G") | F42: =COUNTIFS('Statistics'!$P$7:$P$58,"S2",'Statistics'!$D$7:$D$58,"") | G42: =IFERROR(E42/B42,0)
A43: Statistics 3: Probability | B43: =COUNTIFS('Statistics'!$P$7:$P$58,"S3") | C43: =COUNTIFS('Statistics'!$P$7:$P$58,"S3",'Statistics'!$D$7:$D$58,"R") | D43: =COUNTIFS('Statistics'!$P$7:$P$58,"S3",'Statistics'!$D$7:$D$58,"A") | E43: =COUNTIFS('Statistics'!$P$7:$P$58,"S3",'Statistics'!$D$7:$D$58,"G") | F43: =COUNTIFS('Statistics'!$P$7:$P$58,"S3",'Statistics'!$D$7:$D$58,"") | G43: =IFERROR(E43/B43,0)
A44: Statistics 4: Statistical distributions | B44: =COUNTIFS('Statistics'!$P$7:$P$58,"S4") | C44: =COUNTIFS('Statistics'!$P$7:$P$58,"S4",'Statistics'!$D$7:$D$58,"R") | D44: =COUNTIFS('Statistics'!$P$7:$P$58,"S4",'Statistics'!$D$7:$D$58,"A") | E44: =COUNTIFS('Statistics'!$P$7:$P$58,"S4",'Statistics'!$D$7:$D$58,"G") | F44: =COUNTIFS('Statistics'!$P$7:$P$58,"S4",'Statistics'!$D$7:$D$58,"") | G44: =IFERROR(E44/B44,0)
A45: Statistics 5: Statistical hypothesis testing | B45: =COUNTIFS('Statistics'!$P$7:$P$58,"S5") | C45: =COUNTIFS('Statistics'!$P$7:$P$58,"S5",'Statistics'!$D$7:$D$58,"R") | D45: =COUNTIFS('Statistics'!$P$7:$P$58,"S5",'Statistics'!$D$7:$D$58,"A") | E45: =COUNTIFS('Statistics'!$P$7:$P$58,"S5",'Statistics'!$D$7:$D$58,"G") | F45: =COUNTIFS('Statistics'!$P$7:$P$58,"S5",'Statistics'!$D$7:$D$58,"") | G45: =IFERROR(E45/B45,0)
...
