Workbook

Sheet Start here
B1: Edexcel A Level Maths: Pure maths
B2: A quick check of how confident you feel on every topic, so revision goes where it's needed most.
B4: How it works
A5: 1 | B5: Open the Pure tab | C5: Each topic has a yellow Rating box. Click it and pick R, A or G. That's the only thing to fill in (Notes are optional).
A7: 2 | B7: Be honest, not kind | C7: If you're torn between two colours, pick the lower one. A Green topic gets almost no time, so only use it when you're sure.
A9: 3 | B9: Take your time | C9: 158 topics, most take a glance. About 30 minutes.
B12: What the colours mean
B13: R · Red | C13: I can't do this yet, or I'd probably get it wrong.
B14: A · Amber | C14: I can do some of it, or I'm slow and make mistakes.
B15: G · Green | C15: I can do this confidently in exam conditions.
B17: The tabs
B18: Pure | C18: 158 topics for Paper 1 and Paper 2.
B19: Chapter tests | C19: Real exam questions for each textbook chapter. Mark them Done as you go.
B20: Progress | C20: Fills itself in: your Red / Amber / Green totals and a practice plan.
B22: Want to check a topic first?
B23: ▶ Watch | C23: A short Maths Genie video lesson on the topic.
B24: Maths Genie | C24: Exam-style questions for the chapter, with worked answers. 'Topic set' = questions on just that topic.
B25: PMT worksheet | C25: Physics & Maths Tutor questions, the mark scheme and model answers.
B26: Textbook | C26: Where it is in the Pearson textbooks (Pure 1 and 2, Applied 1 and 2), with a chapter test of real exam questions.
B27: Ref and Year | C27: The official specification reference (e.g. P7.4). Y1 = AS / first-year content, Y2 = second year.
B29: The exams
C30: Three 2-hour papers, 100 marks each, each worth a third: Paper 1 and Paper 2 are Pure; Paper 3 is Statistics (Section A) and Mechanics (Section B). Year 1 content is examined too, and Pure can come up on Paper 3.

Sheet Pure
A1: Pure maths
A2: Paper 1 and Paper 2 · 158 topics · pick R, A or G in the yellow Rating column for each one
A3: ="Rated so far: "&(COUNTIF($D$7:$D$184,"R")+COUNTIF($D$7:$D$184,"A")+COUNTIF($D$7:$D$184,"G"))&" of 158 Red "&COUNTIF($D$7:$D$184,"R")&" · Amber "&COUNTIF($D$7:$D$184,"A")&" · Green "&COUNTIF($D$7:$D$184,"G")
A5: Your check | F5: Maths Genie | I5: PMT worksheet | M5: Textbook chapter test
A6: Ref | B6: Topic | C6: Year | D6: Rating | E6: Notes | F6: Video | G6: Questions | H6: Answers | I6: Worksheet | J6: Questions | K6: Mark scheme | L6: Answers | M6: Textbook | N6: Questions | O6: Mark scheme
A8: 1 | B8: Proof | E8: 3 topics · Year 1: 2 · Year 2: 1
A9: P1.1 | B9: Proof by deduction and proof by exhaustion | C9: 1 | F9: ▶ Watch | G9: Questions | H9: Answers | I9: Proof | J9: Questions | K9: Marks | L9: Answers | M9: Pure 1 Ch7 | N9: Set 1 of 2 | O9: Marks | P9: P1
A10: P1.1 | B10: Disproof by counter-example | C10: 1 | F10: ▶ Watch | G10: Questions | H10: Answers | I10: Proof | J10: Questions | K10: Marks | L10: Answers | M10: Pure 1 Ch7 | N10: Set 1 of 2 | O10: Marks | P10: P1
A11: P1.1 | B11: Proof by contradiction (incl. √2 irrational, infinitely many primes) | C11: 2 | F11: ▶ Watch | G11: Questions | H11: Answers | I11: Proof | J11: Questions | K11: Marks | L11: Answers | M11: Pure 2 Ch1 | N11: Questions | O11: Marks | P11: P1
A13: 2 | B13: Algebra and functions | E13: 38 topics · Year 1: 25 · Year 2: 13
A14: P2.1 | B14: Laws of indices | C14: 1 | F14: ▶ Watch | G14: Questions | H14: Answers | I14: none for this topic | M14: Pure 1 Ch1 | N14: Questions | O14: Marks | P14: P2
A15: P2.1 | B15: Negative and fractional indices | C15: 1 | F15: ▶ Watch | G15: Questions | H15: Answers | I15: Exponential Equations | J15: Questions | K15: Marks | L15: Answers | M15: Pure 1 Ch1 | N15: Questions | O15: Marks | P15: P2
A16: P2.2 | B16: Surds and rationalising the denominator | C16: 1 | F16: ▶ Watch | G16: Questions | H16: Answers | I16: none for this topic | M16: Pure 1 Ch1 | N16: Questions | O16: Marks | P16: P2
A17: P2.3 | B17: Solving quadratics (factorising, formula, calculator) | C17: 1 | F17: ▶ Watch | G17: Questions | H17: Answers | I17: Quadratics | J17: Questions | K17: Marks | L17: Answers | M17: Pure 1 Ch2 | N17: Questions | O17: Marks | P17: P2
A18: P2.3 | B18: Completing the square | C18: 1 | F18: ▶ Watch | G18: Topic set | H18: Answers | I18: Quadratics | J18: Questions | K18: Marks | L18: Answers | M18: Pure 1 Ch2 | N18: Questions | O18: Marks | P18: P2
A19: P2.3 | B19: Sketching quadratic graphs and quadratic functions | C19: 1 | F19: ▶ Watch | G19: Questions | H19: Answers | I19: Quadratics | J19: Questions | K19: Marks | L19: Answers | M19: Pure 1 Ch2 | N19: Questions | O19: Marks | P19: P2
A20: P2.3 | B20: The discriminant (real, repeated and no roots) | C20: 1 | F20: ▶ Watch | G20: Topic set | H20: Answers | I20: Quadratics | J20: Questions | K20: Marks | L20: Answers | M20: Pure 1 Ch2 | N20: Questions | O20: Marks | P20: P2
A21: P2.3 | B21: Hidden quadratics (quadratics in a function of x) | C21: 1 | F21: ▶ Watch | G21: Questions | H21: Answers | I21: Quadratics | J21: Questions | K21: Marks | L21: Answers | M21: Pure 1 Ch2 | N21: Questions | O21: Marks | P21: P2
A22: P2.4 | B22: Linear simultaneous equations | C22: 1 | F22: ▶ Watch | G22: Questions | H22: Answers | I22: Straight Lines | J22: Questions | K22: Marks | L22: Answers | M22: Pure 1 Ch3 | N22: Questions | O22: Marks | P22: P2
A23: P2.4 | B23: Simultaneous equations: one linear, one quadratic | C23: 1 | F23: ▶ Watch | G23: Questions | H23: Answers | I23: Circles | J23: Questions | K23: Marks | L23: Answers | M23: Pure 1 Ch3 | N23: Questions | O23: Marks | P23: P2
A24: P2.5 | B24: Linear inequalities | C24: 1 | F24: ▶ Watch | G24: Questions | H24: Answers | I24: none for this topic | M24: Pure 1 Ch3 | N24: Questions | O24: Marks | P24: P2
A25: P2.5 | B25: Quadratic inequalities (incl. set notation answers) | C25: 1 | F25: ▶ Watch | G25: Topic set | H25: Answers | I25: Inequalities | J25: Questions | K25: Marks | L25: Answers | M25: Pure 1 Ch3 | N25: Questions | O25: Marks | P25: P2
A26: P2.5 | B26: Inequalities on graphs (shading regions) | C26: 1 | F26: ▶ Watch | G26: Questions | H26: Answers | I26: Inequalities | J26: Questions | K26: Marks | L26: Answers | M26: Pure 1 Ch3 | N26: Questions | O26: Marks | P26: P2
A27: P2.6 | B27: Expanding brackets and collecting like terms | C27: 1 | F27: ▶ Watch | G27: Questions | H27: Answers | I27: none for this topic | M27: Pure 1 Ch1 | N27: Questions | O27: Marks | P27: P2
A28: P2.6 | B28: Factorising (incl. cubics) | C28: 1 | F28: ▶ Watch | G28: Questions | H28: Answers | I28: Factor Theorem | J28: Questions | K28: Marks | L28: Answers | M28: Pure 1 Ch1 | N28: Questions | O28: Marks | P28: P2
A29: P2.6 | B29: Simplifying algebraic fractions (factorising and cancelling) | C29: 2 | F29: ▶ Watch | G29: Questions | H29: Answers | I29: none for this topic | M29: Pure 1 Ch7 | N29: Set 1 of 2 | O29: Marks | P29: P2
A30: P2.6 | B30: Algebraic division | C30: 1 | F30: ▶ Watch | G30: Questions | H30: Answers | I30: Factor Theorem | J30: Questions | K30: Marks | L30: Answers | M30: Pure 1 Ch7 | N30: Set 1 of 2 | O30: Marks | P30: P2
A31: P2.6 | B31: The factor theorem | C31: 1 | F31: ▶ Watch | G31: Topic set | H31: Answers | I31: Factor Theorem | J31: Questions | K31: Marks | L31: Answers | M31: Pure 1 Ch7 | N31: Set 1 of 2 | O31: Marks | P31: P2
A32: P2.6 | B32: Adding, subtracting, multiplying and dividing algebraic fractions | C32: 2 | F32: ▶ Watch | G32: Questions | H32: Answers | I32: none for this topic | M32: Pure 2 Ch1 | N32: Questions | O32: Marks | P32: P2
A33: P2.6 | B33: Algebraic division of improper fractions | C33: 2 | F33: ▶ Watch | G33: Questions | H33: Answers | I33: Composite & Inverse Functions (Yr 2) | J33: Questions | K33: Marks | L33: Answers | M33: Pure 2 Ch1 | N33: Questions | O33: Marks | P33: P2
A34: P2.7 | B34: Sketching cubic graphs | C34: 1 | F34: ▶ Watch | G34: Questions | H34: Answers | I34: Transformations & Graphs | J34: Questions | K34: Marks | L34: Answers | M34: Pure 1 Ch4 | N34: Set 1 of 2 | O34: Marks | P34: P2
A35: P2.7 | B35: Sketching quartic graphs | C35: 1 | F35: ▶ Watch | G35: Questions | H35: Answers | I35: none for this topic | M35: Pure 1 Ch4 | N35: Set 1 of 2 | O35: Marks | P35: P2
A36: P2.7 | B36: Reciprocal graphs y = a/x and y = a/x² (asymptotes) | C36: 1 | F36: ▶ Watch | G36: Questions | H36: Answers | I36: Transformations & Graphs | J36: Questions | K36: Marks | L36: Answers | M36: Pure 1 Ch4 | N36: Set 1 of 2 | O36: Marks | P36: P2
A37: P2.7 | B37: Points of intersection and solving equations graphically | C37: 1 | F37: ▶ Watch | G37: Questions | H37: Answers | I37: Transformations & Graphs | J37: Questions | K37: Marks | L37: Answers | M37: Pure 1 Ch4 | N37: Set 1 of 2 | O37: Marks | P37: P2
A38: P2.7 | B38: Proportional relationships and their graphs | C38: 1 | F38: ▶ Watch | G38: Questions | H38: Answers | I38: none for this topic | M38: Pure 1 Ch4 | N38: Set 1 of 2 | O38: Marks | P38: P2
A39: P2.7 | B39: The modulus function and its graph y = |ax + b| | C39: 2 | F39: ▶ Watch | G39: Questions | H39: Answers | I39: Modulus of Functions (Yr 2) | J39: Questions | K39: Marks | L39: Answers | M39: Pure 2 Ch2 | N39: Set 1 of 2 | O39: Marks | P39: P2
A40: P2.7 | B40: Solving modulus equations and inequalities | C40: 2 | F40: ▶ Watch | G40: Questions | H40: Answers | I40: Modulus of Functions (Yr 2) | J40: Questions | K40: Marks | L40: Answers | M40: Pure 2 Ch2 | N40: Set 1 of 2 | O40: Marks | P40: P2
A41: P2.8 | B41: Functions and mappings: domain and range | C41: 2 | F41: ▶ Watch | G41: Questions | H41: Answers | I41: Composite & Inverse Functions (Yr 2) | J41: Questions | K41: Marks | L41: Answers | M41: Pure 2 Ch2 | N41: Set 1 of 2 | O41: Marks | P41: P2
A42: P2.8 | B42: Composite functions | C42: 2 | F42: ▶ Watch | G42: Questions | H42: Answers | I42: Composite & Inverse Functions (Yr 2) | J42: Questions | K42: Marks | L42: Answers | M42: Pure 2 Ch2 | N42: Set 1 of 2 | O42: Marks | P42: P2
A43: P2.8 | B43: Inverse functions and their graphs | C43: 2 | F43: ▶ Watch | G43: Questions | H43: Answers | I43: Composite & Inverse Functions (Yr 2) | J43: Questions | K43: Marks | L43: Answers | M43: Pure 2 Ch2 | N43: Set 1 of 2 | O43: Marks | P43: P2
...

Sheet Chapter tests
A1: Chapter tests
A2: Real Edexcel exam questions for each textbook chapter, plus the textbook review exercises. Try one once every topic in it is Amber or Green.
A4: Book | B4: Chapters | C4: Test | D4: Questions | E4: Mark scheme | F4: Done? | G4: Score / notes
A6: Pure maths | C6: Paper 1 and Paper 2
A7: Pure 1 | B7: Ch1 Algebraic Expression | C7: Ch1 Algebraic Expression Exam Questions | D7: Questions | E7: Marks
A8: Pure 1 | B8: Ch2 Quadratics, Ch3 Equations and Inequalities | C8: Ch2 Quadratics and Ch3 Equations and Inequalities Exam Questions | D8: Questions | E8: Marks
A9: Pure 1 | B9: Ch1-Ch4 review (textbook) | C9: Textbook review exercise 1 - pg.85-88 | D9: in the book
A10: Pure 1 | B10: Ch5 Straight Line Graphs | C10: Ch5 Straight Line Graphs Exam Questions | D10: Questions | E10: Marks
A11: Pure 1 | B11: Ch6 Circles | C11: Ch6 Circles Exam Questions | D11: Questions | E11: Marks
A12: Pure 1 | B12: Ch4 Graphs and Transformations, Ch7 Algebraic Methods | C12: Ch4 Graphs and Transformations + Ch7 Algebraic Methods Exam Questions 1 | D12: Questions | E12: Marks
A13: Pure 1 | B13: Ch4 Graphs and Transformations, Ch7 Algebraic Methods | C13: Ch4 Graphs and Transformations + Ch7 Algebraic Methods Exam Questions 2 | D13: Questions | E13: Marks
A14: Pure 1 | B14: Ch8 Binomial Expansion | C14: Ch8 Binomial Expansion Exam Questions | D14: Questions | E14: Marks
A15: Pure 1 | B15: Ch9 Trigonometric ratios | C15: Ch9 Trigonometric Ratos Exam Questions | D15: Questions | E15: Marks
A16: Pure 1 | B16: Ch10 Trigonometric Identities and Equations | C16: Ch10 Trigonometric Identities and Equations Exam Questions | D16: Questions | E16: Marks
A17: Pure 1 | B17: Ch5-Ch10 review (textbook) | C17: Textbook review exercise 2 - pg.226 - 229 | D17: in the book
A18: Pure 1 | B18: Ch11 Vectors | C18: Ch11 Vectors Exam Questions | D18: Questions | E18: Marks
A19: Pure 1 | B19: Ch12 Differentiation | C19: Ch12 Differentiation Exam Questions | D19: Questions | E19: Marks
A20: Pure 1 | B20: Ch13 Integration | C20: Ch13 Integration Exam Question | D20: Questions | E20: Marks
A21: Pure 1 | B21: Ch14 Exponential and Logarithms | C21: Ch14 Exponential and Logarithms Exam Questions 1 | D21: Questions | E21: Marks
A22: Pure 1 | B22: Ch14 Exponential and Logarithms | C22: Ch14 Exponential and Logarithms Exam Questions 2 | D22: Questions | E22: Marks
A23: Pure 1 | B23: Ch11-Ch14 review (textbook) | C23: Textbook review exercise 3 - pg.338-341 | D23: in the book
A24: Pure 2 | B24: Ch1 Algebraic Methods | C24: Ch1 Algebraic Methods Exam Questions | D24: Questions | E24: Marks
A25: Pure 2 | B25: Ch2 Functions and Graphs | C25: Ch2 Functions and Graphs Exam Questions 1 | D25: Questions | E25: Marks
A26: Pure 2 | B26: Ch2 Functions and Graphs | C26: Ch2 Functions and Graphs Exam Questions 2 | D26: Questions | E26: Marks
A27: Pure 2 | B27: Ch3 Sequences and Series | C27: Ch3 Sequences and Series Exam Questions 1 | D27: Questions | E27: Marks
A28: Pure 2 | B28: Ch3 Sequences and Series | C28: Ch3 Sequences and Series Exam Questions 2 | D28: Questions | E28: Marks
A29: Pure 2 | B29: Ch4 Binomial Expansion | C29: Ch4 Binomial Expansion Exam Questions | D29: Questions | E29: none
A30: Pure 2 | B30: Ch1-Ch4 review (textbook) | C30: Textbook review exercise 1 - pg.107-112 | D30: in the book
A31: Pure 2 | B31: Ch5 Radians | C31: Ch5 Radians Exam Questions | D31: Questions | E31: Marks
A32: Pure 2 | B32: Ch6 Trigonometric Functions, Ch7 Trigonometry and Modelling | C32: Ch6 Trigonometric Functions and Ch7 Trigonometry and Modelling Exam Questions 1 | D32: Questions | E32: Marks
A33: Pure 2 | B33: Ch6 Trigonometric Functions, Ch7 Trigonometry and Modelling | C33: Ch6 Trigonometric Functions and Ch7 Trigonometry and Modelling Exam Questions 2 | D33: Questions | E33: Marks
A34: Pure 2 | B34: Ch8 Parametric Equations | C34: Ch8 Parametric Equations Exam Questions | D34: Questions | E34: Marks
A35: Pure 2 | B35: Ch5-Ch8 review (textbook) | C35: Textbook review exercise 2 - pg.225-230 | D35: in the book
A36: Pure 2 | B36: Ch9 Differentiation | C36: Ch9 Differentiation Exam Questions 1 | D36: Questions | E36: Marks
A37: Pure 2 | B37: Ch9 Differentiation | C37: Ch9 Differentiation Exam Questions 2 | D37: Questions | E37: Marks
A38: Pure 2 | B38: Ch9 Differentiation | C38: Ch9 Differentiation Exam Questions 3 | D38: Questions | E38: Marks
A39: Pure 2 | B39: Ch10 Numerical Methods | C39: Ch10 Numerical Methods Exam Questions | D39: Questions | E39: Marks
A40: Pure 2 | B40: Ch11 Integration | C40: Ch11 Integration Exam Questions 1 | D40: Questions | E40: Marks
A41: Pure 2 | B41: Ch11 Integration | C41: Ch11 Integration Exam Questions 2 | D41: Questions | E41: Marks
A42: Pure 2 | B42: Ch11 Integration | C42: Ch11 Integration Exam Questions 3 | D42: Questions | E42: Marks
...

Sheet Progress
A1: Progress
A2: This page fills itself in from your ratings. Nothing to type here except the yellow cells, if you want to change them.
A4: =TEXT((COUNTIFS('Pure'!$D$7:$D$184,"R",'Pure'!$C$7:$C$184,">0")+COUNTIFS('Pure'!$D$7:$D$184,"A",'Pure'!$C$7:$C$184,">0")+COUNTIFS('Pure'!$D$7:$D$184,"G",'Pure'!$C$7:$C$184,">0"))/158,"0%") | C4: =COUNTIFS('Pure'!$D$7:$D$184,"R",'Pure'!$C$7:$C$184,">0") | E4: =COUNTIFS('Pure'!$D$7:$D$184,"A",'Pure'!$C$7:$C$184,">0") | G4: =COUNTIFS('Pure'!$D$7:$D$184,"G",'Pure'!$C$7:$C$184,">0")
A5: Topics rated (of 158) | C5: Red | E5: Amber | G5: Green
A7: Your practice plan
A8: Rating | B8: Topics | C8: Qs each | D8: Qs total | E8: What to do
A9: Red | B9: =COUNTIFS('Pure'!$D$7:$D$184,"R",'Pure'!$C$7:$C$184,">0") | C9: 10 | D9: =B9*C9 | E9: Full worksheet, taught first
A10: Amber | B10: =COUNTIFS('Pure'!$D$7:$D$184,"A",'Pure'!$C$7:$C$184,">0") | C10: 5 | D10: =B10*C10 | E10: Practise until 3 right in a row
A11: Green | B11: =COUNTIFS('Pure'!$D$7:$D$184,"G",'Pure'!$C$7:$C$184,">0") | C11: 2 | D11: =B11*C11 | E11: 2-question spot check
A12: Not rated yet | B12: =COUNTIFS('Pure'!$D$7:$D$184,"",'Pure'!$C$7:$C$184,">0")
A13: Total questions | D13: =SUM(D9:D11)
A14: Minutes per question | D14: 6
A15: Hours of practice | D15: =ROUND(D13*D14/60,1)
A16: Chapter tests done | D16: =COUNTIF('Chapter tests'!$F$5:$F$45,"Done")&" of 39"
A18: By year
B19: Topics | C19: Red | D19: Amber | E19: Green | F19: Not rated | G19: % Green
A20: Year 1 (AS content) | B20: =COUNTIFS('Pure'!$C$7:$C$184,1) | C20: =COUNTIFS('Pure'!$C$7:$C$184,1,'Pure'!$D$7:$D$184,"R") | D20: =COUNTIFS('Pure'!$C$7:$C$184,1,'Pure'!$D$7:$D$184,"A") | E20: =COUNTIFS('Pure'!$C$7:$C$184,1,'Pure'!$D$7:$D$184,"G") | F20: =COUNTIFS('Pure'!$C$7:$C$184,1,'Pure'!$D$7:$D$184,"") | G20: =IFERROR(E20/B20,0)
A21: Year 2 | B21: =COUNTIFS('Pure'!$C$7:$C$184,2) | C21: =COUNTIFS('Pure'!$C$7:$C$184,2,'Pure'!$D$7:$D$184,"R") | D21: =COUNTIFS('Pure'!$C$7:$C$184,2,'Pure'!$D$7:$D$184,"A") | E21: =COUNTIFS('Pure'!$C$7:$C$184,2,'Pure'!$D$7:$D$184,"G") | F21: =COUNTIFS('Pure'!$C$7:$C$184,2,'Pure'!$D$7:$D$184,"") | G21: =IFERROR(E21/B21,0)
A23: By topic area
B24: Topics | C24: Red | D24: Amber | E24: Green | F24: Not rated | G24: % Green
A25: Pure 1: Proof | B25: =COUNTIFS('Pure'!$P$7:$P$184,"P1") | C25: =COUNTIFS('Pure'!$P$7:$P$184,"P1",'Pure'!$D$7:$D$184,"R") | D25: =COUNTIFS('Pure'!$P$7:$P$184,"P1",'Pure'!$D$7:$D$184,"A") | E25: =COUNTIFS('Pure'!$P$7:$P$184,"P1",'Pure'!$D$7:$D$184,"G") | F25: =COUNTIFS('Pure'!$P$7:$P$184,"P1",'Pure'!$D$7:$D$184,"") | G25: =IFERROR(E25/B25,0)
A26: Pure 2: Algebra and functions | B26: =COUNTIFS('Pure'!$P$7:$P$184,"P2") | C26: =COUNTIFS('Pure'!$P$7:$P$184,"P2",'Pure'!$D$7:$D$184,"R") | D26: =COUNTIFS('Pure'!$P$7:$P$184,"P2",'Pure'!$D$7:$D$184,"A") | E26: =COUNTIFS('Pure'!$P$7:$P$184,"P2",'Pure'!$D$7:$D$184,"G") | F26: =COUNTIFS('Pure'!$P$7:$P$184,"P2",'Pure'!$D$7:$D$184,"") | G26: =IFERROR(E26/B26,0)
A27: Pure 3: Coordinate geometry in the (x, y) plane | B27: =COUNTIFS('Pure'!$P$7:$P$184,"P3") | C27: =COUNTIFS('Pure'!$P$7:$P$184,"P3",'Pure'!$D$7:$D$184,"R") | D27: =COUNTIFS('Pure'!$P$7:$P$184,"P3",'Pure'!$D$7:$D$184,"A") | E27: =COUNTIFS('Pure'!$P$7:$P$184,"P3",'Pure'!$D$7:$D$184,"G") | F27: =COUNTIFS('Pure'!$P$7:$P$184,"P3",'Pure'!$D$7:$D$184,"") | G27: =IFERROR(E27/B27,0)
A28: Pure 4: Sequences and series | B28: =COUNTIFS('Pure'!$P$7:$P$184,"P4") | C28: =COUNTIFS('Pure'!$P$7:$P$184,"P4",'Pure'!$D$7:$D$184,"R") | D28: =COUNTIFS('Pure'!$P$7:$P$184,"P4",'Pure'!$D$7:$D$184,"A") | E28: =COUNTIFS('Pure'!$P$7:$P$184,"P4",'Pure'!$D$7:$D$184,"G") | F28: =COUNTIFS('Pure'!$P$7:$P$184,"P4",'Pure'!$D$7:$D$184,"") | G28: =IFERROR(E28/B28,0)
A29: Pure 5: Trigonometry | B29: =COUNTIFS('Pure'!$P$7:$P$184,"P5") | C29: =COUNTIFS('Pure'!$P$7:$P$184,"P5",'Pure'!$D$7:$D$184,"R") | D29: =COUNTIFS('Pure'!$P$7:$P$184,"P5",'Pure'!$D$7:$D$184,"A") | E29: =COUNTIFS('Pure'!$P$7:$P$184,"P5",'Pure'!$D$7:$D$184,"G") | F29: =COUNTIFS('Pure'!$P$7:$P$184,"P5",'Pure'!$D$7:$D$184,"") | G29: =IFERROR(E29/B29,0)
A30: Pure 6: Exponentials and logarithms | B30: =COUNTIFS('Pure'!$P$7:$P$184,"P6") | C30: =COUNTIFS('Pure'!$P$7:$P$184,"P6",'Pure'!$D$7:$D$184,"R") | D30: =COUNTIFS('Pure'!$P$7:$P$184,"P6",'Pure'!$D$7:$D$184,"A") | E30: =COUNTIFS('Pure'!$P$7:$P$184,"P6",'Pure'!$D$7:$D$184,"G") | F30: =COUNTIFS('Pure'!$P$7:$P$184,"P6",'Pure'!$D$7:$D$184,"") | G30: =IFERROR(E30/B30,0)
A31: Pure 7: Differentiation | B31: =COUNTIFS('Pure'!$P$7:$P$184,"P7") | C31: =COUNTIFS('Pure'!$P$7:$P$184,"P7",'Pure'!$D$7:$D$184,"R") | D31: =COUNTIFS('Pure'!$P$7:$P$184,"P7",'Pure'!$D$7:$D$184,"A") | E31: =COUNTIFS('Pure'!$P$7:$P$184,"P7",'Pure'!$D$7:$D$184,"G") | F31: =COUNTIFS('Pure'!$P$7:$P$184,"P7",'Pure'!$D$7:$D$184,"") | G31: =IFERROR(E31/B31,0)
A32: Pure 8: Integration | B32: =COUNTIFS('Pure'!$P$7:$P$184,"P8") | C32: =COUNTIFS('Pure'!$P$7:$P$184,"P8",'Pure'!$D$7:$D$184,"R") | D32: =COUNTIFS('Pure'!$P$7:$P$184,"P8",'Pure'!$D$7:$D$184,"A") | E32: =COUNTIFS('Pure'!$P$7:$P$184,"P8",'Pure'!$D$7:$D$184,"G") | F32: =COUNTIFS('Pure'!$P$7:$P$184,"P8",'Pure'!$D$7:$D$184,"") | G32: =IFERROR(E32/B32,0)
A33: Pure 9: Numerical methods | B33: =COUNTIFS('Pure'!$P$7:$P$184,"P9") | C33: =COUNTIFS('Pure'!$P$7:$P$184,"P9",'Pure'!$D$7:$D$184,"R") | D33: =COUNTIFS('Pure'!$P$7:$P$184,"P9",'Pure'!$D$7:$D$184,"A") | E33: =COUNTIFS('Pure'!$P$7:$P$184,"P9",'Pure'!$D$7:$D$184,"G") | F33: =COUNTIFS('Pure'!$P$7:$P$184,"P9",'Pure'!$D$7:$D$184,"") | G33: =IFERROR(E33/B33,0)
A34: Pure 10: Vectors | B34: =COUNTIFS('Pure'!$P$7:$P$184,"P10") | C34: =COUNTIFS('Pure'!$P$7:$P$184,"P10",'Pure'!$D$7:$D$184,"R") | D34: =COUNTIFS('Pure'!$P$7:$P$184,"P10",'Pure'!$D$7:$D$184,"A") | E34: =COUNTIFS('Pure'!$P$7:$P$184,"P10",'Pure'!$D$7:$D$184,"G") | F34: =COUNTIFS('Pure'!$P$7:$P$184,"P10",'Pure'!$D$7:$D$184,"") | G34: =IFERROR(E34/B34,0)
