Workbook

Sheet Start here
B1: Edexcel A Level Maths: Statistics
B2: A quick check of how confident you feel on every topic, so revision goes where it's needed most.
B4: How it works
A5: 1 | B5: Open the Statistics tab | C5: Each topic has a yellow Rating box. Click it and pick R, A or G. That's the only thing to fill in (Notes are optional).
A7: 2 | B7: Be honest, not kind | C7: If you're torn between two colours, pick the lower one. A Green topic gets almost no time, so only use it when you're sure.
A9: 3 | B9: Take your time | C9: 42 topics, most take a glance. About 10 minutes.
B12: What the colours mean
B13: R · Red | C13: I can't do this yet, or I'd probably get it wrong.
B14: A · Amber | C14: I can do some of it, or I'm slow and make mistakes.
B15: G · Green | C15: I can do this confidently in exam conditions.
B17: The tabs
B18: Statistics | C18: 42 topics for Paper 3, Section A.
B19: Chapter tests | C19: Real exam questions for each textbook chapter. Mark them Done as you go.
B20: Progress | C20: Fills itself in: your Red / Amber / Green totals and a practice plan.
B22: Want to check a topic first?
B23: ▶ Watch | C23: A short Maths Genie video lesson on the topic.
B24: Maths Genie | C24: Exam-style questions for the chapter, with worked answers. 'Topic set' = questions on just that topic.
B25: PMT worksheet | C25: Physics & Maths Tutor questions, the mark scheme and model answers.
B26: Textbook | C26: Where it is in the Pearson textbooks (Pure 1 and 2, Applied 1 and 2), with a chapter test of real exam questions.
B27: Ref and Year | C27: The official specification reference (e.g. P7.4). Y1 = AS / first-year content, Y2 = second year.
B29: The exams
C30: Three 2-hour papers, 100 marks each, each worth a third: Paper 1 and Paper 2 are Pure; Paper 3 is Statistics (Section A) and Mechanics (Section B). Year 1 content is examined too, and Pure can come up on Paper 3.

Sheet Statistics
A1: Statistics
A2: Paper 3, Section A · 42 topics · pick R, A or G in the yellow Rating column for each one
A3: ="Rated so far: "&(COUNTIF($D$7:$D$58,"R")+COUNTIF($D$7:$D$58,"A")+COUNTIF($D$7:$D$58,"G"))&" of 42 Red "&COUNTIF($D$7:$D$58,"R")&" · Amber "&COUNTIF($D$7:$D$58,"A")&" · Green "&COUNTIF($D$7:$D$58,"G")
A5: Your check | F5: Maths Genie | I5: PMT worksheet | M5: Textbook chapter test
A6: Ref | B6: Topic | C6: Year | D6: Rating | E6: Notes | F6: Video | G6: Questions | H6: Answers | I6: Worksheet | J6: Questions | K6: Mark scheme | L6: Answers | M6: Textbook | N6: Questions | O6: Mark scheme
A8: 1 | B8: Statistical sampling | E8: 3 topics · Year 1: 3
A9: S1.1 | B9: Populations, samples and census | C9: 1 | F9: ▶ Watch | G9: Questions | H9: Answers | I9: none for this topic | M9: Applied 1 Ch1 | N9: none | P9: S1
A10: S1.1 | B10: Random sampling: simple random, systematic, stratified | C10: 1 | F10: ▶ Watch | G10: Topic set | H10: Answers | I10: Sampling | J10: Questions | K10: Marks | L10: Answers | M10: Applied 1 Ch1 | N10: none | P10: S1
A11: S1.1 | B11: Non-random sampling: quota and opportunity | C11: 1 | F11: ▶ Watch | G11: Questions | H11: Answers | I11: Sampling | J11: Questions | K11: Marks | L11: Answers | M11: Applied 1 Ch1 | N11: none | P11: S1
A13: 2 | B13: Data presentation and interpretation | E13: 14 topics · Year 1: 13 · Year 2: 1
A14: S2.3 | B14: Types of data (qualitative, discrete, continuous, grouped) | C14: 1 | F14: ▶ Watch | G14: Questions | H14: Answers | I14: none for this topic | M14: Applied 1 Ch1 | N14: none | P14: S2
A15: S2.3 | B15: Mean, median and mode (incl. grouped data) | C15: 1 | F15: ▶ Watch | G15: Questions | H15: Answers | I15: Data Presentation | J15: Questions | K15: Marks | L15: Answers | M15: Applied 1 Ch2 | N15: Set 1 of 2 | O15: Marks | P15: S2
A16: S2.3 | B16: Quartiles, percentiles and interpolation | C16: 1 | F16: ▶ Watch | G16: Questions | H16: Answers | I16: Data Presentation | J16: Questions | K16: Marks | L16: Answers | M16: Applied 1 Ch2 | N16: Set 1 of 2 | O16: Marks | P16: S2
A17: S2.3 | B17: Range, IQR, variance and standard deviation | C17: 1 | F17: ▶ Watch | G17: Topic set | H17: Answers | I17: Data Presentation | J17: Questions | K17: Marks | L17: Answers | M17: Applied 1 Ch2 | N17: Set 1 of 2 | O17: Marks | P17: S2
A18: S2.3 | B18: Coding | C18: 1 | F18: ▶ Watch | G18: Questions | H18: Answers | I18: Large data sets | J18: Questions | K18: Marks | L18: Answers | M18: Applied 1 Ch2 | N18: Set 1 of 2 | O18: Marks | P18: S2
A19: S2.1 | B19: Box plots | C19: 1 | F19: ▶ Watch | G19: Topic set | H19: Answers | I19: Large data sets | J19: Questions | K19: Marks | L19: Answers | M19: Applied 1 Ch3 | N19: Set 1 of 2 | O19: Marks | P19: S2
A20: S2.1 | B20: Cumulative frequency diagrams | C20: 1 | F20: ▶ Watch | G20: Questions | H20: Answers | I20: none for this topic | M20: Applied 1 Ch3 | N20: Set 1 of 2 | O20: Marks | P20: S2
A21: S2.1 | B21: Histograms (frequency density) and frequency polygons | C21: 1 | F21: ▶ Watch | G21: Topic set | H21: Answers | I21: Data Presentation | J21: Questions | K21: Marks | L21: Answers | M21: Applied 1 Ch3 | N21: Set 1 of 2 | O21: Marks | P21: S2
A22: S2.4 | B22: Outliers and cleaning data | C22: 1 | F22: ▶ Watch | G22: Questions | H22: Answers | I22: Data Presentation | J22: Questions | K22: Marks | L22: Answers | M22: Applied 1 Ch3 | N22: Set 1 of 2 | O22: Marks | P22: S2
A23: S2.4 | B23: Comparing distributions | C23: 1 | F23: ▶ Watch | G23: Questions | H23: Answers | I23: Large data sets | J23: Questions | K23: Marks | L23: Answers | M23: Applied 1 Ch3 | N23: Set 1 of 2 | O23: Marks | P23: S2
A24: S2.2 | B24: Scatter diagrams and correlation (correlation vs causation) | C24: 1 | F24: ▶ Watch | G24: Questions | H24: Answers | I24: Regression and Correlation | J24: Questions | K24: Marks | L24: Answers | M24: Applied 1 Ch4 | N24: Questions | O24: Marks | P24: S2
A25: S2.2 | B25: Linear regression lines (interpolation and extrapolation) | C25: 1 | F25: ▶ Watch | G25: Questions | H25: Answers | I25: Regression and Correlation | J25: Questions | K25: Marks | L25: Answers | M25: Applied 1 Ch4 | N25: Questions | O25: Marks | P25: S2
A26: S2.2 | B26: Exponential models and log coding (y = axⁿ, y = kbˣ) | C26: 2 | F26: ▶ Watch | G26: Questions | H26: Answers | I26: Regression and Correlation (Yr 2) | J26: Questions | K26: Marks | L26: Answers | M26: Applied 2 Ch1 | N26: Questions | O26: Marks | P26: S2
A27: LDS | B27: The large data set (context and familiarity) | C27: 1 | F27: ▶ Watch | G27: Questions | H27: Answers | I27: Large data sets | J27: Questions | K27: Marks | L27: Answers | M27: Applied 1 Ch1 | N27: none | P27: S2
A29: 3 | B29: Probability | E29: 10 topics · Year 1: 4 · Year 2: 6
A30: S3.1 | B30: Calculating probabilities and sample spaces | C30: 1 | F30: ▶ Watch | G30: Questions | H30: Answers | I30: Probability | J30: Questions | K30: Marks | L30: Answers | M30: Applied 1 Ch5 | N30: Questions | O30: Marks | P30: S3
A31: S3.1 | B31: Venn diagrams | C31: 1 | F31: ▶ Watch | G31: Questions | H31: Answers | I31: Probability | J31: Questions | K31: Marks | L31: Answers | M31: Applied 1 Ch5 | N31: Questions | O31: Marks | P31: S3
A32: S3.1 | B32: Mutually exclusive and independent events | C32: 1 | F32: ▶ Watch | G32: Questions | H32: Answers | I32: Probability | J32: Questions | K32: Marks | L32: Answers | M32: Applied 1 Ch5 | N32: Questions | O32: Marks | P32: S3
A33: S3.1 | B33: Tree diagrams | C33: 1 | F33: ▶ Watch | G33: Questions | H33: Answers | I33: none for this topic | M33: Applied 1 Ch5 | N33: Questions | O33: Marks | P33: S3
A34: S3.1 | B34: Set notation for probability | C34: 2 | F34: ▶ Watch | G34: Questions | H34: Answers | I34: Probability (Yr 2) | J34: Questions | K34: Marks | L34: Answers | M34: Applied 2 Ch2 | N34: Questions | O34: Marks | P34: S3
A35: S3.2 | B35: Conditional probability (incl. two-way tables) | C35: 2 | F35: ▶ Watch | G35: Questions | H35: Answers | I35: Conditional Probability (Yr 2) | J35: Questions | K35: Marks | L35: Answers | M35: Applied 2 Ch2 | N35: Questions | O35: Marks | P35: S3
A36: S3.2 | B36: Conditional probability with Venn diagrams | C36: 2 | F36: ▶ Watch | G36: Questions | H36: Answers | I36: Conditional Probability (Yr 2) | J36: Questions | K36: Marks | L36: Answers | M36: Applied 2 Ch2 | N36: Questions | O36: Marks | P36: S3
A37: S3.2 | B37: Probability formulae: P(A ∪ B) and P(A | B) | C37: 2 | F37: ▶ Watch | G37: Questions | H37: Answers | I37: Conditional Probability (Yr 2) | J37: Questions | K37: Marks | L37: Answers | M37: Applied 2 Ch2 | N37: Questions | O37: Marks | P37: S3
A38: S3.2 | B38: Conditional probability with tree diagrams | C38: 2 | F38: ▶ Watch | G38: Questions | H38: Answers | I38: none for this topic | M38: Applied 2 Ch2 | N38: Questions | O38: Marks | P38: S3
A39: S3.3 | B39: Modelling with probability: critiquing assumptions (e.g. a fair die) | C39: 2 | F39: ▶ Watch | G39: Questions | H39: Answers | I39: Probability (Yr 2) | J39: Questions | K39: Marks | L39: Answers | M39: Applied 2 Ch2 | N39: Questions | O39: Marks | P39: S3
A41: 4 | B41: Statistical distributions | E41: 8 topics · Year 1: 3 · Year 2: 5
A42: S4.1 | B42: Discrete random variables, probability distributions and the discrete uniform distribution | C42: 1 | F42: ▶ Watch | G42: Questions | H42: Answers | I42: Probability | J42: Questions | K42: Marks | L42: Answers | M42: Applied 1 Ch6 | N42: Questions | O42: Marks | P42: S4
A43: S4.1 | B43: The binomial distribution B(n, p) | C43: 1 | F43: ▶ Watch | G43: Questions | H43: Answers | I43: Binomial Distribution | J43: Questions | K43: Marks | L43: Answers | M43: Applied 1 Ch6 | N43: Questions | O43: Marks | P43: S4
A44: S4.1 | B44: Cumulative binomial probabilities | C44: 1 | F44: ▶ Watch | G44: Questions | H44: Answers | I44: Binomial Distribution | J44: Questions | K44: Marks | L44: Answers | M44: Applied 1 Ch6 | N44: Questions | O44: Marks | P44: S4
A45: S4.2 | B45: The normal distribution: properties (incl. inflection at μ ± σ) and finding probabilities | C45: 2 | F45: ▶ Watch | G45: Questions | H45: Answers | I45: Normal Distribution (Yr 2) | J45: Questions | K45: Marks | L45: Answers | M45: Applied 2 Ch3 | N45: Questions | O45: Marks | P45: S4
...

Sheet Chapter tests
A1: Chapter tests
A2: Real Edexcel exam questions for each textbook chapter, plus the textbook review exercises. Try one once every topic in it is Amber or Green.
A4: Book | B4: Chapters | C4: Test | D4: Questions | E4: Mark scheme | F4: Done? | G4: Score / notes
A6: Statistics | C6: Paper 3, Section A
A7: Applied 1 | B7: Ch2 Measures of Location and Spread, Ch3 Representations of Data | C7: Ch2 Measures of Location and Spread + Ch3 Representation of Data Exam Questions 1 | D7: Questions | E7: Marks
A8: Applied 1 | B8: Ch2 Measures of Location and Spread, Ch3 Representations of Data | C8: Ch2 Measures of Location and Spread + Ch3 Representation of Data Exam Questions 2 | D8: Questions | E8: Marks
A9: Applied 1 | B9: Ch4 Correlation | C9: Ch4 Correlation Exam Questions | D9: Questions | E9: Marks
A10: Applied 1 | B10: Ch5 Probability | C10: Ch5 Probability Exam Questions | D10: Questions | E10: Marks
A11: Applied 1 | B11: Ch6 Statistical Distributions, Ch7 Hypothesis Testing | C11: Ch6 Statistical Distributions and Ch7 Hypothesis Testing Exam Questions | D11: Questions | E11: Marks
A12: Applied 1 | B12: Ch1-Ch7 review (textbook) | C12: Textbook review exercise 1 - pg. 113-117 | D12: in the book
A13: Applied 2 | B13: Ch1 Regression, Correlation and Hypothesis Testing | C13: Ch1 Regression, Correlation and Hypothesis Testing Exam Questions | D13: Questions | E13: Marks
A14: Applied 2 | B14: Ch2 Conditional Probability | C14: Ch2 Conditional Probability Exam Questions | D14: Questions | E14: Marks
A15: Applied 2 | B15: Ch3 The Normal Distribution | C15: Ch3 The Normal Distribution Exam Questions | D15: Questions | E15: Marks
A16: Applied 2 | B16: Ch1-Ch3 review (textbook) | C16: Textbook review exercise 1 - pg.65-69 | D16: in the book

Sheet Progress
A1: Progress
A2: This page fills itself in from your ratings. Nothing to type here except the yellow cells, if you want to change them.
A4: =TEXT((COUNTIFS('Statistics'!$D$7:$D$58,"R",'Statistics'!$C$7:$C$58,">0")+COUNTIFS('Statistics'!$D$7:$D$58,"A",'Statistics'!$C$7:$C$58,">0")+COUNTIFS('Statistics'!$D$7:$D$58,"G",'Statistics'!$C$7:$C$58,">0"))/42,"0%") | C4: =COUNTIFS('Statistics'!$D$7:$D$58,"R",'Statistics'!$C$7:$C$58,">0") | E4: =COUNTIFS('Statistics'!$D$7:$D$58,"A",'Statistics'!$C$7:$C$58,">0") | G4: =COUNTIFS('Statistics'!$D$7:$D$58,"G",'Statistics'!$C$7:$C$58,">0")
A5: Topics rated (of 42) | C5: Red | E5: Amber | G5: Green
A7: Your practice plan
A8: Rating | B8: Topics | C8: Qs each | D8: Qs total | E8: What to do
A9: Red | B9: =COUNTIFS('Statistics'!$D$7:$D$58,"R",'Statistics'!$C$7:$C$58,">0") | C9: 10 | D9: =B9*C9 | E9: Full worksheet, taught first
A10: Amber | B10: =COUNTIFS('Statistics'!$D$7:$D$58,"A",'Statistics'!$C$7:$C$58,">0") | C10: 5 | D10: =B10*C10 | E10: Practise until 3 right in a row
A11: Green | B11: =COUNTIFS('Statistics'!$D$7:$D$58,"G",'Statistics'!$C$7:$C$58,">0") | C11: 2 | D11: =B11*C11 | E11: 2-question spot check
A12: Not rated yet | B12: =COUNTIFS('Statistics'!$D$7:$D$58,"",'Statistics'!$C$7:$C$58,">0")
A13: Total questions | D13: =SUM(D9:D11)
A14: Minutes per question | D14: 6
A15: Hours of practice | D15: =ROUND(D13*D14/60,1)
A16: Chapter tests done | D16: =COUNTIF('Chapter tests'!$F$5:$F$16,"Done")&" of 10"
A18: By year
B19: Topics | C19: Red | D19: Amber | E19: Green | F19: Not rated | G19: % Green
A20: Year 1 (AS content) | B20: =COUNTIFS('Statistics'!$C$7:$C$58,1) | C20: =COUNTIFS('Statistics'!$C$7:$C$58,1,'Statistics'!$D$7:$D$58,"R") | D20: =COUNTIFS('Statistics'!$C$7:$C$58,1,'Statistics'!$D$7:$D$58,"A") | E20: =COUNTIFS('Statistics'!$C$7:$C$58,1,'Statistics'!$D$7:$D$58,"G") | F20: =COUNTIFS('Statistics'!$C$7:$C$58,1,'Statistics'!$D$7:$D$58,"") | G20: =IFERROR(E20/B20,0)
A21: Year 2 | B21: =COUNTIFS('Statistics'!$C$7:$C$58,2) | C21: =COUNTIFS('Statistics'!$C$7:$C$58,2,'Statistics'!$D$7:$D$58,"R") | D21: =COUNTIFS('Statistics'!$C$7:$C$58,2,'Statistics'!$D$7:$D$58,"A") | E21: =COUNTIFS('Statistics'!$C$7:$C$58,2,'Statistics'!$D$7:$D$58,"G") | F21: =COUNTIFS('Statistics'!$C$7:$C$58,2,'Statistics'!$D$7:$D$58,"") | G21: =IFERROR(E21/B21,0)
A23: By topic area
B24: Topics | C24: Red | D24: Amber | E24: Green | F24: Not rated | G24: % Green
A25: Statistics 1: Statistical sampling | B25: =COUNTIFS('Statistics'!$P$7:$P$58,"S1") | C25: =COUNTIFS('Statistics'!$P$7:$P$58,"S1",'Statistics'!$D$7:$D$58,"R") | D25: =COUNTIFS('Statistics'!$P$7:$P$58,"S1",'Statistics'!$D$7:$D$58,"A") | E25: =COUNTIFS('Statistics'!$P$7:$P$58,"S1",'Statistics'!$D$7:$D$58,"G") | F25: =COUNTIFS('Statistics'!$P$7:$P$58,"S1",'Statistics'!$D$7:$D$58,"") | G25: =IFERROR(E25/B25,0)
A26: Statistics 2: Data presentation and interpretation | B26: =COUNTIFS('Statistics'!$P$7:$P$58,"S2") | C26: =COUNTIFS('Statistics'!$P$7:$P$58,"S2",'Statistics'!$D$7:$D$58,"R") | D26: =COUNTIFS('Statistics'!$P$7:$P$58,"S2",'Statistics'!$D$7:$D$58,"A") | E26: =COUNTIFS('Statistics'!$P$7:$P$58,"S2",'Statistics'!$D$7:$D$58,"G") | F26: =COUNTIFS('Statistics'!$P$7:$P$58,"S2",'Statistics'!$D$7:$D$58,"") | G26: =IFERROR(E26/B26,0)
A27: Statistics 3: Probability | B27: =COUNTIFS('Statistics'!$P$7:$P$58,"S3") | C27: =COUNTIFS('Statistics'!$P$7:$P$58,"S3",'Statistics'!$D$7:$D$58,"R") | D27: =COUNTIFS('Statistics'!$P$7:$P$58,"S3",'Statistics'!$D$7:$D$58,"A") | E27: =COUNTIFS('Statistics'!$P$7:$P$58,"S3",'Statistics'!$D$7:$D$58,"G") | F27: =COUNTIFS('Statistics'!$P$7:$P$58,"S3",'Statistics'!$D$7:$D$58,"") | G27: =IFERROR(E27/B27,0)
A28: Statistics 4: Statistical distributions | B28: =COUNTIFS('Statistics'!$P$7:$P$58,"S4") | C28: =COUNTIFS('Statistics'!$P$7:$P$58,"S4",'Statistics'!$D$7:$D$58,"R") | D28: =COUNTIFS('Statistics'!$P$7:$P$58,"S4",'Statistics'!$D$7:$D$58,"A") | E28: =COUNTIFS('Statistics'!$P$7:$P$58,"S4",'Statistics'!$D$7:$D$58,"G") | F28: =COUNTIFS('Statistics'!$P$7:$P$58,"S4",'Statistics'!$D$7:$D$58,"") | G28: =IFERROR(E28/B28,0)
A29: Statistics 5: Statistical hypothesis testing | B29: =COUNTIFS('Statistics'!$P$7:$P$58,"S5") | C29: =COUNTIFS('Statistics'!$P$7:$P$58,"S5",'Statistics'!$D$7:$D$58,"R") | D29: =COUNTIFS('Statistics'!$P$7:$P$58,"S5",'Statistics'!$D$7:$D$58,"A") | E29: =COUNTIFS('Statistics'!$P$7:$P$58,"S5",'Statistics'!$D$7:$D$58,"G") | F29: =COUNTIFS('Statistics'!$P$7:$P$58,"S5",'Statistics'!$D$7:$D$58,"") | G29: =IFERROR(E29/B29,0)
