Workbook

Sheet Start here
B1: Edexcel A Level Maths: Mechanics
B2: A quick check of how confident you feel on every topic, so revision goes where it's needed most.
B4: How it works
A5: 1 | B5: Open the Mechanics tab | C5: Each topic has a yellow Rating box. Click it and pick R, A or G. That's the only thing to fill in (Notes are optional).
A7: 2 | B7: Be honest, not kind | C7: If you're torn between two colours, pick the lower one. A Green topic gets almost no time, so only use it when you're sure.
A9: 3 | B9: Take your time | C9: 36 topics, most take a glance. About 10 minutes.
B12: What the colours mean
B13: R · Red | C13: I can't do this yet, or I'd probably get it wrong.
B14: A · Amber | C14: I can do some of it, or I'm slow and make mistakes.
B15: G · Green | C15: I can do this confidently in exam conditions.
B17: The tabs
B18: Mechanics | C18: 36 topics for Paper 3, Section B.
B19: Chapter tests | C19: Real exam questions for each textbook chapter. Mark them Done as you go.
B20: Progress | C20: Fills itself in: your Red / Amber / Green totals and a practice plan.
B22: Want to check a topic first?
B23: ▶ Watch | C23: A short Maths Genie video lesson on the topic.
B24: Maths Genie | C24: Exam-style questions for the chapter, with worked answers. 'Topic set' = questions on just that topic.
B25: PMT worksheet | C25: Physics & Maths Tutor questions, the mark scheme and model answers.
B26: Textbook | C26: Where it is in the Pearson textbooks (Pure 1 and 2, Applied 1 and 2), with a chapter test of real exam questions.
B27: Ref and Year | C27: The official specification reference (e.g. P7.4). Y1 = AS / first-year content, Y2 = second year.
B29: The exams
C30: Three 2-hour papers, 100 marks each, each worth a third: Paper 1 and Paper 2 are Pure; Paper 3 is Statistics (Section A) and Mechanics (Section B). Year 1 content is examined too, and Pure can come up on Paper 3.

Sheet Mechanics
A1: Mechanics
A2: Paper 3, Section B · 36 topics · pick R, A or G in the yellow Rating column for each one
A3: ="Rated so far: "&(COUNTIF($D$7:$D$50,"R")+COUNTIF($D$7:$D$50,"A")+COUNTIF($D$7:$D$50,"G"))&" of 36 Red "&COUNTIF($D$7:$D$50,"R")&" · Amber "&COUNTIF($D$7:$D$50,"A")&" · Green "&COUNTIF($D$7:$D$50,"G")
A5: Your check | F5: Maths Genie | I5: PMT worksheet | M5: Textbook chapter test
A6: Ref | B6: Topic | C6: Year | D6: Rating | E6: Notes | F6: Video | G6: Questions | H6: Answers | I6: Worksheet | J6: Questions | K6: Mark scheme | L6: Answers | M6: Textbook | N6: Questions | O6: Mark scheme
A8: 6 | B8: Quantities and units in mechanics | E8: 2 topics · Year 1: 2
A9: M6.1 | B9: SI units and derived quantities | C9: 1 | F9: ▶ Watch | G9: Topic set | H9: Answers | I9: none for this topic | M9: Applied 1 Ch8 | N9: none | P9: M6
A10: OT3.5 | B10: Modelling assumptions (particle, light, inextensible, smooth, rigid) | C10: 1 | F10: ▶ Watch | G10: Topic set | H10: Answers | I10: none for this topic | M10: Applied 1 Ch8 | N10: none | P10: M6
A12: 7 | B12: Kinematics | E12: 15 topics · Year 1: 10 · Year 2: 5
A13: M7.1 | B13: Language of kinematics: position, displacement, distance, velocity, speed, acceleration | C13: 1 | F13: ▶ Watch | G13: Questions | H13: Answers | I13: suvat | J13: Questions | K13: Marks | L13: Answers | M13: Applied 1 Ch9 | N13: Set 1 of 2 | O13: Marks | P13: M7
A14: M7.2 | B14: Displacement-time graphs | C14: 1 | F14: ▶ Watch | G14: Questions | H14: Answers | I14: none for this topic | M14: Applied 1 Ch9 | N14: Set 1 of 2 | O14: Marks | P14: M7
A15: M7.2 | B15: Velocity-time graphs (gradient and area) | C15: 1 | F15: ▶ Watch | G15: Topic set | H15: Answers | I15: Motion Graphs | J15: Questions | K15: Marks | L15: Answers | M15: Applied 1 Ch9 | N15: Set 1 of 2 | O15: Marks | P15: M7
A16: M7.3 | B16: Constant acceleration (suvat) formulae | C16: 1 | F16: ▶ Watch | G16: Questions | H16: Answers | I16: suvat | J16: Questions | K16: Marks | L16: Answers | M16: Applied 1 Ch9 | N16: Set 1 of 2 | O16: Marks | P16: M7
A17: M7.3 | B17: suvat: multi-stage and two-particle problems | C17: 1 | F17: ▶ Watch | G17: Questions | H17: Answers | I17: Motion Graphs | J17: Questions | K17: Marks | L17: Answers | M17: Applied 1 Ch9 | N17: Set 1 of 2 | O17: Marks | P17: M7
A18: M7.3 | B18: Vertical motion under gravity (suvat with g) | C18: 1 | F18: ▶ Watch | G18: Questions | H18: Answers | I18: suvat | J18: Questions | K18: Marks | L18: Answers | M18: Applied 1 Ch9 | N18: Set 1 of 2 | O18: Marks | P18: M7
A19: M7.4 | B19: Variable acceleration: using differentiation | C19: 1 | F19: ▶ Watch | G19: Questions | H19: Answers | I19: Calculus in Kinematics | J19: Questions | K19: Marks | L19: Answers | M19: Applied 1 Ch11 | N19: Questions | O19: Marks | P19: M7
A20: M7.4 | B20: Variable acceleration: maxima and minima | C20: 1 | F20: ▶ Watch | G20: Questions | H20: Answers | I20: Calculus in Kinematics | J20: Questions | K20: Marks | L20: Answers | M20: Applied 1 Ch11 | N20: Questions | O20: Marks | P20: M7
A21: M7.4 | B21: Variable acceleration: using integration | C21: 1 | F21: ▶ Watch | G21: Questions | H21: Answers | I21: Calculus in Kinematics | J21: Questions | K21: Marks | L21: Answers | M21: Applied 1 Ch11 | N21: Questions | O21: Marks | P21: M7
A22: M7.3 | B22: Deriving the suvat formulae (using graphs or calculus) | C22: 1 | F22: ▶ Watch | G22: Questions | H22: Answers | I22: none for this topic | M22: Applied 1 Ch11 | N22: Questions | O22: Marks | P22: M7
A23: M7.3 | B23: Constant acceleration in 2D with vectors | C23: 2 | F23: ▶ Watch | G23: Questions | H23: Answers | I23: suvat (Yr 2) | J23: Questions | K23: Marks | L23: Answers | M23: Applied 2 Ch8 | N23: Set 1 of 2 | O23: Marks | P23: M7
A24: M7.4 | B24: Variable acceleration in 2D: differentiating and integrating vectors | C24: 2 | F24: ▶ Watch | G24: Questions | H24: Answers | I24: Calculus in Kinematics (Yr 2) | J24: Questions | K24: Marks | L24: Answers | M24: Applied 2 Ch8 | N24: Set 1 of 2 | O24: Marks | P24: M7
A25: M7.5 | B25: Projectiles: horizontal projection | C25: 2 | F25: ▶ Watch | G25: Questions | H25: Answers | I25: none for this topic | M25: Applied 2 Ch6 | N25: Questions | O25: Marks | P25: M7
A26: M7.5 | B26: Projectiles at any angle (horizontal and vertical components) | C26: 2 | F26: ▶ Watch | G26: Questions | H26: Answers | I26: Projectiles (Yr 2) | J26: Questions | K26: Marks | L26: Answers | M26: Applied 2 Ch6 | N26: Questions | O26: Marks | P26: M7
A27: M7.5 | B27: Projectile formulae: time of flight, range, maximum height, equation of the path | C27: 2 | F27: ▶ Watch | G27: Questions | H27: Answers | I27: Projectiles (Yr 2) | J27: Questions | K27: Marks | L27: Answers | M27: Applied 2 Ch6 | N27: Questions | O27: Marks | P27: M7
A29: 8 | B29: Forces and Newton's laws | E29: 13 topics · Year 1: 6 · Year 2: 7
A30: M8.1 | B30: Force diagrams, types of force and Newton's first law | C30: 1 | F30: ▶ Watch | G30: Questions | H30: Answers | I30: Forces & Newton's Laws | J30: Questions | K30: Marks | L30: Answers | M30: Applied 1 Ch10 | N30: Questions | O30: Marks | P30: M8
A31: M8.2 | B31: Forces as vectors in i, j form | C31: 1 | F31: ▶ Watch | G31: Questions | H31: Answers | I31: Forces & Newton's Laws | J31: Questions | K31: Marks | L31: Answers | M31: Applied 1 Ch10 | N31: Questions | O31: Marks | P31: M8
A32: M8.2 | B32: Newton's second law F = ma (incl. weight, M8.3) | C32: 1 | F32: ▶ Watch | G32: Questions | H32: Answers | I32: Forces & Newton's Laws | J32: Questions | K32: Marks | L32: Answers | M32: Applied 1 Ch10 | N32: Questions | O32: Marks | P32: M8
A33: M8.2 | B33: F = ma in 2D with vectors | C33: 1 | F33: ▶ Watch | G33: Questions | H33: Answers | I33: Forces & Newton's Laws | J33: Questions | K33: Marks | L33: Answers | M33: Applied 1 Ch10 | N33: Questions | O33: Marks | P33: M8
A34: M8.4 | B34: Connected particles (incl. Newton's third law) | C34: 1 | F34: ▶ Watch | G34: Questions | H34: Answers | I34: Connected Particles (Yr 2) | J34: Questions | K34: Marks | L34: Answers | M34: Applied 1 Ch10 | N34: Questions | O34: Marks | P34: M8
A35: M8.4 | B35: Pulleys | C35: 1 | F35: ▶ Watch | G35: Questions | H35: Answers | I35: Connected Particles (Yr 2) | J35: Questions | K35: Marks | L35: Answers | M35: Applied 1 Ch10 | N35: Questions | O35: Marks | P35: M8
A36: M8.5 | B36: Resolving forces and resultant forces (magnitude-direction form) | C36: 2 | F36: ▶ Watch | G36: Questions | H36: Answers | I36: Forces & Newton's Laws (Yr 2) | J36: Questions | K36: Marks | L36: Answers | M36: Applied 2 Ch5 | N36: Set 1 of 2 | O36: Marks | P36: M8
A37: M8.2 | B37: Inclined planes | C37: 2 | F37: ▶ Watch | G37: Questions | H37: Answers | I37: F = ma on a slope (Yr 2) | J37: Questions | K37: Marks | L37: Answers | M37: Applied 2 Ch5 | N37: Set 1 of 2 | O37: Marks | P37: M8
A38: M8.6 | B38: Friction (F ≤ μR) and limiting friction | C38: 2 | F38: ▶ Watch | G38: Questions | H38: Answers | I38: F = ma on a slope (Yr 2) | J38: Questions | K38: Marks | L38: Answers | M38: Applied 2 Ch5 | N38: Set 1 of 2 | O38: Marks | P38: M8
A39: M8.4 | B39: Statics: particles in equilibrium | C39: 2 | F39: ▶ Watch | G39: Questions | H39: Answers | I39: Forces & Newton's Laws (Yr 2) | J39: Questions | K39: Marks | L39: Answers | M39: Applied 2 Ch7 | N39: Set 1 of 2 | O39: Marks | P39: M8
A40: M8.6 | B40: Friction and static particles (limiting equilibrium) | C40: 2 | F40: ▶ Watch | G40: Questions | H40: Answers | I40: Forces & Newton's Laws (Yr 2) | J40: Questions | K40: Marks | L40: Answers | M40: Applied 2 Ch7 | N40: Set 1 of 2 | O40: Marks | P40: M8
A41: M8.2 | B41: Dynamics on inclined planes | C41: 2 | F41: ▶ Watch | G41: Questions | H41: Answers | I41: F = ma on a slope (Yr 2) | J41: Questions | K41: Marks | L41: Answers | M41: Applied 2 Ch7 | N41: Set 1 of 2 | O41: Marks | P41: M8
A42: M8.4 | B42: Connected particles on slopes and with friction | C42: 2 | F42: ▶ Watch | G42: Questions | H42: Answers | I42: Connected Particles (Yr 2) | J42: Questions | K42: Marks | L42: Answers | M42: Applied 2 Ch7 | N42: Set 1 of 2 | O42: Marks | P42: M8
A44: 9 | B44: Moments | E44: 6 topics · Year 2: 6
A45: M9.1 | B45: Moments of a force | C45: 2 | F45: ▶ Watch | G45: Questions | H45: Answers | I45: Moments (Yr 2) | J45: Questions | K45: Marks | L45: Answers | M45: Applied 2 Ch4 | N45: Questions | O45: Marks | P45: M9
...

Sheet Chapter tests
A1: Chapter tests
A2: Real Edexcel exam questions for each textbook chapter, plus the textbook review exercises. Try one once every topic in it is Amber or Green.
A4: Book | B4: Chapters | C4: Test | D4: Questions | E4: Mark scheme | F4: Done? | G4: Score / notes
A6: Mechanics | C6: Paper 3, Section B
A7: Applied 1 | B7: Ch9 Constant Acceleration | C7: Ch9 Constant Acceleration Exam Questions 1 | D7: Questions | E7: Marks
A8: Applied 1 | B8: Ch9 Constant Acceleration | C8: Ch9 Constant Acceleration Exam Questions 2 | D8: Questions | E8: Marks
A9: Applied 1 | B9: Ch10 Forces and Motion | C9: Ch10 Forces and Motion Exam Questions Excluding Question 1 and 7 | D9: Questions | E9: Marks
A10: Applied 1 | B10: Ch11 Variable Acceleration | C10: Ch11 Variable Acceleration Exam Questions | D10: Questions | E10: Marks
A11: Applied 1 | B11: Ch8-Ch11 review (textbook) | C11: Textbook review exercise 2 - pg. 197-200 | D11: in the book
A12: Applied 2 | B12: Ch4 Moments | C12: Ch4 Moments Exam Questions | D12: Questions | E12: Marks
A13: Applied 2 | B13: Ch6 Projectiles | C13: Ch6 Projectiles Exam Questions | D13: Questions | E13: Marks
A14: Applied 2 | B14: Ch5 Forces and Friction, Ch7 Application of Forces | C14: Ch5 Forces and Friction + Ch7 Application of Forces Exam Questions 1 | D14: Questions | E14: Marks
A15: Applied 2 | B15: Ch5 Forces and Friction, Ch7 Application of Forces | C15: Ch5 Forces and Friction + Ch7 Application of Forces Exam Questions 2 | D15: Questions | E15: Marks
A16: Applied 2 | B16: Ch8 Further Kinematics | C16: Ch8 Further Kinematics Exam Questions 1 | D16: Questions | E16: Marks
A17: Applied 2 | B17: Ch8 Further Kinematics | C17: Ch8 Further Kinematics Exam Questions 2 | D17: Questions | E17: Marks
A18: Applied 2 | B18: Ch4-Ch8 review (textbook) | C18: Textbook review exercise 2 - pg.182-186 | D18: in the book

Sheet Progress
A1: Progress
A2: This page fills itself in from your ratings. Nothing to type here except the yellow cells, if you want to change them.
A4: =TEXT((COUNTIFS('Mechanics'!$D$7:$D$50,"R",'Mechanics'!$C$7:$C$50,">0")+COUNTIFS('Mechanics'!$D$7:$D$50,"A",'Mechanics'!$C$7:$C$50,">0")+COUNTIFS('Mechanics'!$D$7:$D$50,"G",'Mechanics'!$C$7:$C$50,">0"))/36,"0%") | C4: =COUNTIFS('Mechanics'!$D$7:$D$50,"R",'Mechanics'!$C$7:$C$50,">0") | E4: =COUNTIFS('Mechanics'!$D$7:$D$50,"A",'Mechanics'!$C$7:$C$50,">0") | G4: =COUNTIFS('Mechanics'!$D$7:$D$50,"G",'Mechanics'!$C$7:$C$50,">0")
A5: Topics rated (of 36) | C5: Red | E5: Amber | G5: Green
A7: Your practice plan
A8: Rating | B8: Topics | C8: Qs each | D8: Qs total | E8: What to do
A9: Red | B9: =COUNTIFS('Mechanics'!$D$7:$D$50,"R",'Mechanics'!$C$7:$C$50,">0") | C9: 10 | D9: =B9*C9 | E9: Full worksheet, taught first
A10: Amber | B10: =COUNTIFS('Mechanics'!$D$7:$D$50,"A",'Mechanics'!$C$7:$C$50,">0") | C10: 5 | D10: =B10*C10 | E10: Practise until 3 right in a row
A11: Green | B11: =COUNTIFS('Mechanics'!$D$7:$D$50,"G",'Mechanics'!$C$7:$C$50,">0") | C11: 2 | D11: =B11*C11 | E11: 2-question spot check
A12: Not rated yet | B12: =COUNTIFS('Mechanics'!$D$7:$D$50,"",'Mechanics'!$C$7:$C$50,">0")
A13: Total questions | D13: =SUM(D9:D11)
A14: Minutes per question | D14: 6
A15: Hours of practice | D15: =ROUND(D13*D14/60,1)
A16: Chapter tests done | D16: =COUNTIF('Chapter tests'!$F$5:$F$18,"Done")&" of 12"
A18: By year
B19: Topics | C19: Red | D19: Amber | E19: Green | F19: Not rated | G19: % Green
A20: Year 1 (AS content) | B20: =COUNTIFS('Mechanics'!$C$7:$C$50,1) | C20: =COUNTIFS('Mechanics'!$C$7:$C$50,1,'Mechanics'!$D$7:$D$50,"R") | D20: =COUNTIFS('Mechanics'!$C$7:$C$50,1,'Mechanics'!$D$7:$D$50,"A") | E20: =COUNTIFS('Mechanics'!$C$7:$C$50,1,'Mechanics'!$D$7:$D$50,"G") | F20: =COUNTIFS('Mechanics'!$C$7:$C$50,1,'Mechanics'!$D$7:$D$50,"") | G20: =IFERROR(E20/B20,0)
A21: Year 2 | B21: =COUNTIFS('Mechanics'!$C$7:$C$50,2) | C21: =COUNTIFS('Mechanics'!$C$7:$C$50,2,'Mechanics'!$D$7:$D$50,"R") | D21: =COUNTIFS('Mechanics'!$C$7:$C$50,2,'Mechanics'!$D$7:$D$50,"A") | E21: =COUNTIFS('Mechanics'!$C$7:$C$50,2,'Mechanics'!$D$7:$D$50,"G") | F21: =COUNTIFS('Mechanics'!$C$7:$C$50,2,'Mechanics'!$D$7:$D$50,"") | G21: =IFERROR(E21/B21,0)
A23: By topic area
B24: Topics | C24: Red | D24: Amber | E24: Green | F24: Not rated | G24: % Green
A25: Mechanics 6: Quantities and units in mechanics | B25: =COUNTIFS('Mechanics'!$P$7:$P$50,"M6") | C25: =COUNTIFS('Mechanics'!$P$7:$P$50,"M6",'Mechanics'!$D$7:$D$50,"R") | D25: =COUNTIFS('Mechanics'!$P$7:$P$50,"M6",'Mechanics'!$D$7:$D$50,"A") | E25: =COUNTIFS('Mechanics'!$P$7:$P$50,"M6",'Mechanics'!$D$7:$D$50,"G") | F25: =COUNTIFS('Mechanics'!$P$7:$P$50,"M6",'Mechanics'!$D$7:$D$50,"") | G25: =IFERROR(E25/B25,0)
A26: Mechanics 7: Kinematics | B26: =COUNTIFS('Mechanics'!$P$7:$P$50,"M7") | C26: =COUNTIFS('Mechanics'!$P$7:$P$50,"M7",'Mechanics'!$D$7:$D$50,"R") | D26: =COUNTIFS('Mechanics'!$P$7:$P$50,"M7",'Mechanics'!$D$7:$D$50,"A") | E26: =COUNTIFS('Mechanics'!$P$7:$P$50,"M7",'Mechanics'!$D$7:$D$50,"G") | F26: =COUNTIFS('Mechanics'!$P$7:$P$50,"M7",'Mechanics'!$D$7:$D$50,"") | G26: =IFERROR(E26/B26,0)
A27: Mechanics 8: Forces and Newton's laws | B27: =COUNTIFS('Mechanics'!$P$7:$P$50,"M8") | C27: =COUNTIFS('Mechanics'!$P$7:$P$50,"M8",'Mechanics'!$D$7:$D$50,"R") | D27: =COUNTIFS('Mechanics'!$P$7:$P$50,"M8",'Mechanics'!$D$7:$D$50,"A") | E27: =COUNTIFS('Mechanics'!$P$7:$P$50,"M8",'Mechanics'!$D$7:$D$50,"G") | F27: =COUNTIFS('Mechanics'!$P$7:$P$50,"M8",'Mechanics'!$D$7:$D$50,"") | G27: =IFERROR(E27/B27,0)
A28: Mechanics 9: Moments | B28: =COUNTIFS('Mechanics'!$P$7:$P$50,"M9") | C28: =COUNTIFS('Mechanics'!$P$7:$P$50,"M9",'Mechanics'!$D$7:$D$50,"R") | D28: =COUNTIFS('Mechanics'!$P$7:$P$50,"M9",'Mechanics'!$D$7:$D$50,"A") | E28: =COUNTIFS('Mechanics'!$P$7:$P$50,"M9",'Mechanics'!$D$7:$D$50,"G") | F28: =COUNTIFS('Mechanics'!$P$7:$P$50,"M9",'Mechanics'!$D$7:$D$50,"") | G28: =IFERROR(E28/B28,0)
