Workbook

Sheet Topic check
A1: Edexcel IGCSE Mathematics A (4MA1) — Topic check
A2: Please fill this in before our first lesson. It takes about ten minutes. Don't think too hard about any single row.
A4: NAME | B4: TIER | C4: DATE
A7: Green — I could do this in a test tomorrow | D7: RUNNING TOTAL
A8: Amber — I've seen it, but I'd need reminding | D8: =COUNTIF(C13:C127,"Green")&" green "&COUNTIF(C13:C127,"Amber")&" amber "&COUNTIF(C13:C127,"Red")&" red"
A9: Red — I don't recognise this, or I always get it wrong | D9: Fills in as you go.
A10: Rows marked Higher are on the Higher paper only. On Foundation, leave those blank. There is no wrong answer here — an honest red is worth far more to me than a hopeful green.
A12: Topic | B12: Tier | C12: How I feel about it | D12: Anything you want to tell me
A13: 1 Number and the number system
A14: Place value, ordering, rounding to decimal places and significant figures | B14: Both
A15: Four operations with integers, decimals and negative numbers | B15: Both
A16: Factors, multiples, primes, HCF and LCM, prime factorisation | B16: Both
A17: Fractions: simplifying, comparing, all four operations, mixed numbers | B17: Both
A18: Converting between fractions, decimals and percentages | B18: Both
A19: Percentage of an amount; percentage increase and decrease | B19: Both
A20: Percentage change, profit and loss | B20: Both
A21: Reverse percentages (finding the original amount) | B21: Both
A22: Compound interest, depreciation, growth and decay | B22: Both
A23: Ratio: simplifying, sharing in a ratio, the unitary method | B23: Both
A24: Direct and inverse proportion | B24: Both
A25: Compound measures: speed, density and pressure | B25: Both
... A32: Set language, set notation and Venn diagrams | B32: Both
A33: 2 Equations, formulae and identities
A34: Algebraic notation and collecting like terms | B34: Both
A35: Expanding single brackets | B35: Both
A36: Expanding double brackets | B36: Both
A37: Factorising using a common factor | B37: Both
A38: Factorising quadratics of the form x² + bx + c | B38: Both
A39: Factorising quadratics of the form ax² + bx + c | B39: Higher
A40: The difference of two squares | B40: Higher
A41: Substituting numbers into expressions and formulae | B41: Both
A42: Solving linear equations, including x on both sides | B42: Both
A43: Solving equations with brackets and with fractions | B43: Both
A44: Rearranging a formula to change the subject | B44: Both
A45: Rearranging where the new subject appears twice | B45: Higher
... A57: Algebraic proof and reasoning | B57: Higher
A58: 3 Sequences, functions and graphs
A59: Sequences: term-to-term rules and number patterns | B59: Both
A60: The nth term of a linear sequence | B60: Both
A61: The nth term of a quadratic sequence | B61: Higher
...

Sheet Summary
A1: Summary
A2: Fills in on its own as the topic sheet is completed.
A4: Area | B4: Green | C4: Amber | D4: Red | E4: Not yet rated
A5: 1 Number and the number system | B5: =COUNTIF('Topic check'!C14:C32,"Green") | C5: =COUNTIF('Topic check'!C14:C32,"Amber") | D5: =COUNTIF('Topic check'!C14:C32,"Red") | E5: =19-SUM(B5:D5)
A6: 2 Equations, formulae and identities | B6: =COUNTIF('Topic check'!C34:C57,"Green") | C6: =COUNTIF('Topic check'!C34:C57,"Amber") | D6: =COUNTIF('Topic check'!C34:C57,"Red") | E6: =24-SUM(B6:D6)
A7: 3 Sequences, functions and graphs | B7: =COUNTIF('Topic check'!C59:C79,"Green") | C7: =COUNTIF('Topic check'!C59:C79,"Amber") | D7: =COUNTIF('Topic check'!C59:C79,"Red") | E7: =21-SUM(B7:D7)
A8: 4 Geometry and trigonometry | B8: =COUNTIF('Topic check'!C81:C103,"Green") | C8: =COUNTIF('Topic check'!C81:C103,"Amber") | D8: =COUNTIF('Topic check'!C81:C103,"Red") | E8: =23-SUM(B8:D8)
A9: 5 Vectors and transformation geometry | B9: =COUNTIF('Topic check'!C105:C109,"Green") | C9: =COUNTIF('Topic check'!C105:C109,"Amber") | D9: =COUNTIF('Topic check'!C105:C109,"Red") | E9: =5-SUM(B9:D9)
A10: 6 Statistics and probability | B10: =COUNTIF('Topic check'!C111:C127,"Green") | C10: =COUNTIF('Topic check'!C111:C127,"Amber") | D10: =COUNTIF('Topic check'!C111:C127,"Red") | E10: =17-SUM(B10:D10)
A11: Total | B11: =SUM(B5:B10) | C11: =SUM(C5:C10) | D11: =SUM(D5:D10) | E11: =SUM(E5:E10)
A13: We start with the reds in the biggest areas. Ambers get folded into practice. Greens we leave alone.

Sheet Where to practise
A1: Where to practise
A2: All free. Search any topic name from the checklist and you'll find questions on it.
A4: Site | B4: What it's best for
A5: Maths Genie | B5: Past-paper questions sorted by topic and by grade, with worked solutions. Start here.
A6: Physics & Maths Tutor | B6: Edexcel IGCSE 4MA1 questions grouped by topic, with mark schemes.
A7: Corbettmaths | B7: A short video and a worksheet for every topic. The 5-a-day sheets are ideal for daily practice.
A8: Dr Frost Maths | B8: Free account, marks itself, and remembers what you got wrong.
A9: Save My Exams | B9: Revision notes and topic questions for 4MA1 specifically.
A10: Past papers | B10: 4MA1 papers back to 2018, plus the R variants. Always use the real mark scheme.
A12: Check you're getting IGCSE 4MA1 material, not domestic GCSE — the overlap is large but not total, and both IGCSE papers allow a calculator.
