Workbook

Sheet Start here
B1: OCR MEI A Level Maths
B2: OCR A Level Mathematics B (MEI), H640. A quick check of how confident you feel on every topic, so revision goes where it's needed most.
B4: How it works
A5: 1 | B5: Open the Pure / Statistics / Mechanics tabs | C5: Each topic has a yellow Rating box. Click it and pick R, A or G. That's the only thing to fill in (Notes are optional).
A7: 2 | B7: Be honest, not kind | C7: If you're torn between two colours, pick the lower one. A Green topic gets almost no time, so only use it when you're sure.
A9: 3 | B9: Take your time | C9: 245 topics, most take a glance. About 45 minutes, and it's fine to do one tab at a time.
B12: What the colours mean
B13: R · Red | C13: I can't do this yet, or I'd probably get it wrong.
B14: A · Amber | C14: I can do some of it, or I'm slow and make mistakes.
B15: G · Green | C15: I can do this confidently in exam conditions.
B17: The tabs
B18: Pure | C18: 149 topics, examined on Papers 1, 2 and 3.
B19: Statistics | C19: 51 topics, examined on Paper 2.
B20: Mechanics | C20: 45 topics, examined on Paper 1.
B21: OCR MEI sheets | C21: 63 sheets of real OCR MEI exam questions by topic. Mark them Done as you go.
B22: Progress | C22: Fills itself in: your Red / Amber / Green totals and a practice plan.
B24: Want to check a topic first?
B25: ▶ Watch / Topic page | C25: The Maths Genie OCR MEI page for that exact learning outcome ('▶ Watch' when it has a video lesson).
B26: Questions links | C26: Each link lists the questions on that topic. 'Q 3, 7' means questions 3 and 7; 'Q 4–11' means questions 4 to 11. Past-paper sheets use pages instead, e.g. 'Pages 2, 5'. Click to open the PDF at the first one; hover to see which parts. 'none on this topic' means that source has no question on it.
B27: Maths Genie | C27: Maths Genie exam-style questions with worked answers: its OCR MEI booklets where one covers the topic, otherwise its booklet questions on the same skill.
B28: PMT practice | C28: Physics & Maths Tutor sheets: a Solomon topic worksheet (with answers) or Edexcel past-paper questions on the same topic (with mark scheme), for extra practice.
B29: OCR MEI past papers | C29: Real OCR MEI exam questions on the topic. 'Marks' opens the mark scheme at the back of the same PDF.
B30: Ref and Year | C30: The official H640 learning-outcome code (e.g. Mc14 = chain rule). Y1 = also in the AS specification (H630); Y2 = A Level only. LDS = the large data set.
B32: The exams
C33: Three 2-hour papers. Paper 1: Pure Mathematics and Mechanics (100 marks, 36.4%). Paper 2: Pure Mathematics and Statistics (100 marks, 36.4%), including questions on the large data set. Paper 3: Pure Mathematics and Comprehension (75 marks, 27.3%), where mechanics and statistics are assumed knowledge. Any paper can test Year 1 content.

Sheet Pure
A1: Pure maths
A2: OCR MEI Papers 1, 2 and 3 · 149 topics · pick R, A or G in the yellow Rating column for each one
A3: ="Rated so far: "&(COUNTIF($D$7:$D$181,"R")+COUNTIF($D$7:$D$181,"A")+COUNTIF($D$7:$D$181,"G"))&" of 149 Red "&COUNTIF($D$7:$D$181,"R")&" · Amber "&COUNTIF($D$7:$D$181,"A")&" · Green "&COUNTIF($D$7:$D$181,"G")
A5: Your check | F5: Maths Genie | I5: PMT practice | M5: OCR MEI past-paper questions
A6: Ref | B6: Topic | C6: Year | D6: Rating | E6: Notes | F6: Video | G6: Questions | H6: Answers | I6: Worksheet | J6: Questions | K6: Mark scheme | L6: Answers | M6: OCR MEI sheet | N6: Questions | O6: Mark scheme
A8: 1 | B8: Proof | E8: 3 topics · Year 1: 2 · Year 2: 1
A9: Mp1 | B9: Structure of mathematical proof | C9: 1 | F9: Topic page | G9: Q 11, 12, 14, 15, 17, 18, 28, 32 | H9: Answers | I9: Edexcel: Proof | J9: Pages 1–5 | K9: Marks | L9: Answers | M9: Proof (Yr. 1) | N9: Pages 1, 2 | O9: Marks | P9: P1
A10: Mp2 | B10: Disproof by counter example | C10: 1 | F10: Topic page | G10: Q 8, 11, 13, 17, 18, 24, 32, 35 | H10: Answers | I10: Solomon: Mixed exam-style questions on proof | J10: Q 1, 3, 7, 8 | K10: none | L10: Answers | M10: Proof (Yr. 1) | N10: Pages 1, 2 | O10: Marks | P10: P1
A11: Mp3 | B11: Proof by contradiction | C11: 2 | F11: ▶ Watch | G11: Q 13–18 | H11: Answers | I11: Solomon: Mixed exam-style questions on proof | J11: Q 2, 4, 6, 8 | K11: none | L11: Answers | M11: Proof (Yr. 2) | N11: Pages 1, 2 | O11: Marks | P11: P1
A13: 2 | B13: Algebra | E13: 16 topics · Year 1: 14 · Year 2: 2
A14: Ma1 | B14: Algebraic vocabulary and notation | C14: 1 | F14: Topic page | G14: none on this topic | I14: none for this topic | J14: none on this topic | M14: none for this topic | N14: none on this topic | P14: P2
A15: Ma2 | B15: Solve quadratic equations | C15: 1 | F15: ▶ Watch | G15: Q 6, 7, 9 | H15: Answers | I15: Solomon: Quadratics – factorising | J15: Q 3, 6 | K15: none | L15: Answers | M15: Graphs (Yr. 1) | N15: Pages 3, 5, 6 | O15: Marks | P15: P2
A16: Ma3 | B16: Discriminant of a quadratic | C16: 1 | F16: ▶ Watch | G16: Q 1–4, 6–8, 22 | H16: Answers | I16: Edexcel: Inequalities | J16: Pages 1–3 | K16: in the PDF | L16: in the PDF | M16: Graphs (Yr. 1) | N16: Pages 2, 3, 6 | O16: Marks | P16: P2
A17: Ma4 | B17: Linear simultaneous equations | C17: 1 | F17: ▶ Watch | G17: Q 7, 10, 18 | H17: Answers | I17: Solomon: Simultaneous equations | J17: Q 1 | K17: none | L17: Answers | M17: Solution of Equations | N17: Page 1 | O17: Marks | P17: P2
A18: Ma5 | B18: One linear one quadratic simultaneous equations | C18: 1 | F18: ▶ Watch | G18: Q 3, 5–7, 12 | H18: Answers | I18: Edexcel: Simultaneous Equations | J18: Pages 1–4 | K18: in the PDF | L18: in the PDF | M18: Curves | N18: Page 2 | O18: Marks | P18: P2
A19: Ma6 | B19: Points of intersection and solutions | C19: 1 | F19: ▶ Watch | G19: Q 2, 23 | H19: Answers | I19: Edexcel: Transformations and Graphs | J19: Pages 3, 4 | K19: Marks | L19: Answers | M19: Graphs (Yr. 1) | N19: Pages 2, 3, 5, 6 | O19: Marks | P19: P2
A20: Ma7 | B20: Linear inequalities | C20: 1 | F20: ▶ Watch | G20: Q 8, 13 | H20: Answers | I20: Edexcel: Inequalities | J20: Pages 1–4 | K20: in the PDF | L20: in the PDF | M20: Inequalities | N20: Page 1 | O20: Marks | P20: P2
A21: Ma8 | B21: Quadratic inequalities | C21: 1 | F21: ▶ Watch | G21: Q 1, 2, 4, 8–11, 15 | H21: Answers | I21: Edexcel: Inequalities | J21: Pages 1–4 | K21: in the PDF | L21: in the PDF | M21: Inequalities | N21: Page 1 | O21: Marks | P21: P2
A22: Ma9 | B22: Writing inequality solutions with 'and', 'or' or set notation | C22: 1 | F22: Topic page | G22: Q 1, 8, 9, 11, 15 | H22: Answers | I22: Edexcel: Inequalities | J22: Pages 1–4 | K22: in the PDF | L22: in the PDF | M22: Inequalities | N22: Page 1 | O22: Marks | P22: P2
A23: Ma10 | B23: Use and manipulate surds | C23: 1 | F23: ▶ Watch | G23: Q 3, 5 | H23: Answers | I23: Solomon: Surds | J23: Q 2–7, 9 | K23: none | L23: Answers | M23: Surds and Indices | N23: Pages 1–4 | O23: Marks | P23: P2
A24: Ma11 | B24: Rationalise the denominator | C24: 1 | F24: Topic page | G24: Q 6, 8, 9, 11 | H24: Answers | I24: Solomon: Surds | J24: Q 8, 12, 15 | K24: none | L24: Answers | M24: Surds and Indices | N24: Pages 1–4 | O24: Marks | P24: P2
A25: Ma12 | B25: Laws of indices | C25: 1 | F25: ▶ Watch | G25: Q 2, 4, 5, 8, 10 | H25: Answers | I25: Solomon: Indices | J25: Q 2, 3, 7, 11, 12, 14, 15, 17 | K25: none | L25: Answers | M25: Surds and Indices | N25: Pages 1–3 | O25: Marks | P25: P2
A26: Ma13 | B26: Negative, fractional and zero indices | C26: 1 | F26: ▶ Watch | G26: Q 1–3 | H26: Answers | I26: Solomon: Indices | J26: Q 1, 4–6, 9, 10 | K26: none | L26: Answers | M26: Surds and Indices | N26: Pages 1–3 | O26: Marks | P26: P2
A27: Ma14 | B27: Proportional relationships | C27: 1 | F27: Topic page | G27: Q 6 | H27: Answers | I27: none for this topic | J27: none on this topic | M27: none for this topic | N27: none on this topic | P27: P2
A28: Ma15 | B28: Partial fractions | C28: 2 | F28: ▶ Watch | G28: Q 1–4, 10, 12 | H28: Answers | I28: Edexcel: Partial Fractions | J28: Pages 1–3 | K28: Marks | L28: Answers | M28: Partial Fractions | N28: Page 1 | O28: Marks | P28: P2
A29: Ma16 | B29: Simplify rational expressions | C29: 2 | F29: ▶ Watch | G29: Q 18, 19 | H29: Answers | I29: Solomon: Mixed exam-style questions on rational expressions | J29: Q 1–4 | K29: none | L29: Answers | M29: Rational Expressions | N29: Page 1 | O29: Marks | P29: P2
A31: 3 | B31: Functions | E31: 8 topics · Year 1: 2 · Year 2: 6
A32: Mf1 | B32: Add, subtract, multiply and divide polynomials | C32: 1 | F32: ▶ Watch | G32: Q 1, 2, 25, 29, 33 | H32: Answers | I32: Solomon: Polynomials | J32: Q 1–6 | K32: none | L32: Answers | M32: Polynomials | N32: Page 1 | O32: Marks | P32: P3
A33: Mf2 | B33: Factor theorem | C33: 1 | F33: ▶ Watch | G33: Q 1–6, 21, 33 | H33: Answers | I33: Edexcel: Factor Theorem | J33: Pages 1–5 | K33: Marks | L33: Answers | M33: Polynomials | N33: Page 1 | O33: Marks | P33: P3
A34: Mf3 | B34: Definition of a function | C34: 2 | F34: ▶ Watch | G34: Q 6, 11, 20, 21, 23, 24, 29 | H34: Answers | I34: Solomon: Domain, range and values of functions | J34: Q 3–5, 7 | K34: none | L34: Answers | M34: The Language of Functions | N34: Page 1 | O34: Marks | P34: P3
A35: Mf4 | B35: Composite functions | C35: 2 | F35: ▶ Watch | G35: Q 1, 4, 8, 12, 26, 29, 32 | H35: Answers | I35: Solomon: Composite functions | J35: Q 1, 3–5, 7, 8, 10 | K35: none | L35: Answers | M35: The Language of Functions | N35: Page 1 | O35: Marks | P35: P3
A36: Mf5 | B36: Inverse functions and their graphs | C36: 2 | F36: ▶ Watch | G36: Q 2, 5, 8, 13, 19, 31, 33 | H36: Answers | I36: Solomon: Inverse of a function | J36: Q 1–3, 5–8 | K36: none | L36: Answers | M36: The Language of Functions | N36: Page 1 | O36: Marks | P36: P3
A37: Mf6 | B37: The modulus function | C37: 2 | F37: ▶ Watch | G37: Q 7, 16–18, 22, 30 | H37: Answers | I37: Edexcel: Modulus of Functions | J37: Pages 1, 2 | K37: Marks | L37: Answers | M37: The Modulus Function | N37: Pages 1, 2 | O37: Marks | P37: P3
A38: Mf7 | B38: Inequalities with a modulus sign | C38: 2 | F38: Topic page | G38: Q 7, 22, 34 | H38: Answers | I38: Solomon: The modulus function | J38: Q 6 | K38: none | L38: Answers | M38: The Modulus Function | N38: Pages 1, 2 | O38: Marks | P38: P3
A39: Mf8 | B39: Functions in modelling | C39: 2 | F39: ▶ Watch | G39: Q 17, 21, 25 | H39: Answers | I39: Edexcel: Quadratics | J39: Pages 7, 8 | K39: Marks | L39: Answers | M39: Graphs (Yr. 1) | N39: Page 1 | O39: Marks | P39: P3
A41: 4 | B41: Graphs | E41: 9 topics · Year 1: 7 · Year 2: 2
A42: MC1 | B42: Graphs of functions and sketching curves | C42: 1 | F42: Topic page | G42: Q 2, 15, 21 | H42: Answers | I42: Solomon: Graphs of functions | J42: Q 1, 8–10 | K42: none | L42: Answers | M42: Graphs (Yr. 1) | N42: Pages 1, 3–6 | O42: Marks | P42: P4
A43: MC2 | B43: Intersection points with axes | C43: 1 | F43: Topic page | G43: Q 1, 8, 18, 22, 24 | H43: Answers | I43: Solomon: Graphs of functions | J43: Q 2–5, 7 | K43: none | L43: Answers | M43: Graphs (Yr. 1) | N43: Pages 1, 2, 5, 6 | O43: Marks | P43: P4
A44: MC3 | B44: Completing the square for a quadratic curve | C44: 1 | F44: ▶ Watch | G44: Q 12–14, 17–19, 24 | H44: Answers | I44: Solomon: Quadratics – completing the square | J44: Q 1, 2, 4–6 | K44: none | L44: Answers | M44: Graphs (Yr. 1) | N44: Pages 1, 2, 6 | O44: Marks | P44: P4
A45: MC4 | B45: Sketch graphs of simple functions | C45: 1 | F45: ▶ Watch | G45: Q 8, 15, 16, 18, 20–22, 24 | H45: Answers | I45: Edexcel: Transformations and Graphs | J45: Pages 2, 4, 9, 12 | K45: in the PDF | L45: in the PDF | M45: Graphs (Yr. 1) | N45: Pages 1, 4–6 | O45: Marks | P45: P4
...

Sheet Statistics
A1: Statistics
A2: OCR MEI Paper 2 · 51 topics · pick R, A or G in the yellow Rating column for each one
A3: ="Rated so far: "&(COUNTIF($D$7:$D$67,"R")+COUNTIF($D$7:$D$67,"A")+COUNTIF($D$7:$D$67,"G"))&" of 51 Red "&COUNTIF($D$7:$D$67,"R")&" · Amber "&COUNTIF($D$7:$D$67,"A")&" · Green "&COUNTIF($D$7:$D$67,"G")
A5: Your check | F5: Maths Genie | I5: PMT practice | M5: OCR MEI past-paper questions
A6: Ref | B6: Topic | C6: Year | D6: Rating | E6: Notes | F6: Video | G6: Questions | H6: Answers | I6: Worksheet | J6: Questions | K6: Mark scheme | L6: Answers | M6: OCR MEI sheet | N6: Questions | O6: Mark scheme
A8: 1 | B8: Sampling | E8: 5 topics · Year 1: 5
A9: Mp21 | B9: Population and sample | C9: 1 | F9: ▶ Watch | G9: Q 4, 8 | H9: Answers | I9: Edexcel: Sampling methods 1 | J9: Pages 1–5 | K9: in the PDF | L9: in the PDF | M9: Data Presentation and Interpretation | N9: Page 11 | O9: Marks | P9: S1
A10: Mp22 | B10: Using samples to make informal inferences | C10: 1 | F10: Topic page | G10: Q 1 | H10: Answers | I10: Edexcel: Large data sets | J10: Pages 2, 5, 6 | K10: Marks | L10: Answers | M10: Data Presentation and Interpretation | N10: Pages 11, 15, 25 | O10: Marks | P10: S1
A11: Mp23 | B11: Random sampling | C11: 1 | F11: Topic page | G11: none on this topic | I11: Edexcel: Sampling methods 2 | J11: Pages 3, 4 | K11: in the PDF | L11: in the PDF | M11: Data Presentation and Interpretation | N11: Pages 8, 11, 15, 20, 25 | O11: Marks | P11: S1
A12: Mp24 | B12: Variety of sampling techniques | C12: 1 | F12: ▶ Watch | G12: Q 1–3, 5–8 | H12: Answers | I12: Edexcel: Sampling methods 2 | J12: Pages 1–5 | K12: in the PDF | L12: in the PDF | M12: Sampling | N12: Page 1 | O12: Marks | P12: S1
A13: Mp25 | B13: Select or evaluate sampling techniques | C13: 1 | F13: Topic page | G13: Q 4–8 | H13: Answers | I13: Edexcel: Sampling methods 2 | J13: Pages 1–5 | K13: in the PDF | L13: in the PDF | M13: Sampling | N13: Page 1 | O13: Marks | P13: S1
A15: 2 | B15: Data presentation and interpretation | E15: 15 topics · Year 1: 15
A16: MD1 | B16: Types of data and standard diagrams | C16: 1 | F16: ▶ Watch | G16: Q 1–3 | H16: Answers | I16: Edexcel: Representation and summary data | J16: Pages 13, 19, 23, 25, 27, 28, 31 | K16: in the PDF | L16: in the PDF | M16: Data Presentation and Interpretation | N16: Pages 2, 5, 9, 22, 26 | O16: Marks | P16: S2
A17: MD2 | B17: Area in a histogram is proportional to frequency | C17: 1 | F17: ▶ Watch | G17: Q 1–3, 5–8 | H17: Answers | I17: Edexcel: Representation and summary data | J17: Pages 1, 5, 8, 13, 16, 19, 29, 31 | K17: in the PDF | L17: in the PDF | M17: Data Presentation and Interpretation | N17: Pages 1, 4, 5, 19, 26 | O17: Marks | P17: S2
A18: MD3 | B18: Cumulative frequency diagram | C18: 1 | F18: ▶ Watch | G18: none on this topic | I18: none for this topic | J18: none on this topic | M18: Data Presentation and Interpretation | N18: Pages 2, 4, 17 | O18: Marks | P18: S2
A19: MD4 | B19: Describe frequency distributions | C19: 1 | F19: ▶ Watch | G19: Q 6 | H19: Answers | I19: Edexcel: Representation and summary data | J19: Pages 1, 3, 8, 13, 22, 26, 31, 32 | K19: in the PDF | L19: in the PDF | M19: Data Presentation and Interpretation | N19: Pages 2, 5, 10, 17, 21, 22, 25 | O19: Marks | P19: S2
A20: MD5 | B20: Samples and theoretical distributions (larger samples, closer fit) | C20: 1 | F20: Topic page | G20: none on this topic | I20: none for this topic | J20: none on this topic | M20: none for this topic | N20: none on this topic | P20: S2
A21: MD6 | B21: Interpret a scatter diagram | C21: 1 | F21: ▶ Watch | G21: Q 1–3 | H21: Answers | I21: Edexcel: Regression and Correlation | J21: Pages 1–3 | K21: none | L21: Answers | M21: Data Presentation and Interpretation | N21: Pages 11, 15, 20, 23 | O21: Marks | P21: S2
A22: MD7 | B22: Distinct sections and outliers in scatter diagrams | C22: 1 | F22: Topic page | G22: none on this topic | I22: Edexcel: Representation and summary data | J22: Page 14 | K22: in the PDF | L22: in the PDF | M22: Data Presentation and Interpretation | N22: Pages 11, 20 | O22: Marks | P22: S2
A23: MD8 | B23: Correlation and causation | C23: 1 | F23: ▶ Watch | G23: Q 5, 7 | H23: Answers | I23: Edexcel: Regression and Correlation | J23: Pages 1, 2, 4 | K23: Marks | L23: Answers | M23: Data Presentation and Interpretation | N23: Pages 9, 11, 15, 20 | O23: Marks | P23: S2
A24: MD9 | B24: Select or critique data presentation techniques | C24: 1 | F24: Topic page | G24: Q 5 | H24: Answers | I24: Edexcel: Representation and summary data | J24: Pages 19, 23, 27 | K24: in the PDF | L24: in the PDF | M24: Data Presentation and Interpretation | N24: Pages 14, 19, 20, 26 | O24: Marks | P24: S2
A25: MD10 | B25: Measures of central tendency | C25: 1 | F25: ▶ Watch | G25: Q 1–4 | H25: Answers | I25: Edexcel: Representation and summary data | J25: Pages 8, 9, 17, 21, 29, 31 | K25: in the PDF | L25: in the PDF | M25: Data Presentation and Interpretation | N25: Pages 1, 5, 9, 11, 19, 21 | O25: Marks | P25: S2
A26: MD11 | B26: Simple measures of spread | C26: 1 | F26: Topic page | G26: Q 1, 2, 4, 6, 8 | H26: Answers | I26: Edexcel: Representation and summary data | J26: Pages 2, 8, 12, 25, 26, 31–33 | K26: in the PDF | L26: in the PDF | M26: Data Presentation and Interpretation | N26: Pages 2, 4, 7, 10, 17, 25 | O26: Marks | P26: S2
A27: MD12 | B27: Variance and standard deviation | C27: 1 | F27: ▶ Watch | G27: Q 2–6, 8 | H27: Answers | I27: Edexcel: Representation and summary data | J27: Pages 1, 3, 5, 12, 23, 28–30 | K27: in the PDF | L27: in the PDF | M27: Data Presentation and Interpretation | N27: Pages 2, 4, 5, 7, 8, 11, 16, 21 | O27: Marks | P27: S2
A28: MD13 | B28: Outliers | C28: 1 | F28: ▶ Watch | G28: Q 1–5, 7, 8 | H28: Answers | I28: Edexcel: Representation and summary data | J28: Pages 2, 6, 12, 24, 30–32 | K28: in the PDF | L28: in the PDF | M28: Data Presentation and Interpretation | N28: Pages 2, 4, 7, 8, 10, 17, 21 | O28: Marks | P28: S2
A29: MD14 | B29: Cleaning data | C29: 1 | F29: Topic page | G29: Q 3, 4, 6, 8 | H29: Answers | I29: Edexcel: Data Presentation | J29: Pages 3, 6 | K29: none | L29: Answers | M29: Data Presentation and Interpretation | N29: Pages 2, 8, 26 | O29: Marks | P29: S2
A30: LDS | B30: The OCR MEI large data set (familiarity and context) | C30: 1 | F30: Topic page | G30: Q 1–8 | H30: Answers | I30: none for this topic | J30: none on this topic | M30: Data Presentation and Interpretation | N30: Pages 9, 11, 15, 20, 24, 26 | O30: Marks | P30: S2
A32: 3 | B32: Probability | E32: 7 topics · Year 1: 3 · Year 2: 4
A33: Mu1 | B33: Mutually exclusive and independent events | C33: 1 | F33: ▶ Watch | G33: Q 1, 2, 4–6 | H33: Answers | I33: Edexcel: Probability | J33: Pages 1, 2, 4, 8 | K33: none | L33: Answers | M33: Probability (Yr. 1) | N33: Pages 1, 3, 4 | O33: Marks | P33: S3
A34: Mu2 | B34: Add probabilities for mutually exclusive events | C34: 1 | F34: Topic page | G34: Q 2, 3, 6 | H34: Answers | I34: Edexcel: Probability | J34: Pages 3, 5, 15–17 | K34: in the PDF | L34: in the PDF | M34: Probability (Yr. 1) | N34: Pages 1, 3 | O34: Marks | P34: S3
A35: Mu3 | B35: Multiply probabilities for independent events | C35: 1 | F35: Topic page | G35: Q 1, 5 | H35: Answers | I35: Edexcel: Probability | J35: Pages 1, 15–17 | K35: in the PDF | L35: in the PDF | M35: Probability (Yr. 1) | N35: Pages 1–4 | O35: Marks | P35: S3
A36: Mu4 | B36: Mutually exclusive and independent events: notation and definitions | C36: 2 | F36: Topic page | G36: Q 2, 3, 9, 10 | H36: Answers | I36: Edexcel: Probability | J36: Pages 2, 5, 6, 11, 15, 19 | K36: in the PDF | L36: in the PDF | M36: Probability (Yr. 2) | N36: Pages 1, 2, 4 | O36: Marks | P36: S3
A37: Mu5 | B37: Venn diagrams for probabilities | C37: 2 | F37: ▶ Watch | G37: Q 1–7 | H37: Answers | I37: Edexcel: Probability | J37: Pages 2, 3, 7, 8, 10, 11, 13, 14 | K37: in the PDF | L37: in the PDF | M37: Probability (Yr. 2) | N37: Pages 1–3 | O37: Marks | P37: S3
A38: Mu6 | B38: Conditional probabilities | C38: 2 | F38: ▶ Watch | G38: Q 1, 2, 4, 6–8, 10 | H38: Answers | I38: Edexcel: Probability | J38: Pages 2, 3, 7, 8, 10, 12, 13, 19 | K38: in the PDF | L38: in the PDF | M38: Probability (Yr. 2) | N38: Pages 1–4 | O38: Marks | P38: S3
A39: Mu7 | B39: Independence via conditional probability | C39: 2 | F39: Topic page | G39: Q 2, 3, 9, 10 | H39: Answers | I39: Edexcel: Conditional Probability | J39: Pages 1, 3, 4 | K39: none | L39: Answers | M39: Probability (Yr. 2) | N39: Pages 1, 2, 4 | O39: Marks | P39: S3
A41: 4 | B41: Probability distributions | E41: 13 topics · Year 1: 7 · Year 2: 6
A42: MR1 | B42: Recognise binomial situations | C42: 1 | F42: Topic page | G42: Q 12 | H42: Answers | I42: Edexcel: Discrete distributions - Binomial | J42: Pages 1, 11, 14 | K42: in the PDF | L42: in the PDF | M42: Hypothesis Testing for Binomial Probabilities | N42: Page 10 | O42: Marks | P42: S4
A43: MR2 | B43: Probability of success p | C43: 1 | F43: Topic page | G43: Q 7, 8, 10 | H43: Answers | I43: Edexcel: Discrete distributions - Binomial | J43: Pages 2, 4, 8, 9, 11, 13, 14 | K43: in the PDF | L43: in the PDF | M43: Hypothesis Testing for Binomial Probabilities | N43: Pages 2, 10 | O43: Marks | P43: S4
A44: MR3 | B44: Calculate binomial probabilities | C44: 1 | F44: ▶ Watch | G44: Q 5–8, 10, 14 | H44: Answers | I44: Edexcel: Discrete distributions - Binomial | J44: Pages 1–5, 7, 10, 14 | K44: in the PDF | L44: in the PDF | M44: Binomial Distribution | N44: Pages 1–4 | O44: Marks | P44: S4
A45: MR4 | B45: Mean of the binomial distribution | C45: 1 | F45: Topic page | G45: none on this topic | I45: Edexcel: Discrete distributions - Binomial | J45: Page 9 | K45: in the PDF | L45: in the PDF | M45: Hypothesis Testing for Binomial Probabilities | N45: Pages 1, 4, 5, 10 | O45: Marks | P45: S4
...

Sheet Mechanics
A1: Mechanics
A2: OCR MEI Paper 1 · 45 topics · pick R, A or G in the yellow Rating column for each one
A3: ="Rated so far: "&(COUNTIF($D$7:$D$65,"R")+COUNTIF($D$7:$D$65,"A")+COUNTIF($D$7:$D$65,"G"))&" of 45 Red "&COUNTIF($D$7:$D$65,"R")&" · Amber "&COUNTIF($D$7:$D$65,"A")&" · Green "&COUNTIF($D$7:$D$65,"G")
A5: Your check | F5: Maths Genie | I5: PMT practice | M5: OCR MEI past-paper questions
A6: Ref | B6: Topic | C6: Year | D6: Rating | E6: Notes | F6: Video | G6: Questions | H6: Answers | I6: Worksheet | J6: Questions | K6: Mark scheme | L6: Answers | M6: OCR MEI sheet | N6: Questions | O6: Mark scheme
A8: 1 | B8: Models and quantities | E8: 5 topics · Year 1: 4 · Year 2: 1
A9: Mp31 | B9: Language of simplifying assumptions | C9: 1 | F9: Topic page | G9: Q 2, 3, 5, 7 | H9: Answers | I9: Edexcel: Connected particles | J9: Pages 2, 5–8, 11–13 | K9: in the PDF | L9: in the PDF | M9: Calculus in Kinematics | N9: Pages 3, 4 | O9: Marks | P9: M1
A10: Mp32 | B10: The particle model | C10: 1 | F10: Topic page | G10: Q 1, 2, 6 | H10: Answers | I10: Edexcel: Moments - Moments about a point 1 | J10: Pages 3, 10 | K10: in the PDF | L10: in the PDF | M10: none for this topic | N10: none on this topic | P10: M1
A11: Mp33 | B11: Fundamental quantities and units | C11: 1 | F11: Topic page | G11: none on this topic | I11: none for this topic | J11: none on this topic | M11: none for this topic | N11: none on this topic | P11: M1
A12: Mp34 | B12: Derived quantities and units | C12: 1 | F12: Topic page | G12: Q 3 | H12: Answers | I12: Edexcel: by Graphical Methods | J12: Page 1 | K12: Marks | L12: Answers | M12: none for this topic | N12: none on this topic | P12: M1
A13: Mp35 | B13: Derived quantity: moment | C13: 2 | F13: Topic page | G13: none on this topic | I13: none for this topic | J13: none on this topic | M13: Rigid Bodies in Equilibrium | N13: Page 3 | O13: Marks | P13: M1
A15: 2 | B15: Kinematics in 1 dimension | E15: 8 topics · Year 1: 8
A16: Mk1 | B16: Language of kinematics | C16: 1 | F16: ▶ Watch | G16: none on this topic | I16: Edexcel: Uniform Acceleration Formulae | J16: Pages 1, 3 | K16: Marks | L16: Answers | M16: Motion in 1 Dimension, Kinematics Graphs and Constant Acceleration Formulae | N16: Page 5 | O16: Marks | P16: M2
A17: Mk2 | B17: Position, displacement, distance and distance travelled | C17: 1 | F17: Topic page | G17: Q 1, 4, 7, 9 | H17: Answers | I17: Edexcel: Problems in Calculus | J17: Pages 1–3 | K17: Marks | L17: Answers | M17: Calculus in Kinematics | N17: Pages 1, 4 | O17: Marks | P17: M2
A18: Mk3 | B18: Velocity, speed and acceleration distinctions | C18: 1 | F18: Topic page | G18: Q 6, 7 | H18: Answers | I18: Edexcel: Problems in Calculus | J18: Page 3 | K18: Marks | L18: Answers | M18: Calculus in Kinematics | N18: Pages 1, 4 | O18: Marks | P18: M2
A19: Mk4 | B19: Draw and interpret kinematics graphs | C19: 1 | F19: ▶ Watch | G19: Q 1–4 | H19: Answers | I19: Edexcel: by graphical methods | J19: Pages 1–5, 7 | K19: in the PDF | L19: in the PDF | M19: Motion in 1 Dimension, Kinematics Graphs and Constant Acceleration Formulae | N19: Pages 1–5 | O19: Marks | P19: M2
A20: Mk5 | B20: Differentiate position and velocity | C20: 1 | F20: ▶ Watch | G20: Q 4, 5, 8, 9, 11 | H20: Answers | I20: Edexcel: Problems in Calculus | J20: Pages 1–3 | K20: Marks | L20: Answers | M20: Calculus in Kinematics | N20: Pages 1, 4 | O20: Marks | P20: M2
A21: Mk6 | B21: Integrate acceleration and velocity | C21: 1 | F21: ▶ Watch | G21: Q 1–4, 6, 7, 10, 12 | H21: Answers | I21: Edexcel: Problems with calculus | J21: Pages 1–5 | K21: in the PDF | L21: in the PDF | M21: Calculus in Kinematics | N21: Pages 2–4 | O21: Marks | P21: M2
A22: Mk7 | B22: When constant acceleration formulae apply | C22: 1 | F22: Topic page | G22: Q 4, 8 | H22: Answers | I22: Edexcel: by Graphical Methods | J22: Page 1 | K22: none | L22: Answers | M22: Motion in 1 Dimension, Kinematics Graphs and Constant Acceleration Formulae | N22: Page 6 | O22: Marks | P22: M2
A23: Mk8 | B23: Solve 1-D kinematics problems | C23: 1 | F23: ▶ Watch | G23: Q 2, 5–10, 15 | H23: Answers | I23: Edexcel: Uniform acceleration formulae | J23: Pages 1, 4–7, 9 | K23: in the PDF | L23: in the PDF | M23: Motion in 1 Dimension, Kinematics Graphs and Constant Acceleration Formulae | N23: Pages 1–5 | O23: Marks | P23: M2
A25: 3 | B25: Kinematics in 2 dimensions | E25: 4 topics · Year 2: 4
A26: Mk9 | B26: Language of kinematics in 2 dimensions | C26: 2 | F26: Topic page | G26: Q 2–4, 12, 16, 21 | H26: Answers | I26: Edexcel: Problems with vectors 1 | J26: Pages 1, 4, 5, 7, 9 | K26: in the PDF | L26: in the PDF | M26: Motion in 2 Dimensions | N26: Pages 1–3 | O26: Marks | P26: M3
A27: Mk10 | B27: Extending 1-D kinematics to 2-D using vectors | C27: 2 | F27: ▶ Watch | G27: Q 1, 10, 13, 14, 16–19 | H27: Answers | I27: Edexcel: Problems in Calculus | J27: Pages 5–10 | K27: none | L27: Answers | M27: Motion in 2 Dimensions | N27: Pages 1–4 | O27: Marks | P27: M3
A28: Mk11 | B28: Cartesian equation of a path | C28: 2 | F28: Topic page | G28: Q 6 | H28: Answers | I28: Edexcel: Projectiles 2 | J28: Pages 2, 3 | K28: in the PDF | L28: in the PDF | M28: Motion in 2 Dimensions | N28: Pages 2–4 | O28: Marks | P28: M3
A29: Mk12 | B29: Vectors to solve kinematics problems | C29: 2 | F29: ▶ Watch | G29: Q 5, 7–9, 12, 14, 18, 20 | H29: Answers | I29: Edexcel: Problems with vectors 1 | J29: Pages 1, 3, 4, 6–10 | K29: in the PDF | L29: in the PDF | M29: Motion in 2 Dimensions | N29: Pages 1–4 | O29: Marks | P29: M3
A31: 4 | B31: Projectiles | E31: 5 topics · Year 2: 5
A32: My1 | B32: Model motion under gravity using vectors | C32: 2 | F32: ▶ Watch | G32: Q 2, 5, 7–9 | H32: Answers | I32: Edexcel: Projectiles 2 | J32: Pages 2, 4, 8, 11 | K32: in the PDF | L32: in the PDF | M32: Motion Under Gravity in Two Dimensions | N32: Pages 3, 4, 8 | O32: Marks | P32: M4
A33: My2 | B33: Position, velocity, range and maximum height | C33: 2 | F33: ▶ Watch | G33: Q 1–7, 9 | H33: Answers | I33: Edexcel: Projectiles 2 | J33: Pages 1, 4–6, 9, 11–13 | K33: in the PDF | L33: in the PDF | M33: Motion Under Gravity in Two Dimensions | N33: Pages 1–3, 5, 7, 8 | O33: Marks | P33: M4
A34: My3 | B34: Find the initial velocity of a projectile | C34: 2 | F34: Topic page | G34: Q 3–5, 7–9 | H34: Answers | I34: Edexcel: Projectiles 2 | J34: Pages 1, 4, 8, 9, 11, 12 | K34: in the PDF | L34: in the PDF | M34: Motion Under Gravity in Two Dimensions | N34: Pages 5, 6, 8 | O34: Marks | P34: M4
A35: My4 | B35: Equation of the trajectory | C35: 2 | F35: Topic page | G35: Q 6 | H35: Answers | I35: Edexcel: Projectiles 2 | J35: Pages 2, 3 | K35: in the PDF | L35: in the PDF | M35: Motion Under Gravity in Two Dimensions | N35: Pages 3, 7 | O35: Marks | P35: M4
A36: My5 | B36: Solve simple projectile problems | C36: 2 | F36: ▶ Watch | G36: Q 2–9 | H36: Answers | I36: Edexcel: Projectiles 2 | J36: Pages 1, 3, 5, 8, 9, 12, 13 | K36: in the PDF | L36: in the PDF | M36: Motion Under Gravity in Two Dimensions | N36: Pages 1–5, 7 | O36: Marks | P36: M4
A38: 5 | B38: Forces | E38: 12 topics · Year 1: 5 · Year 2: 7
A39: MF1 | B39: Language relating to forces | C39: 1 | F39: Topic page | G39: Q 8 | H39: Answers | I39: Edexcel: F = ma on a slope | J39: Page 3 | K39: none | L39: Answers | M39: Forces | N39: Page 1 | O39: Marks | P39: M5
A40: MF2 | B40: Acceleration due to gravity | C40: 1 | F40: Topic page | G40: none on this topic | I40: none for this topic | J40: none on this topic | M40: Motion Under Gravity in Two Dimensions | N40: Page 6 | O40: Marks | P40: M5
A41: MF3 | B41: Identify forces and draw force diagrams | C41: 1 | F41: ▶ Watch | G41: none on this topic | I41: Edexcel: Statics - Equilibrium problems | J41: Page 2 | K41: in the PDF | L41: in the PDF | M41: Forces | N41: Page 1 | O41: Marks | P41: M5
A42: MF4 | B42: Resultant of concurrent forces | C42: 1 | F42: ▶ Watch | G42: Q 9, 12 | H42: Answers | I42: Edexcel: Statics | J42: Page 3 | K42: in the PDF | L42: in the PDF | M42: Vectors (Yr. 1) | N42: Page 1 | O42: Marks | P42: M5
A43: MF5 | B43: Equilibrium of a particle | C43: 1 | F43: Topic page | G43: Q 6 | H43: Answers | I43: none for this topic | J43: none on this topic | M43: Forces | N43: Pages 1, 2 | O43: Marks | P43: M5
A44: MF6 | B44: Resolve a force into components | C44: 2 | F44: ▶ Watch | G44: Q 1, 2, 8 | H44: Answers | I44: Edexcel: Statics | J44: Pages 1, 2, 4, 5 | K44: in the PDF | L44: in the PDF | M44: Vector Treatment of Forces | N44: Pages 1–3 | O44: Marks | P44: M5
A45: MF7 | B45: Equilibrium condition for resultant zero | C45: 2 | F45: Topic page | G45: Q 1, 2 | H45: Answers | I45: Edexcel: Statics - Equilibrium problems | J45: Pages 4, 5, 7, 9, 12, 13 | K45: in the PDF | L45: in the PDF | M45: Vector Treatment of Forces | N45: Pages 1–3 | O45: Marks | P45: M5
A46: MF8 | B46: Forces in equilibrium sum to zero | C46: 2 | F46: Topic page | G46: Q 6 | H46: Answers | I46: Edexcel: Statics - Equilibrium problems | J46: Pages 5, 9, 12, 13 | K46: in the PDF | L46: in the PDF | M46: Forces | N46: Page 1 | O46: Marks | P46: M5
...

Sheet OCR MEI sheets
A1: OCR MEI topic sheets
A2: Real OCR MEI exam questions grouped by topic, with the mark scheme at the back of each PDF. Try a sheet once most of its topics are Amber or Green.
A4: Sheet | B4: Questions | C4: Mark scheme | D4: Done? | E4: Score / notes
A6: Pure maths · Papers 1, 2 and 3
A7: Graphs (Yr. 1) | B7: Questions | C7: Marks
A8: Inequalities | B8: Questions | C8: Marks
A9: Polynomials | B9: Questions | C9: Marks
A10: Solution of Equations | B10: Questions | C10: Marks
A11: Surds and Indices | B11: Questions | C11: Marks
A12: Graphs (Yr. 2) | B12: Questions | C12: Marks
A13: Partial Fractions | B13: Questions | C13: Marks
A14: Rational Expressions | B14: Questions | C14: Marks
A15: The Language of Functions | B15: Questions | C15: Marks
A16: The Modulus Function | B16: Questions | C16: Marks
A17: Curves | B17: Questions | C17: Marks
A18: Straight Lines | B18: Questions | C18: Marks
... A49: Vectors (Yr. 2) | B49: Questions | C49: Marks
A51: Statistics · Paper 2
A52: Data Presentation and Interpretation | B52: Questions | C52: Marks
A53: Hypothesis Testing for Binomial Probabilities | B53: Questions | C53: Marks
A54: Hypothesis Testing for Correlation and Association | B54: Questions | C54: Marks
A55: Hypothesis Testing for Normal Mean | B55: Questions | C55: Marks
A56: Probability (Yr. 1) | B56: Questions | C56: Marks
A57: Probability (Yr. 2) | B57: Questions | C57: Marks
A58: Binomial Distribution | B58: Questions | C58: Marks
A59: Discrete Probability Distributions | B59: Questions | C59: Marks
A60: Normal Distribution | B60: Questions | C60: Marks
A61: Sampling | B61: Questions | C61: Marks
A63: Mechanics · Paper 1
A64: Forces | B64: Questions | C64: Marks
A65: Newton's Laws of Motion (Yr. 1) | B65: Questions | C65: Marks
A66: Frictional Force and Normal Contact Force | B66: Questions | C66: Marks
A67: Newton's Laws of Motion (Yr. 2) | B67: Questions | C67: Marks
A68: Rigid Bodies in Equilibrium | B68: Questions | C68: Marks
A69: Vector Treatment of Forces | B69: Questions | C69: Marks
A70: Calculus in Kinematics | B70: Questions | C70: Marks
A71: Motion in 1 Dimension, Kinematics Graphs and Constant Acceleration Formulae | B71: Questions | C71: Marks
A72: Motion Under Gravity in Two Dimensions | B72: Questions | C72: Marks
A73: Motion in 2 Dimensions | B73: Questions | C73: Marks

Sheet Progress
A1: Progress
A2: This page fills itself in from your ratings. Nothing to type here except the yellow cells, if you want to change them.
A4: =TEXT((COUNTIFS('Pure'!$D$7:$D$181,"R",'Pure'!$C$7:$C$181,">0")+COUNTIFS('Statistics'!$D$7:$D$67,"R",'Statistics'!$C$7:$C$67,">0")+COUNTIFS('Mechanics'!$D$7:$D$65,"R",'Mechanics'!$C$7:$C$65,">0")+COUNTIFS('Pure'!$D$7:$D$181,"A",'Pure'!$C$7:$C$181,">0")+COUNTIFS('Statistics'!$D$7:$D$67,"A",'Statistics'!$C$7:$C$67,">0")+COUNTIFS('Mechanics'!$D$7:$D$65,"A",'Mechanics'!$C$7:$C$65,">0")+COUNTIFS('Pure'!$D$7:$D$181,"G",'Pure'!$C$7:$C$181,">0")+COUNTIFS('Statistics'!$D$7:$D$67,"G",'Statistics'!$C$7:$C$67,">0")+COUNTIFS('Mechanics'!$D$7:$D$65,"G",'Mechanics'!$C$7:$C$65,">0"))/245,"0%") | C4: =COUNTIFS('Pure'!$D$7:$D$181,"R",'Pure'!$C$7:$C$181,">0")+COUNTIFS('Statistics'!$D$7:$D$67,"R",'Statistics'!$C$7:$C$67,">0")+COUNTIFS('Mechanics'!$D$7:$D$65,"R",'Mechanics'!$C$7:$C$65,">0") | E4: =COUNTIFS('Pure'!$D$7:$D$181,"A",'Pure'!$C$7:$C$181,">0")+COUNTIFS('Statistics'!$D$7:$D$67,"A",'Statistics'!$C$7:$C$67,">0")+COUNTIFS('Mechanics'!$D$7:$D$65,"A",'Mechanics'!$C$7:$C$65,">0") | G4: =COUNTIFS('Pure'!$D$7:$D$181,"G",'Pure'!$C$7:$C$181,">0")+COUNTIFS('Statistics'!$D$7:$D$67,"G",'Statistics'!$C$7:$C$67,">0")+COUNTIFS('Mechanics'!$D$7:$D$65,"G",'Mechanics'!$C$7:$C$65,">0")
A5: Topics rated (of 245) | C5: Red | E5: Amber | G5: Green
A7: Your practice plan
A8: Rating | B8: Topics | C8: Qs each | D8: Qs total | E8: What to do
A9: Red | B9: =COUNTIFS('Pure'!$D$7:$D$181,"R",'Pure'!$C$7:$C$181,">0")+COUNTIFS('Statistics'!$D$7:$D$67,"R",'Statistics'!$C$7:$C$67,">0")+COUNTIFS('Mechanics'!$D$7:$D$65,"R",'Mechanics'!$C$7:$C$65,">0") | C9: 10 | D9: =B9*C9 | E9: Full worksheet, taught first
A10: Amber | B10: =COUNTIFS('Pure'!$D$7:$D$181,"A",'Pure'!$C$7:$C$181,">0")+COUNTIFS('Statistics'!$D$7:$D$67,"A",'Statistics'!$C$7:$C$67,">0")+COUNTIFS('Mechanics'!$D$7:$D$65,"A",'Mechanics'!$C$7:$C$65,">0") | C10: 5 | D10: =B10*C10 | E10: Practise until 3 right in a row
A11: Green | B11: =COUNTIFS('Pure'!$D$7:$D$181,"G",'Pure'!$C$7:$C$181,">0")+COUNTIFS('Statistics'!$D$7:$D$67,"G",'Statistics'!$C$7:$C$67,">0")+COUNTIFS('Mechanics'!$D$7:$D$65,"G",'Mechanics'!$C$7:$C$65,">0") | C11: 2 | D11: =B11*C11 | E11: 2-question spot check
A12: Not rated yet | B12: =COUNTIFS('Pure'!$C$7:$C$181,">0")+COUNTIFS('Statistics'!$C$7:$C$67,">0")+COUNTIFS('Mechanics'!$C$7:$C$65,">0")-B9-B10-B11
A13: Total questions | D13: =SUM(D9:D11)
A14: Minutes per question | D14: 6
A15: Hours of practice | D15: =ROUND(D13*D14/60,1)
A16: OCR MEI topic sheets done | D16: =COUNTIF('OCR MEI sheets'!$D$5:$D$73,"Done")&" of 63"
A18: By year
B19: Topics | C19: Red | D19: Amber | E19: Green | F19: Not rated | G19: % Green
A20: Year 1 (AS content) | B20: =COUNTIFS('Pure'!$C$7:$C$181,1)+COUNTIFS('Statistics'!$C$7:$C$67,1)+COUNTIFS('Mechanics'!$C$7:$C$65,1) | C20: =COUNTIFS('Pure'!$C$7:$C$181,1,'Pure'!$D$7:$D$181,"R")+COUNTIFS('Statistics'!$C$7:$C$67,1,'Statistics'!$D$7:$D$67,"R")+COUNTIFS('Mechanics'!$C$7:$C$65,1,'Mechanics'!$D$7:$D$65,"R") | D20: =COUNTIFS('Pure'!$C$7:$C$181,1,'Pure'!$D$7:$D$181,"A")+COUNTIFS('Statistics'!$C$7:$C$67,1,'Statistics'!$D$7:$D$67,"A")+COUNTIFS('Mechanics'!$C$7:$C$65,1,'Mechanics'!$D$7:$D$65,"A") | E20: =COUNTIFS('Pure'!$C$7:$C$181,1,'Pure'!$D$7:$D$181,"G")+COUNTIFS('Statistics'!$C$7:$C$67,1,'Statistics'!$D$7:$D$67,"G")+COUNTIFS('Mechanics'!$C$7:$C$65,1,'Mechanics'!$D$7:$D$65,"G") | F20: =COUNTIFS('Pure'!$C$7:$C$181,1,'Pure'!$D$7:$D$181,"")+COUNTIFS('Statistics'!$C$7:$C$67,1,'Statistics'!$D$7:$D$67,"")+COUNTIFS('Mechanics'!$C$7:$C$65,1,'Mechanics'!$D$7:$D$65,"") | G20: =IFERROR(E20/B20,0)
A21: Year 2 | B21: =COUNTIFS('Pure'!$C$7:$C$181,2)+COUNTIFS('Statistics'!$C$7:$C$67,2)+COUNTIFS('Mechanics'!$C$7:$C$65,2) | C21: =COUNTIFS('Pure'!$C$7:$C$181,2,'Pure'!$D$7:$D$181,"R")+COUNTIFS('Statistics'!$C$7:$C$67,2,'Statistics'!$D$7:$D$67,"R")+COUNTIFS('Mechanics'!$C$7:$C$65,2,'Mechanics'!$D$7:$D$65,"R") | D21: =COUNTIFS('Pure'!$C$7:$C$181,2,'Pure'!$D$7:$D$181,"A")+COUNTIFS('Statistics'!$C$7:$C$67,2,'Statistics'!$D$7:$D$67,"A")+COUNTIFS('Mechanics'!$C$7:$C$65,2,'Mechanics'!$D$7:$D$65,"A") | E21: =COUNTIFS('Pure'!$C$7:$C$181,2,'Pure'!$D$7:$D$181,"G")+COUNTIFS('Statistics'!$C$7:$C$67,2,'Statistics'!$D$7:$D$67,"G")+COUNTIFS('Mechanics'!$C$7:$C$65,2,'Mechanics'!$D$7:$D$65,"G") | F21: =COUNTIFS('Pure'!$C$7:$C$181,2,'Pure'!$D$7:$D$181,"")+COUNTIFS('Statistics'!$C$7:$C$67,2,'Statistics'!$D$7:$D$67,"")+COUNTIFS('Mechanics'!$C$7:$C$65,2,'Mechanics'!$D$7:$D$65,"") | G21: =IFERROR(E21/B21,0)
A23: By area
B24: Topics | C24: Red | D24: Amber | E24: Green | F24: Not rated | G24: % Green
A25: Pure maths (Papers 1, 2 and 3) | B25: =COUNTIFS('Pure'!$C$7:$C$181,">0") | C25: =COUNTIFS('Pure'!$C$7:$C$181,">0",'Pure'!$D$7:$D$181,"R") | D25: =COUNTIFS('Pure'!$C$7:$C$181,">0",'Pure'!$D$7:$D$181,"A") | E25: =COUNTIFS('Pure'!$C$7:$C$181,">0",'Pure'!$D$7:$D$181,"G") | F25: =COUNTIFS('Pure'!$C$7:$C$181,">0",'Pure'!$D$7:$D$181,"") | G25: =IFERROR(E25/B25,0)
A26: Statistics (Paper 2) | B26: =COUNTIFS('Statistics'!$C$7:$C$67,">0") | C26: =COUNTIFS('Statistics'!$C$7:$C$67,">0",'Statistics'!$D$7:$D$67,"R") | D26: =COUNTIFS('Statistics'!$C$7:$C$67,">0",'Statistics'!$D$7:$D$67,"A") | E26: =COUNTIFS('Statistics'!$C$7:$C$67,">0",'Statistics'!$D$7:$D$67,"G") | F26: =COUNTIFS('Statistics'!$C$7:$C$67,">0",'Statistics'!$D$7:$D$67,"") | G26: =IFERROR(E26/B26,0)
A27: Mechanics (Paper 1) | B27: =COUNTIFS('Mechanics'!$C$7:$C$65,">0") | C27: =COUNTIFS('Mechanics'!$C$7:$C$65,">0",'Mechanics'!$D$7:$D$65,"R") | D27: =COUNTIFS('Mechanics'!$C$7:$C$65,">0",'Mechanics'!$D$7:$D$65,"A") | E27: =COUNTIFS('Mechanics'!$C$7:$C$65,">0",'Mechanics'!$D$7:$D$65,"G") | F27: =COUNTIFS('Mechanics'!$C$7:$C$65,">0",'Mechanics'!$D$7:$D$65,"") | G27: =IFERROR(E27/B27,0)
A29: By topic area
B30: Topics | C30: Red | D30: Amber | E30: Green | F30: Not rated | G30: % Green
A31: Pure 1: Proof | B31: =COUNTIFS('Pure'!$P$7:$P$181,"P1") | C31: =COUNTIFS('Pure'!$P$7:$P$181,"P1",'Pure'!$D$7:$D$181,"R") | D31: =COUNTIFS('Pure'!$P$7:$P$181,"P1",'Pure'!$D$7:$D$181,"A") | E31: =COUNTIFS('Pure'!$P$7:$P$181,"P1",'Pure'!$D$7:$D$181,"G") | F31: =COUNTIFS('Pure'!$P$7:$P$181,"P1",'Pure'!$D$7:$D$181,"") | G31: =IFERROR(E31/B31,0)
A32: Pure 2: Algebra | B32: =COUNTIFS('Pure'!$P$7:$P$181,"P2") | C32: =COUNTIFS('Pure'!$P$7:$P$181,"P2",'Pure'!$D$7:$D$181,"R") | D32: =COUNTIFS('Pure'!$P$7:$P$181,"P2",'Pure'!$D$7:$D$181,"A") | E32: =COUNTIFS('Pure'!$P$7:$P$181,"P2",'Pure'!$D$7:$D$181,"G") | F32: =COUNTIFS('Pure'!$P$7:$P$181,"P2",'Pure'!$D$7:$D$181,"") | G32: =IFERROR(E32/B32,0)
A33: Pure 3: Functions | B33: =COUNTIFS('Pure'!$P$7:$P$181,"P3") | C33: =COUNTIFS('Pure'!$P$7:$P$181,"P3",'Pure'!$D$7:$D$181,"R") | D33: =COUNTIFS('Pure'!$P$7:$P$181,"P3",'Pure'!$D$7:$D$181,"A") | E33: =COUNTIFS('Pure'!$P$7:$P$181,"P3",'Pure'!$D$7:$D$181,"G") | F33: =COUNTIFS('Pure'!$P$7:$P$181,"P3",'Pure'!$D$7:$D$181,"") | G33: =IFERROR(E33/B33,0)
A34: Pure 4: Graphs | B34: =COUNTIFS('Pure'!$P$7:$P$181,"P4") | C34: =COUNTIFS('Pure'!$P$7:$P$181,"P4",'Pure'!$D$7:$D$181,"R") | D34: =COUNTIFS('Pure'!$P$7:$P$181,"P4",'Pure'!$D$7:$D$181,"A") | E34: =COUNTIFS('Pure'!$P$7:$P$181,"P4",'Pure'!$D$7:$D$181,"G") | F34: =COUNTIFS('Pure'!$P$7:$P$181,"P4",'Pure'!$D$7:$D$181,"") | G34: =IFERROR(E34/B34,0)
A35: Pure 5: Coordinate geometry | B35: =COUNTIFS('Pure'!$P$7:$P$181,"P5") | C35: =COUNTIFS('Pure'!$P$7:$P$181,"P5",'Pure'!$D$7:$D$181,"R") | D35: =COUNTIFS('Pure'!$P$7:$P$181,"P5",'Pure'!$D$7:$D$181,"A") | E35: =COUNTIFS('Pure'!$P$7:$P$181,"P5",'Pure'!$D$7:$D$181,"G") | F35: =COUNTIFS('Pure'!$P$7:$P$181,"P5",'Pure'!$D$7:$D$181,"") | G35: =IFERROR(E35/B35,0)
A36: Pure 6: Sequences and series | B36: =COUNTIFS('Pure'!$P$7:$P$181,"P6") | C36: =COUNTIFS('Pure'!$P$7:$P$181,"P6",'Pure'!$D$7:$D$181,"R") | D36: =COUNTIFS('Pure'!$P$7:$P$181,"P6",'Pure'!$D$7:$D$181,"A") | E36: =COUNTIFS('Pure'!$P$7:$P$181,"P6",'Pure'!$D$7:$D$181,"G") | F36: =COUNTIFS('Pure'!$P$7:$P$181,"P6",'Pure'!$D$7:$D$181,"") | G36: =IFERROR(E36/B36,0)
A37: Pure 7: Trigonometry | B37: =COUNTIFS('Pure'!$P$7:$P$181,"P7") | C37: =COUNTIFS('Pure'!$P$7:$P$181,"P7",'Pure'!$D$7:$D$181,"R") | D37: =COUNTIFS('Pure'!$P$7:$P$181,"P7",'Pure'!$D$7:$D$181,"A") | E37: =COUNTIFS('Pure'!$P$7:$P$181,"P7",'Pure'!$D$7:$D$181,"G") | F37: =COUNTIFS('Pure'!$P$7:$P$181,"P7",'Pure'!$D$7:$D$181,"") | G37: =IFERROR(E37/B37,0)
A38: Pure 8: Exponentials and logarithms | B38: =COUNTIFS('Pure'!$P$7:$P$181,"P8") | C38: =COUNTIFS('Pure'!$P$7:$P$181,"P8",'Pure'!$D$7:$D$181,"R") | D38: =COUNTIFS('Pure'!$P$7:$P$181,"P8",'Pure'!$D$7:$D$181,"A") | E38: =COUNTIFS('Pure'!$P$7:$P$181,"P8",'Pure'!$D$7:$D$181,"G") | F38: =COUNTIFS('Pure'!$P$7:$P$181,"P8",'Pure'!$D$7:$D$181,"") | G38: =IFERROR(E38/B38,0)
A39: Pure 9: Differentiation | B39: =COUNTIFS('Pure'!$P$7:$P$181,"P9") | C39: =COUNTIFS('Pure'!$P$7:$P$181,"P9",'Pure'!$D$7:$D$181,"R") | D39: =COUNTIFS('Pure'!$P$7:$P$181,"P9",'Pure'!$D$7:$D$181,"A") | E39: =COUNTIFS('Pure'!$P$7:$P$181,"P9",'Pure'!$D$7:$D$181,"G") | F39: =COUNTIFS('Pure'!$P$7:$P$181,"P9",'Pure'!$D$7:$D$181,"") | G39: =IFERROR(E39/B39,0)
A40: Pure 10: Integration | B40: =COUNTIFS('Pure'!$P$7:$P$181,"P10") | C40: =COUNTIFS('Pure'!$P$7:$P$181,"P10",'Pure'!$D$7:$D$181,"R") | D40: =COUNTIFS('Pure'!$P$7:$P$181,"P10",'Pure'!$D$7:$D$181,"A") | E40: =COUNTIFS('Pure'!$P$7:$P$181,"P10",'Pure'!$D$7:$D$181,"G") | F40: =COUNTIFS('Pure'!$P$7:$P$181,"P10",'Pure'!$D$7:$D$181,"") | G40: =IFERROR(E40/B40,0)
A41: Pure 11: Differential equations | B41: =COUNTIFS('Pure'!$P$7:$P$181,"P11") | C41: =COUNTIFS('Pure'!$P$7:$P$181,"P11",'Pure'!$D$7:$D$181,"R") | D41: =COUNTIFS('Pure'!$P$7:$P$181,"P11",'Pure'!$D$7:$D$181,"A") | E41: =COUNTIFS('Pure'!$P$7:$P$181,"P11",'Pure'!$D$7:$D$181,"G") | F41: =COUNTIFS('Pure'!$P$7:$P$181,"P11",'Pure'!$D$7:$D$181,"") | G41: =IFERROR(E41/B41,0)
A42: Pure 12: Numerical methods | B42: =COUNTIFS('Pure'!$P$7:$P$181,"P12") | C42: =COUNTIFS('Pure'!$P$7:$P$181,"P12",'Pure'!$D$7:$D$181,"R") | D42: =COUNTIFS('Pure'!$P$7:$P$181,"P12",'Pure'!$D$7:$D$181,"A") | E42: =COUNTIFS('Pure'!$P$7:$P$181,"P12",'Pure'!$D$7:$D$181,"G") | F42: =COUNTIFS('Pure'!$P$7:$P$181,"P12",'Pure'!$D$7:$D$181,"") | G42: =IFERROR(E42/B42,0)
A43: Pure 13: Vectors | B43: =COUNTIFS('Pure'!$P$7:$P$181,"P13") | C43: =COUNTIFS('Pure'!$P$7:$P$181,"P13",'Pure'!$D$7:$D$181,"R") | D43: =COUNTIFS('Pure'!$P$7:$P$181,"P13",'Pure'!$D$7:$D$181,"A") | E43: =COUNTIFS('Pure'!$P$7:$P$181,"P13",'Pure'!$D$7:$D$181,"G") | F43: =COUNTIFS('Pure'!$P$7:$P$181,"P13",'Pure'!$D$7:$D$181,"") | G43: =IFERROR(E43/B43,0)
A44: Statistics 1: Sampling | B44: =COUNTIFS('Statistics'!$P$7:$P$67,"S1") | C44: =COUNTIFS('Statistics'!$P$7:$P$67,"S1",'Statistics'!$D$7:$D$67,"R") | D44: =COUNTIFS('Statistics'!$P$7:$P$67,"S1",'Statistics'!$D$7:$D$67,"A") | E44: =COUNTIFS('Statistics'!$P$7:$P$67,"S1",'Statistics'!$D$7:$D$67,"G") | F44: =COUNTIFS('Statistics'!$P$7:$P$67,"S1",'Statistics'!$D$7:$D$67,"") | G44: =IFERROR(E44/B44,0)
A45: Statistics 2: Data presentation and interpretation | B45: =COUNTIFS('Statistics'!$P$7:$P$67,"S2") | C45: =COUNTIFS('Statistics'!$P$7:$P$67,"S2",'Statistics'!$D$7:$D$67,"R") | D45: =COUNTIFS('Statistics'!$P$7:$P$67,"S2",'Statistics'!$D$7:$D$67,"A") | E45: =COUNTIFS('Statistics'!$P$7:$P$67,"S2",'Statistics'!$D$7:$D$67,"G") | F45: =COUNTIFS('Statistics'!$P$7:$P$67,"S2",'Statistics'!$D$7:$D$67,"") | G45: =IFERROR(E45/B45,0)
...
