Workbook

Sheet Summary
A1: Charlotte: PMT topic question plan
A2: Edexcel IGCSE Maths A (4MA1) Higher. Source: PMT Questions by Topic.
A4: Week | B4: Dates | C4: Focus | D4: Worksheets | E4: Questions in session | F4: Questions at home
A5: 1 | B5: 21 to 27 Sep | C5: Number: structure and calculation | D5: =COUNTIFS('Session plan'!$A$2:$A$74,$A5) -> 8 | E5: =SUMIFS('Session plan'!$H$2:$H$74,'Session plan'!$A$2:$A$74,$A5) -> 16 | F5: =SUMIFS('Session plan'!$I$2:$I$74,'Session plan'!$A$2:$A$74,$A5) -> 32
A6: 2 | B6: 28 Sep to 4 Oct | C6: Number: accuracy, then ratio | D6: =COUNTIFS('Session plan'!$A$2:$A$74,$A6) -> 11 | E6: =SUMIFS('Session plan'!$H$2:$H$74,'Session plan'!$A$2:$A$74,$A6) -> 22 | F6: =SUMIFS('Session plan'!$I$2:$I$74,'Session plan'!$A$2:$A$74,$A6) -> 44
A7: 3 | B7: 5 to 11 Oct | C7: Algebra | D7: =COUNTIFS('Session plan'!$A$2:$A$74,$A7) -> 10 | E7: =SUMIFS('Session plan'!$H$2:$H$74,'Session plan'!$A$2:$A$74,$A7) -> 20 | F7: =SUMIFS('Session plan'!$I$2:$I$74,'Session plan'!$A$2:$A$74,$A7) -> 40
A8: 4 | B8: 12 to 18 Oct | C8: Geometry: mensuration | D8: =COUNTIFS('Session plan'!$A$2:$A$74,$A8) -> 9 | E8: =SUMIFS('Session plan'!$H$2:$H$74,'Session plan'!$A$2:$A$74,$A8) -> 18 | F8: =SUMIFS('Session plan'!$I$2:$I$74,'Session plan'!$A$2:$A$74,$A8) -> 36
A9: 5 | B9: 19 to 25 Oct | C9: Geometry: properties | D9: =COUNTIFS('Session plan'!$A$2:$A$74,$A9) -> 9 | E9: =SUMIFS('Session plan'!$H$2:$H$74,'Session plan'!$A$2:$A$74,$A9) -> 18 | F9: =SUMIFS('Session plan'!$I$2:$I$74,'Session plan'!$A$2:$A$74,$A9) -> 36
A10: 6 | B10: 26 Oct to 1 Nov | C10: Graphs, probability and statistics | D10: =COUNTIFS('Session plan'!$A$2:$A$74,$A10) -> 12 | E10: =SUMIFS('Session plan'!$H$2:$H$74,'Session plan'!$A$2:$A$74,$A10) -> 24 | F10: =SUMIFS('Session plan'!$I$2:$I$74,'Session plan'!$A$2:$A$74,$A10) -> 48
A11: Spare | B11: if ahead | C11: Stretch topics, grade 6 single step | D11: =COUNTIFS('Session plan'!$A$2:$A$74,"Spare") -> 14 | E11: =SUMIFS('Session plan'!$H$2:$H$74,'Session plan'!$A$2:$A$74,"Spare") -> 0 | F11: =SUMIFS('Session plan'!$I$2:$I$74,'Session plan'!$A$2:$A$74,"Spare") -> 84
C12: Total | D12: =SUM(D5:D11) -> 73 | E12: =SUM(E5:E11) -> 118 | F12: =SUM(F5:F11) -> 320
A14: How to use it
A15: Each worksheet: 2 questions in the session (one modelled, one done by Charlotte), 4 at home. About half the sheet.
A16: Median PMT Higher worksheet is 13 pages, about 13 questions, about 45 marks. Six questions is roughly 20 marks.
A17: She marks her own at home against the MS column. The Answers column is worked solutions, for when the MS is not enough.
A18: Stretch rows (shaded) are grade 6 single step topics. Do them only once the Core rows for that week are done.
A19: The Not covered tab lists the 22 worksheets deliberately left out, with the reason for each.
A20: Tick the Done column on the Session plan tab.

Sheet Session plan
A1: Week | B1: Dates | C1: Focus | D1: Folder | E1: Sub-folder | F1: Worksheet | G1: Priority | H1: In session | I1: At home | J1: QP | K1: MS | L1: Answers | M1: Done
A2: 1 | B2: 21 to 27 Sep | C2: Number: structure and calculation | D2: Number | E2: Fractions Decimals and Percentages | F2: Fractions | G2: Core | H2: 2 | I2: 4 | J2: QP | K2: MS | L2: Ans
A3: 1 | B3: 21 to 27 Sep | C3: Number: structure and calculation | D3: Number | E3: Fractions Decimals and Percentages | F3: Percentages | G3: Core | H3: 2 | I3: 4 | J3: QP | K3: MS | L3: Ans
A4: 1 | B4: 21 to 27 Sep | C4: Number: structure and calculation | D4: Number | E4: Structure and Calculation | F4: Calculating Problems | G4: Core | H4: 2 | I4: 4 | J4: QP | K4: MS | L4: Ans
A5: 1 | B5: 21 to 27 Sep | C5: Number: structure and calculation | D5: Number | E5: Structure and Calculation | F5: Four Operations | G5: Core | H5: 2 | I5: 4 | J5: QP | K5: MS | L5: Ans
A6: 1 | B6: 21 to 27 Sep | C6: Number: structure and calculation | D6: Number | E6: Structure and Calculation | F6: Indices | G6: Core | H6: 2 | I6: 4 | J6: QP | K6: MS | L6: Ans
A7: 1 | B7: 21 to 27 Sep | C7: Number: structure and calculation | D7: Number | E7: Structure and Calculation | F7: Primes, Factors and Multiples | G7: Core | H7: 2 | I7: 4 | J7: QP | K7: MS | L7: Ans
A8: 1 | B8: 21 to 27 Sep | C8: Number: structure and calculation | D8: Number | E8: Structure and Calculation | F8: Roots and Powers | G8: Core | H8: 2 | I8: 4 | J8: QP | K8: MS | L8: Ans
A9: 1 | B9: 21 to 27 Sep | C9: Number: structure and calculation | D9: Number | E9: Structure and Calculation | F9: Standard Form | G9: Core | H9: 2 | I9: 4 | J9: QP | K9: MS | L9: Ans
A10: 2 | B10: 28 Sep to 4 Oct | C10: Number: accuracy, then ratio | D10: Number | E10: Measures and Accuracy | F10: Approximation and Estimation | G10: Core | H10: 2 | I10: 4 | J10: QP | K10: MS | L10: Ans
A11: 2 | B11: 28 Sep to 4 Oct | C11: Number: accuracy, then ratio | D11: Number | E11: Measures and Accuracy | F11: Rounding | G11: Core | H11: 2 | I11: 4 | J11: QP | K11: MS | L11: Ans
A12: 2 | B12: 28 Sep to 4 Oct | C12: Number: accuracy, then ratio | D12: Number | E12: Measures and Accuracy | F12: Using Measures | G12: Core | H12: 2 | I12: 4 | J12: QP | K12: MS | L12: Ans
A13: 2 | B13: 28 Sep to 4 Oct | C13: Number: accuracy, then ratio | D13: Ratio Proportion and Rates of Change | F13: Compound Measures | G13: Core | H13: 2 | I13: 4 | J13: QP | K13: MS | L13: Ans
A14: 2 | B14: 28 Sep to 4 Oct | C14: Number: accuracy, then ratio | D14: Ratio Proportion and Rates of Change | F14: Compound Units | G14: Core | H14: 2 | I14: 4 | J14: QP | K14: MS | L14: Ans
A15: 2 | B15: 28 Sep to 4 Oct | C15: Number: accuracy, then ratio | D15: Ratio Proportion and Rates of Change | F15: Percentage Increase or Decrease | G15: Core | H15: 2 | I15: 4 | J15: QP | K15: MS | L15: Ans
A16: 2 | B16: 28 Sep to 4 Oct | C16: Number: accuracy, then ratio | D16: Ratio Proportion and Rates of Change | F16: Proportion | G16: Core | H16: 2 | I16: 4 | J16: QP | K16: MS | L16: Ans
A17: 2 | B17: 28 Sep to 4 Oct | C17: Number: accuracy, then ratio | D17: Ratio Proportion and Rates of Change | F17: Ratio | G17: Core | H17: 2 | I17: 4 | J17: QP | K17: MS | L17: Ans
A18: 2 | B18: 28 Sep to 4 Oct | C18: Number: accuracy, then ratio | D18: Ratio Proportion and Rates of Change | F18: Scale Factors | G18: Core | H18: 2 | I18: 4 | J18: QP | K18: MS | L18: Ans
A19: 2 | B19: 28 Sep to 4 Oct | C19: Number: accuracy, then ratio | D19: Ratio Proportion and Rates of Change | F19: Speed | G19: Core | H19: 2 | I19: 4 | J19: QP | K19: MS | L19: Ans
A20: 2 | B20: 28 Sep to 4 Oct | C20: Number: accuracy, then ratio | D20: Ratio Proportion and Rates of Change | F20: Units of Measure | G20: Core | H20: 2 | I20: 4 | J20: QP | K20: MS | L20: Ans
A21: 3 | B21: 5 to 11 Oct | C21: Algebra | D21: Algebra | E21: Notation Vocabulary and Manipulation | F21: Deriving Expressions | G21: Core | H21: 2 | I21: 4 | J21: QP | K21: MS | L21: Ans
A22: 3 | B22: 5 to 11 Oct | C22: Algebra | D22: Algebra | E22: Notation Vocabulary and Manipulation | F22: Expanding Equations | G22: Core | H22: 2 | I22: 4 | J22: QP | K22: MS | L22: Ans
A23: 3 | B23: 5 to 11 Oct | C23: Algebra | D23: Algebra | E23: Notation Vocabulary and Manipulation | F23: Factorising Equations | G23: Core | H23: 2 | I23: 4 | J23: QP | K23: MS | L23: Ans
A24: 3 | B24: 5 to 11 Oct | C24: Algebra | D24: Algebra | E24: Notation Vocabulary and Manipulation | F24: Forming Equations | G24: Core | H24: 2 | I24: 4 | J24: QP | K24: MS | L24: Ans
A25: 3 | B25: 5 to 11 Oct | C25: Algebra | D25: Algebra | E25: Notation Vocabulary and Manipulation | F25: Manipulation of Formulae | G25: Core | H25: 2 | I25: 4 | J25: QP | K25: MS | L25: Ans
A26: 3 | B26: 5 to 11 Oct | C26: Algebra | D26: Algebra | E26: Notation Vocabulary and Manipulation | F26: Simplifying Expressions | G26: Core | H26: 2 | I26: 4 | J26: QP | K26: MS | L26: Ans
A27: 3 | B27: 5 to 11 Oct | C27: Algebra | D27: Algebra | E27: Notation Vocabulary and Manipulation | F27: Substitution into Equations | G27: Core | H27: 2 | I27: 4 | J27: QP | K27: MS | L27: Ans
A28: 3 | B28: 5 to 11 Oct | C28: Algebra | D28: Algebra | E28: Solving Equations and Inequalities | F28: Inequalities | G28: Core | H28: 2 | I28: 4 | J28: QP | K28: MS | L28: Ans
A29: 3 | B29: 5 to 11 Oct | C29: Algebra | D29: Algebra | E29: Solving Equations and Inequalities | F29: Simultaneous Equations | G29: Core | H29: 2 | I29: 4 | J29: QP | K29: MS | L29: Ans
A30: 3 | B30: 5 to 11 Oct | C30: Algebra | D30: Algebra | E30: Solving Equations and Inequalities | F30: Solving Linear Equations | G30: Core | H30: 2 | I30: 4 | J30: QP | K30: MS | L30: Ans
A31: 4 | B31: 12 to 18 Oct | C31: Geometry: mensuration | D31: Geometry and Measures | E31: Mensuration and Calculation | F31: Area | G31: Core | H31: 2 | I31: 4 | J31: QP | K31: MS | L31: Ans
A32: 4 | B32: 12 to 18 Oct | C32: Geometry: mensuration | D32: Geometry and Measures | E32: Mensuration and Calculation | F32: Area of Shaded Region | G32: Core | H32: 2 | I32: 4 | J32: QP | K32: MS | L32: Ans
... A53: 6 | B53: 26 Oct to 1 Nov | C53: Graphs, probability and statistics | D53: Algebra | E53: Sequences | F53: Sequences | G53: Core | H53: 2 | I53: 4 | J53: QP | K53: MS | L53: Ans
A54: 6 | B54: 26 Oct to 1 Nov | C54: Graphs, probability and statistics | D54: Probability | F54: Probability Equations | G54: Core | H54: 2 | I54: 4 | J54: QP | K54: MS | L54: Ans
A55: 6 | B55: 26 Oct to 1 Nov | C55: Graphs, probability and statistics | D55: Probability | F55: Probability of Events | G55: Core | H55: 2 | I55: 4 | J55: QP | K55: MS | L55: Ans
A56: 6 | B56: 26 Oct to 1 Nov | C56: Graphs, probability and statistics | D56: Probability | F56: Tree Diagrams | G56: Core | H56: 2 | I56: 4 | J56: QP | K56: MS | L56: Ans
A57: 6 | B57: 26 Oct to 1 Nov | C57: Graphs, probability and statistics | D57: Probability | F57: Venn Diagrams | G57: Core | H57: 2 | I57: 4 | J57: QP | K57: MS | L57: Ans
A58: 6 | B58: 26 Oct to 1 Nov | C58: Graphs, probability and statistics | D58: Statistics | F58: Frequency Tables | G58: Core | H58: 2 | I58: 4 | J58: QP | K58: MS | L58: Ans
A59: 6 | B59: 26 Oct to 1 Nov | C59: Graphs, probability and statistics | D59: Statistics | F59: Interpreting Data | G59: Core | H59: 2 | I59: 4 | J59: QP | K59: MS | L59: Ans
A60: 6 | B60: 26 Oct to 1 Nov | C60: Graphs, probability and statistics | D60: Statistics | F60: Mean, Median, Mode, Range | G60: Core | H60: 2 | I60: 4 | J60: QP | K60: MS | L60: Ans
...

Sheet Not covered
A1: Folder | B1: Sub-folder | C1: Worksheet | D1: Why it is left out
A2: Algebra | B2: Graphs | C2: Circle Equations and Tangents | D2: Grade 8
A3: Algebra | B3: Graphs | C3: Exponential and Trigonometric Graphs | D3: Grade 8
A4: Algebra | B4: Graphs | C4: Graphs of Circles | D4: Grade 7
A5: Algebra | B5: Graphs | C5: Translations and Reflections of Functions | D5: Grade 8
A6: Algebra | B6: Notation Vocabulary and Manipulation | C6: Algebraic Fractions | D6: Grade 7
A7: Algebra | B7: Notation Vocabulary and Manipulation | C7: Algebraic Proof | D7: Grade 8
A8: Algebra | B8: Notation Vocabulary and Manipulation | C8: Expanding Triple Brackets | D8: Grade 7
A9: Algebra | B9: Notation Vocabulary and Manipulation | C9: Functions (Composite or Inverse) | D9: Grade 7
A10: Algebra | B10: Solving Equations and Inequalities | C10: Completing the square | D10: Grade 7
A11: Algebra | B11: Solving Equations and Inequalities | C11: Inequalities on Graphs | D11: Grade 7
A12: Algebra | B12: Solving Equations and Inequalities | C12: Quadratic Inequalities | D12: Grade 8
... A21: Number | B21: Structure and Calculation | C21: Surds | D21: Grade 7
A22: Ratio Proportion and Rates of Change | C22: Algebraic Direct and Inverse Proportions | D22: Grade 7
A23: Statistics | C23: Histograms | D23: Grade 7, unequal class widths
