Workbook

Sheet Summary
A1: Summary
A2: Fills in automatically once the RAG tracker is completed.
A4: Rating | B4: Topics | C4: What we do | D4: Questions each | E4: Questions total
A5: R | B5: =COUNTIFS('RAG tracker'!$E$2:$E$57,$A5) -> 0 | C5: Full worksheet, taught first | D5: 13 | E5: =$B5*$D5 -> 0
A6: A | B6: =COUNTIFS('RAG tracker'!$E$2:$E$57,$A6) -> 0 | C6: Work until 3 right in a row | D6: 6 | E6: =$B6*$D6 -> 0
A7: G | B7: =COUNTIFS('RAG tracker'!$E$2:$E$57,$A7) -> 0 | C7: 2 question spot check | D7: 2 | E7: =$B7*$D7 -> 0
A8: Not yet rated | B8: =COUNTIFS('RAG tracker'!$E$2:$E$57,"") -> 56
C9: Total questions | E9: =SUM(E5:E7) -> 0
C10: Hours at about 2.5 min a question | E10: =ROUND($E9*2.5/60,1) -> 0
C11: Hours per week over six weeks | E11: =ROUND($E10/6,1) -> 0
A13: Assumptions
A14: 13 questions per worksheet is the measured median of the PMT Higher sheets (13 pages, about 45 marks).
A15: 2.5 minutes a question is an estimate. Charlotte has extra time, so treat the hours as a floor.
A16: Amber topics stop at 3 correct in a row, so 6 is an average rather than a fixed number.
A17: Rows marked 'Not this time' in the plan column sit above a grade 5 and are not scheduled, whatever the rating.
A18: 3.4 Calculus is on the Higher specification but PMT has no topic worksheet for it.

Sheet Start here
A1: Charlotte: maths topic check
A2: Edexcel International GCSE Mathematics A (4MA1), Higher Tier. Every topic below is taken from the Pearson specification.
A4: What to do | B4: Go to the RAG tracker tab. For each row, read the topic and what it covers, then put R, A or G in the 'Your rating' column. That is the only column you need to fill in, plus Notes if you want.
A5: R | B5: I could not start this, or I would get it wrong.
A6: A | B6: I can do it but slowly, or I get some of it right and some wrong.
A7: G | B7: I can do this confidently and quickly.
A8: Be honest rather than kind | B8: A topic marked G gets almost no time from us. If you are unsure between two ratings, pick the lower one.
A9: Higher only rows | B9: Some rows are marked 'Higher only'. Those are the harder end of the paper. Rate them anyway, even if you have never seen them.
A10: How long | B10: About 55 rows. It should take 20 to 30 minutes. You do not need to do any maths to fill it in.
A12: Example of a filled row
A13: Ref | B13: Topic | C13: What it covers | D13: Level | E13: Your rating | F13: Notes
A14: 1.2 | B14: Fractions | C14: Equivalent fractions and simplifying, mixed numbers, all four operations | D14: Foundation | E14: A | F14: Fine adding, always get stuck dividing

Sheet RAG tracker
A1: Ref | B1: Topic | C1: What it covers | D1: Level | E1: Your rating | F1: Notes | G1: In our plan | H1: What we do about it
A2: 1.1 | B2: Integers and the number system | C2: Negative numbers, place value, ordering, the four operations, order of operations, factors, multiples and primes | D2: Foundation | G2: Core | H2: =IF($E2="","",IF($E2="R","Full worksheet, taught first",IF($E2="A","Work until 3 right in a row",IF($E2="G","2 question spot check in week 5",""))))
A3: 1.2 | B3: Fractions | C3: Equivalent fractions and simplifying, mixed numbers, all four operations, a fraction of a quantity, converting to decimals and percentages | D3: Foundation | G3: Core | H3: =IF($E3="","",IF($E3="R","Full worksheet, taught first",IF($E3="A","Work until 3 right in a row",IF($E3="G","2 question spot check in week 5",""))))
A4: 1.3 | B4: Decimals | C4: Place value, ordering decimals, converting decimals to fractions and percentages | D4: Foundation | G4: Core | H4: =IF($E4="","",IF($E4="R","Full worksheet, taught first",IF($E4="A","Work until 3 right in a row",IF($E4="G","2 question spot check in week 5",""))))
A5: 1.3H | B5: Recurring decimals | C5: Converting a recurring decimal into a fraction | D5: Higher only | G5: Not this time | H5: =IF($E5="","",IF($E5="R","Full worksheet, taught first",IF($E5="A","Work until 3 right in a row",IF($E5="G","2 question spot check in week 5",""))))
A6: 1.4 | B6: Powers and roots | C6: Squares, cubes and their roots, index laws for positive and negative powers, product of prime factors, HCF and LCM | D6: Foundation | G6: Core | H6: =IF($E6="","",IF($E6="R","Full worksheet, taught first",IF($E6="A","Work until 3 right in a row",IF($E6="G","2 question spot check in week 5",""))))
A7: 1.4H | B7: Surds and fractional indices | C7: Simplifying and manipulating surds, rationalising a denominator, fractional and negative powers | D7: Higher only | G7: Not this time | H7: =IF($E7="","",IF($E7="R","Full worksheet, taught first",IF($E7="A","Work until 3 right in a row",IF($E7="G","2 question spot check in week 5",""))))
A8: 1.5 | B8: Set language and Venn diagrams | C8: Set notation, universal and empty set, complement, Venn diagrams, n(A), subsets | D8: Foundation + Higher | G8: Core | H8: =IF($E8="","",IF($E8="R","Full worksheet, taught first",IF($E8="A","Work until 3 right in a row",IF($E8="G","2 question spot check in week 5",""))))
A9: 1.6 | B9: Percentages | C9: Percentage of a quantity, one number as a percentage of another, increase and decrease, reverse percentages, compound interest and depreciation, repeated percentage change | D9: Foundation + Higher | G9: Core | H9: =IF($E9="","",IF($E9="R","Full worksheet, taught first",IF($E9="A","Work until 3 right in a row",IF($E9="G","2 question spot check in week 5",""))))
A10: 1.7 | B10: Ratio and proportion | C10: Ratio notation and simplifying, dividing a quantity in a ratio, unitary method, direct proportion, maps and scale diagrams | D10: Foundation | G10: Core | H10: =IF($E10="","",IF($E10="R","Full worksheet, taught first",IF($E10="A","Work until 3 right in a row",IF($E10="G","2 question spot check in week 5",""))))
A11: 1.8 | B11: Degree of accuracy | C11: Rounding to decimal places and significant figures, estimating by rounding to 1 significant figure | D11: Foundation | G11: Core | H11: =IF($E11="","",IF($E11="R","Full worksheet, taught first",IF($E11="A","Work until 3 right in a row",IF($E11="G","2 question spot check in week 5",""))))
A12: 1.8H | B12: Upper and lower bounds | C12: Identifying bounds and solving problems using them | D12: Higher only | G12: Not this time | H12: =IF($E12="","",IF($E12="R","Full worksheet, taught first",IF($E12="A","Work until 3 right in a row",IF($E12="G","2 question spot check in week 5",""))))
A13: 1.9 | B13: Standard form | C13: Calculating with and interpreting numbers in standard form, and solving problems with it | D13: Foundation + Higher | G13: Core | H13: =IF($E13="","",IF($E13="R","Full worksheet, taught first",IF($E13="A","Work until 3 right in a row",IF($E13="G","2 question spot check in week 5",""))))
... A57: 6.3H | B57: Tree diagrams and conditional probability | C57: Tree diagrams, independent events, simple conditional probability | D57: Higher only | G57: Core | H57: =IF($E57="","",IF($E57="R","Full worksheet, taught first",IF($E57="A","Work until 3 right in a row",IF($E57="G","2 question spot check in week 5",""))))

Sheet Worksheets
A1: Ref | B1: Topic | C1: In our plan | D1: Your rating | E1: PMT worksheet | F1: Questions | G1: QP | H1: MS | I1: Answers | J1: Started | K1: 3 in a row | L1: Cleared
A2: 1.1 | B2: Integers and the number system | C2: Core | D2: ='RAG tracker'!$E2 -> 0 | E2: Four Operations | F2: 13 | G2: QP | H2: MS | I2: Ans
A3: 1.1 | B3: Integers and the number system | C3: Core | D3: ='RAG tracker'!$E2 -> 0 | E3: Primes, Factors and Multiples | F3: 13 | G3: QP | H3: MS | I3: Ans
A4: 1.1 | B4: Integers and the number system | C4: Core | D4: ='RAG tracker'!$E2 -> 0 | E4: Calculating Problems | F4: 13 | G4: QP | H4: MS | I4: Ans
A5: 1.2 | B5: Fractions | C5: Core | D5: ='RAG tracker'!$E3 -> 0 | E5: Fractions | F5: 13 | G5: QP | H5: MS | I5: Ans
A6: 1.3 | B6: Decimals | C6: Core | D6: ='RAG tracker'!$E4 -> 0 | E6: Fractions | F6: 13 | G6: QP | H6: MS | I6: Ans
A7: 1.3H | B7: Recurring decimals | C7: Not this time | D7: ='RAG tracker'!$E5 -> 0 | E7: Recurring Decimals into Fractions | F7: 13 | G7: QP | H7: MS | I7: Ans
A8: 1.4 | B8: Powers and roots | C8: Core | D8: ='RAG tracker'!$E6 -> 0 | E8: Roots and Powers | F8: 13 | G8: QP | H8: MS | I8: Ans
A9: 1.4 | B9: Powers and roots | C9: Core | D9: ='RAG tracker'!$E6 -> 0 | E9: Indices | F9: 13 | G9: QP | H9: MS | I9: Ans
A10: 1.4 | B10: Powers and roots | C10: Core | D10: ='RAG tracker'!$E6 -> 0 | E10: Primes, Factors and Multiples | F10: 13 | G10: QP | H10: MS | I10: Ans
A11: 1.4H | B11: Surds and fractional indices | C11: Not this time | D11: ='RAG tracker'!$E7 -> 0 | E11: Surds | F11: 13 | G11: QP | H11: MS | I11: Ans
A12: 1.4H | B12: Surds and fractional indices | C12: Not this time | D12: ='RAG tracker'!$E7 -> 0 | E12: Indices | F12: 13 | G12: QP | H12: MS | I12: Ans
A13: 1.5 | B13: Set language and Venn diagrams | C13: Core | D13: ='RAG tracker'!$E8 -> 0 | E13: Venn Diagrams | F13: 13 | G13: QP | H13: MS | I13: Ans
A14: 1.6 | B14: Percentages | C14: Core | D14: ='RAG tracker'!$E9 -> 0 | E14: Percentages | F14: 13 | G14: QP | H14: MS | I14: Ans
A15: 1.6 | B15: Percentages | C15: Core | D15: ='RAG tracker'!$E9 -> 0 | E15: Percentage Increase or Decrease | F15: 13 | G15: QP | H15: MS | I15: Ans
A16: 1.6 | B16: Percentages | C16: Core | D16: ='RAG tracker'!$E9 -> 0 | E16: Compound Interest | F16: 13 | G16: QP | H16: MS | I16: Ans
A17: 1.7 | B17: Ratio and proportion | C17: Core | D17: ='RAG tracker'!$E10 -> 0 | E17: Ratio | F17: 13 | G17: QP | H17: MS | I17: Ans
A18: 1.7 | B18: Ratio and proportion | C18: Core | D18: ='RAG tracker'!$E10 -> 0 | E18: Proportion | F18: 13 | G18: QP | H18: MS | I18: Ans
A19: 1.7 | B19: Ratio and proportion | C19: Core | D19: ='RAG tracker'!$E10 -> 0 | E19: Scale Factors | F19: 13 | G19: QP | H19: MS | I19: Ans
A20: 1.7 | B20: Ratio and proportion | C20: Core | D20: ='RAG tracker'!$E10 -> 0 | E20: Maps and Scale Drawings | F20: 13 | G20: QP | H20: MS | I20: Ans
A21: 1.8 | B21: Degree of accuracy | C21: Core | D21: ='RAG tracker'!$E11 -> 0 | E21: Rounding | F21: 13 | G21: QP | H21: MS | I21: Ans
A22: 1.8 | B22: Degree of accuracy | C22: Core | D22: ='RAG tracker'!$E11 -> 0 | E22: Approximation and Estimation | F22: 13 | G22: QP | H22: MS | I22: Ans
A23: 1.8H | B23: Upper and lower bounds | C23: Not this time | D23: ='RAG tracker'!$E12 -> 0 | E23: Bounds | F23: 13 | G23: QP | H23: MS | I23: Ans
A24: 1.9 | B24: Standard form | C24: Core | D24: ='RAG tracker'!$E13 -> 0 | E24: Standard Form | F24: 13 | G24: QP | H24: MS | I24: Ans
A25: 1.10 | B25: Applying number | C25: Core | D25: ='RAG tracker'!$E14 -> 0 | E25: Units of Measure | F25: 13 | G25: QP | H25: MS | I25: Ans
A26: 1.10 | B26: Applying number | C26: Core | D26: ='RAG tracker'!$E14 -> 0 | E26: Using Measures | F26: 13 | G26: QP | H26: MS | I26: Ans
A27: 1.10 | B27: Applying number | C27: Core | D27: ='RAG tracker'!$E14 -> 0 | E27: Calculating Problems | F27: 13 | G27: QP | H27: MS | I27: Ans
A28: 1.11 | B28: Calculator use | C28: Core | D28: ='RAG tracker'!$E15 -> 0 | E28: No PMT worksheet for this topic
A29: 2.1 | B29: Use of symbols | C29: Core | D29: ='RAG tracker'!$E16 -> 0 | E29: Simplifying Expressions | F29: 13 | G29: QP | H29: MS | I29: Ans
A30: 2.1 | B30: Use of symbols | C30: Core | D30: ='RAG tracker'!$E16 -> 0 | E30: Indices | F30: 13 | G30: QP | H30: MS | I30: Ans
A31: 2.2 | B31: Algebraic manipulation | C31: Core | D31: ='RAG tracker'!$E17 -> 0 | E31: Expanding Equations | F31: 13 | G31: QP | H31: MS | I31: Ans
A32: 2.2 | B32: Algebraic manipulation | C32: Core | D32: ='RAG tracker'!$E17 -> 0 | E32: Factorising Equations | F32: 13 | G32: QP | H32: MS | I32: Ans
A33: 2.2 | B33: Algebraic manipulation | C33: Core | D33: ='RAG tracker'!$E17 -> 0 | E33: Simplifying Expressions | F33: 13 | G33: QP | H33: MS | I33: Ans
A34: 2.2 | B34: Algebraic manipulation | C34: Core | D34: ='RAG tracker'!$E17 -> 0 | E34: Substitution into Equations | F34: 13 | G34: QP | H34: MS | I34: Ans
A35: 2.2H | B35: Harder algebraic manipulation | C35: Not this time | D35: ='RAG tracker'!$E18 -> 0 | E35: Expanding Triple Brackets | F35: 13 | G35: QP | H35: MS | I35: Ans
A36: 2.2H | B36: Harder algebraic manipulation | C36: Not this time | D36: ='RAG tracker'!$E18 -> 0 | E36: Algebraic Fractions | F36: 13 | G36: QP | H36: MS | I36: Ans
A37: 2.2H | B37: Harder algebraic manipulation | C37: Not this time | D37: ='RAG tracker'!$E18 -> 0 | E37: Completing the square | F37: 13 | G37: QP | H37: MS | I37: Ans
A38: 2.2H | B38: Harder algebraic manipulation | C38: Not this time | D38: ='RAG tracker'!$E18 -> 0 | E38: Algebraic Proof | F38: 13 | G38: QP | H38: MS | I38: Ans
A39: 2.3 | B39: Expressions and formulae | C39: Core | D39: ='RAG tracker'!$E19 -> 0 | E39: Manipulation of Formulae | F39: 13 | G39: QP | H39: MS | I39: Ans
A40: 2.3 | B40: Expressions and formulae | C40: Core | D40: ='RAG tracker'!$E19 -> 0 | E40: Deriving Expressions | F40: 13 | G40: QP | H40: MS | I40: Ans
...
